{"level":"ERROR","location":"[On_message:1442] data_ws","message":"'symbol'","timestamp":"2025-06-26 19:00:06,781+0530","service":"FyersDataSocket","exception":"Traceback (most recent call last):\n  File \"C:\\Python311\\Lib\\site-packages\\fyers_apiv3\\FyersWebsocket\\data_ws.py\", line 1433, in On_message\n    self.OnMessage(message)\n  File \"d:\\FyiersApiAutomation\\websocket\\fyers_websocket_ltp.py\", line 13, in onmessage\n    print(\"Symbol: \",message['symbol'],\"ltp: \",message['ltp'])\n                     ~~~~~~~^^^^^^^^^^\nKeyError: 'symbol'","exception_name":"KeyError"}
{"level":"ERROR","location":"[On_message:1443] data_ws","message":"KeyError: The key 'symbol' is missing in the response.","timestamp":"2025-06-26 19:00:06,785+0530","service":"FyersDataSocket"}
{"level":"ERROR","location":"[On_message:1442] data_ws","message":"'symbol'","timestamp":"2025-06-26 19:00:06,922+0530","service":"FyersDataSocket","exception":"Traceback (most recent call last):\n  File \"C:\\Python311\\Lib\\site-packages\\fyers_apiv3\\FyersWebsocket\\data_ws.py\", line 1433, in On_message\n    self.OnMessage(message)\n  File \"d:\\FyiersApiAutomation\\websocket\\fyers_websocket_ltp.py\", line 13, in onmessage\n    print(\"Symbol: \",message['symbol'],\"ltp: \",message['ltp'])\n                     ~~~~~~~^^^^^^^^^^\nKeyError: 'symbol'","exception_name":"KeyError"}
{"level":"ERROR","location":"[On_message:1443] data_ws","message":"KeyError: The key 'symbol' is missing in the response.","timestamp":"2025-06-26 19:00:06,922+0530","service":"FyersDataSocket"}
{"level":"ERROR","location":"[On_message:1442] data_ws","message":"'symbol'","timestamp":"2025-06-26 19:00:09,232+0530","service":"FyersDataSocket","exception":"Traceback (most recent call last):\n  File \"C:\\Python311\\Lib\\site-packages\\fyers_apiv3\\FyersWebsocket\\data_ws.py\", line 1433, in On_message\n    self.OnMessage(message)\n  File \"d:\\FyiersApiAutomation\\websocket\\fyers_websocket_ltp.py\", line 13, in onmessage\n    print(\"Symbol: \",message['symbol'],\"ltp: \",message['ltp'])\n                     ~~~~~~~^^^^^^^^^^\nKeyError: 'symbol'","exception_name":"KeyError"}
{"level":"ERROR","location":"[On_message:1443] data_ws","message":"KeyError: The key 'symbol' is missing in the response.","timestamp":"2025-06-26 19:00:09,232+0530","service":"FyersDataSocket"}
{"level":"ERROR","location":"[On_message:1442] data_ws","message":"'exch_feed_time'","timestamp":"2025-07-20 11:23:03,540+0530","service":"FyersDataSocket","exception":"Traceback (most recent call last):\n  File \"C:\\Python311\\Lib\\site-packages\\fyers_apiv3\\FyersWebsocket\\data_ws.py\", line 1433, in On_message\n    self.OnMessage(message)\n  File \"d:\\FyiersApiAutomation\\websocket\\fyers_websocket_ohlc.py\", line 37, in onmessage\n    ms = message['exch_feed_time']\n         ~~~~~~~^^^^^^^^^^^^^^^^^^\nKeyError: 'exch_feed_time'","exception_name":"KeyError"}
{"level":"ERROR","location":"[On_message:1443] data_ws","message":"KeyError: The key 'exch_feed_time' is missing in the response.","timestamp":"2025-07-20 11:23:03,556+0530","service":"FyersDataSocket"}
{"level":"ERROR","location":"[On_message:1442] data_ws","message":"'exch_feed_time'","timestamp":"2025-07-20 11:23:03,852+0530","service":"FyersDataSocket","exception":"Traceback (most recent call last):\n  File \"C:\\Python311\\Lib\\site-packages\\fyers_apiv3\\FyersWebsocket\\data_ws.py\", line 1433, in On_message\n    self.OnMessage(message)\n  File \"d:\\FyiersApiAutomation\\websocket\\fyers_websocket_ohlc.py\", line 37, in onmessage\n    ms = message['exch_feed_time']\n         ~~~~~~~^^^^^^^^^^^^^^^^^^\nKeyError: 'exch_feed_time'","exception_name":"KeyError"}
{"level":"ERROR","location":"[On_message:1443] data_ws","message":"KeyError: The key 'exch_feed_time' is missing in the response.","timestamp":"2025-07-20 11:23:03,852+0530","service":"FyersDataSocket"}
{"level":"ERROR","location":"[On_message:1442] data_ws","message":"'exch_feed_time'","timestamp":"2025-07-20 11:23:06,027+0530","service":"FyersDataSocket","exception":"Traceback (most recent call last):\n  File \"C:\\Python311\\Lib\\site-packages\\fyers_apiv3\\FyersWebsocket\\data_ws.py\", line 1433, in On_message\n    self.OnMessage(message)\n  File \"d:\\FyiersApiAutomation\\websocket\\fyers_websocket_ohlc.py\", line 37, in onmessage\n    ms = message['exch_feed_time']\n         ~~~~~~~^^^^^^^^^^^^^^^^^^\nKeyError: 'exch_feed_time'","exception_name":"KeyError"}
{"level":"ERROR","location":"[On_message:1443] data_ws","message":"KeyError: The key 'exch_feed_time' is missing in the response.","timestamp":"2025-07-20 11:23:06,027+0530","service":"FyersDataSocket"}
{"level":"ERROR","location":"[On_message:1442] data_ws","message":"'exch_feed_time'","timestamp":"2025-08-27 19:01:06,134+0530","service":"FyersDataSocket","exception":"Traceback (most recent call last):\n  File \"C:\\Python311\\Lib\\site-packages\\fyers_apiv3\\FyersWebsocket\\data_ws.py\", line 1433, in On_message\n    self.OnMessage(message)\n  File \"d:\\FyiersApiAutomation\\websocket\\fyers_websocket_ohlc.py\", line 37, in onmessage\n    ms = message['exch_feed_time']\n         ~~~~~~~^^^^^^^^^^^^^^^^^^\nKeyError: 'exch_feed_time'","exception_name":"KeyError"}
{"level":"ERROR","location":"[On_message:1443] data_ws","message":"KeyError: The key 'exch_feed_time' is missing in the response.","timestamp":"2025-08-27 19:01:06,171+0530","service":"FyersDataSocket"}
{"level":"ERROR","location":"[On_message:1442] data_ws","message":"'exch_feed_time'","timestamp":"2025-08-27 19:01:06,297+0530","service":"FyersDataSocket","exception":"Traceback (most recent call last):\n  File \"C:\\Python311\\Lib\\site-packages\\fyers_apiv3\\FyersWebsocket\\data_ws.py\", line 1433, in On_message\n    self.OnMessage(message)\n  File \"d:\\FyiersApiAutomation\\websocket\\fyers_websocket_ohlc.py\", line 37, in onmessage\n    ms = message['exch_feed_time']\n         ~~~~~~~^^^^^^^^^^^^^^^^^^\nKeyError: 'exch_feed_time'","exception_name":"KeyError"}
{"level":"ERROR","location":"[On_message:1443] data_ws","message":"KeyError: The key 'exch_feed_time' is missing in the response.","timestamp":"2025-08-27 19:01:06,297+0530","service":"FyersDataSocket"}
{"level":"ERROR","location":"[On_message:1442] data_ws","message":"'exch_feed_time'","timestamp":"2025-08-27 19:01:08,578+0530","service":"FyersDataSocket","exception":"Traceback (most recent call last):\n  File \"C:\\Python311\\Lib\\site-packages\\fyers_apiv3\\FyersWebsocket\\data_ws.py\", line 1433, in On_message\n    self.OnMessage(message)\n  File \"d:\\FyiersApiAutomation\\websocket\\fyers_websocket_ohlc.py\", line 37, in onmessage\n    ms = message['exch_feed_time']\n         ~~~~~~~^^^^^^^^^^^^^^^^^^\nKeyError: 'exch_feed_time'","exception_name":"KeyError"}
{"level":"ERROR","location":"[On_message:1443] data_ws","message":"KeyError: The key 'exch_feed_time' is missing in the response.","timestamp":"2025-08-27 19:01:08,579+0530","service":"FyersDataSocket"}
{"level":"ERROR","location":"[On_message:1442] data_ws","message":"'exch_feed_time'","timestamp":"2025-08-27 19:01:42,854+0530","service":"FyersDataSocket","exception":"Traceback (most recent call last):\n  File \"C:\\Python311\\Lib\\site-packages\\fyers_apiv3\\FyersWebsocket\\data_ws.py\", line 1433, in On_message\n    self.OnMessage(message)\n  File \"d:\\FyiersApiAutomation\\websocket\\fyers_websocket_ohlc.py\", line 37, in onmessage\n    ms = message['exch_feed_time']\n         ~~~~~~~^^^^^^^^^^^^^^^^^^\nKeyError: 'exch_feed_time'","exception_name":"KeyError"}
{"level":"ERROR","location":"[On_message:1443] data_ws","message":"KeyError: The key 'exch_feed_time' is missing in the response.","timestamp":"2025-08-27 19:01:42,854+0530","service":"FyersDataSocket"}
{"level":"ERROR","location":"[On_message:1442] data_ws","message":"'exch_feed_time'","timestamp":"2025-08-27 19:01:42,992+0530","service":"FyersDataSocket","exception":"Traceback (most recent call last):\n  File \"C:\\Python311\\Lib\\site-packages\\fyers_apiv3\\FyersWebsocket\\data_ws.py\", line 1433, in On_message\n    self.OnMessage(message)\n  File \"d:\\FyiersApiAutomation\\websocket\\fyers_websocket_ohlc.py\", line 37, in onmessage\n    ms = message['exch_feed_time']\n         ~~~~~~~^^^^^^^^^^^^^^^^^^\nKeyError: 'exch_feed_time'","exception_name":"KeyError"}
{"level":"ERROR","location":"[On_message:1443] data_ws","message":"KeyError: The key 'exch_feed_time' is missing in the response.","timestamp":"2025-08-27 19:01:43,033+0530","service":"FyersDataSocket"}
{"level":"ERROR","location":"[On_message:1442] data_ws","message":"'exch_feed_time'","timestamp":"2025-08-27 19:01:45,359+0530","service":"FyersDataSocket","exception":"Traceback (most recent call last):\n  File \"C:\\Python311\\Lib\\site-packages\\fyers_apiv3\\FyersWebsocket\\data_ws.py\", line 1433, in On_message\n    self.OnMessage(message)\n  File \"d:\\FyiersApiAutomation\\websocket\\fyers_websocket_ohlc.py\", line 37, in onmessage\n    ms = message['exch_feed_time']\n         ~~~~~~~^^^^^^^^^^^^^^^^^^\nKeyError: 'exch_feed_time'","exception_name":"KeyError"}
{"level":"ERROR","location":"[On_message:1443] data_ws","message":"KeyError: The key 'exch_feed_time' is missing in the response.","timestamp":"2025-08-27 19:01:45,359+0530","service":"FyersDataSocket"}
{"level":"ERROR","location":"[On_message:1442] data_ws","message":"'exch_feed_time'","timestamp":"2025-08-27 19:02:52,416+0530","service":"FyersDataSocket","exception":"Traceback (most recent call last):\n  File \"C:\\Python311\\Lib\\site-packages\\fyers_apiv3\\FyersWebsocket\\data_ws.py\", line 1433, in On_message\n    self.OnMessage(message)\n  File \"d:\\FyiersApiAutomation\\websocket\\fyers_websocket_ohlc.py\", line 37, in onmessage\n    ms = message['exch_feed_time']\n         ~~~~~~~^^^^^^^^^^^^^^^^^^\nKeyError: 'exch_feed_time'","exception_name":"KeyError"}
{"level":"ERROR","location":"[On_message:1443] data_ws","message":"KeyError: The key 'exch_feed_time' is missing in the response.","timestamp":"2025-08-27 19:02:52,416+0530","service":"FyersDataSocket"}
{"level":"ERROR","location":"[On_message:1442] data_ws","message":"'exch_feed_time'","timestamp":"2025-08-27 19:02:52,592+0530","service":"FyersDataSocket","exception":"Traceback (most recent call last):\n  File \"C:\\Python311\\Lib\\site-packages\\fyers_apiv3\\FyersWebsocket\\data_ws.py\", line 1433, in On_message\n    self.OnMessage(message)\n  File \"d:\\FyiersApiAutomation\\websocket\\fyers_websocket_ohlc.py\", line 37, in onmessage\n    ms = message['exch_feed_time']\n         ~~~~~~~^^^^^^^^^^^^^^^^^^\nKeyError: 'exch_feed_time'","exception_name":"KeyError"}
{"level":"ERROR","location":"[On_message:1443] data_ws","message":"KeyError: The key 'exch_feed_time' is missing in the response.","timestamp":"2025-08-27 19:02:52,592+0530","service":"FyersDataSocket"}
{"level":"ERROR","location":"[On_message:1442] data_ws","message":"'exch_feed_time'","timestamp":"2025-08-27 19:02:54,886+0530","service":"FyersDataSocket","exception":"Traceback (most recent call last):\n  File \"C:\\Python311\\Lib\\site-packages\\fyers_apiv3\\FyersWebsocket\\data_ws.py\", line 1433, in On_message\n    self.OnMessage(message)\n  File \"d:\\FyiersApiAutomation\\websocket\\fyers_websocket_ohlc.py\", line 37, in onmessage\n    ms = message['exch_feed_time']\n         ~~~~~~~^^^^^^^^^^^^^^^^^^\nKeyError: 'exch_feed_time'","exception_name":"KeyError"}
{"level":"ERROR","location":"[On_message:1443] data_ws","message":"KeyError: The key 'exch_feed_time' is missing in the response.","timestamp":"2025-08-27 19:02:54,902+0530","service":"FyersDataSocket"}
{"level":"ERROR","location":"[On_message:1442] data_ws","message":"'exch_feed_time'","timestamp":"2025-08-27 19:07:17,740+0530","service":"FyersDataSocket","exception":"Traceback (most recent call last):\n  File \"C:\\Python311\\Lib\\site-packages\\fyers_apiv3\\FyersWebsocket\\data_ws.py\", line 1433, in On_message\n    self.OnMessage(message)\n  File \"d:\\FyiersApiAutomation\\websocket\\fyers_websocket_ohlc.py\", line 37, in onmessage\n    ms = message['exch_feed_time']\n         ~~~~~~~^^^^^^^^^^^^^^^^^^\nKeyError: 'exch_feed_time'","exception_name":"KeyError"}
{"level":"ERROR","location":"[On_message:1443] data_ws","message":"KeyError: The key 'exch_feed_time' is missing in the response.","timestamp":"2025-08-27 19:07:17,740+0530","service":"FyersDataSocket"}
{"level":"ERROR","location":"[On_message:1442] data_ws","message":"'exch_feed_time'","timestamp":"2025-08-27 19:07:17,894+0530","service":"FyersDataSocket","exception":"Traceback (most recent call last):\n  File \"C:\\Python311\\Lib\\site-packages\\fyers_apiv3\\FyersWebsocket\\data_ws.py\", line 1433, in On_message\n    self.OnMessage(message)\n  File \"d:\\FyiersApiAutomation\\websocket\\fyers_websocket_ohlc.py\", line 37, in onmessage\n    ms = message['exch_feed_time']\n         ~~~~~~~^^^^^^^^^^^^^^^^^^\nKeyError: 'exch_feed_time'","exception_name":"KeyError"}
{"level":"ERROR","location":"[On_message:1443] data_ws","message":"KeyError: The key 'exch_feed_time' is missing in the response.","timestamp":"2025-08-27 19:07:17,894+0530","service":"FyersDataSocket"}
{"level":"ERROR","location":"[On_message:1442] data_ws","message":"'exch_feed_time'","timestamp":"2025-08-27 19:07:20,173+0530","service":"FyersDataSocket","exception":"Traceback (most recent call last):\n  File \"C:\\Python311\\Lib\\site-packages\\fyers_apiv3\\FyersWebsocket\\data_ws.py\", line 1433, in On_message\n    self.OnMessage(message)\n  File \"d:\\FyiersApiAutomation\\websocket\\fyers_websocket_ohlc.py\", line 37, in onmessage\n    ms = message['exch_feed_time']\n         ~~~~~~~^^^^^^^^^^^^^^^^^^\nKeyError: 'exch_feed_time'","exception_name":"KeyError"}
{"level":"ERROR","location":"[On_message:1443] data_ws","message":"KeyError: The key 'exch_feed_time' is missing in the response.","timestamp":"2025-08-27 19:07:20,173+0530","service":"FyersDataSocket"}
{"level":"ERROR","location":"[On_message:1442] data_ws","message":"'exch_feed_time'","timestamp":"2025-08-27 19:34:36,322+0530","service":"FyersDataSocket","exception":"Traceback (most recent call last):\n  File \"C:\\Python311\\Lib\\site-packages\\fyers_apiv3\\FyersWebsocket\\data_ws.py\", line 1433, in On_message\n    self.OnMessage(message)\n  File \"d:\\FyiersApiAutomation\\websocket\\fyers_websocket_ohlc.py\", line 38, in onmessage\n    ms = message['exch_feed_time']\n         ~~~~~~~^^^^^^^^^^^^^^^^^^\nKeyError: 'exch_feed_time'","exception_name":"KeyError"}
{"level":"ERROR","location":"[On_message:1443] data_ws","message":"KeyError: The key 'exch_feed_time' is missing in the response.","timestamp":"2025-08-27 19:34:36,324+0530","service":"FyersDataSocket"}
{"level":"ERROR","location":"[On_message:1442] data_ws","message":"'exch_feed_time'","timestamp":"2025-08-27 19:34:36,480+0530","service":"FyersDataSocket","exception":"Traceback (most recent call last):\n  File \"C:\\Python311\\Lib\\site-packages\\fyers_apiv3\\FyersWebsocket\\data_ws.py\", line 1433, in On_message\n    self.OnMessage(message)\n  File \"d:\\FyiersApiAutomation\\websocket\\fyers_websocket_ohlc.py\", line 38, in onmessage\n    ms = message['exch_feed_time']\n         ~~~~~~~^^^^^^^^^^^^^^^^^^\nKeyError: 'exch_feed_time'","exception_name":"KeyError"}
{"level":"ERROR","location":"[On_message:1443] data_ws","message":"KeyError: The key 'exch_feed_time' is missing in the response.","timestamp":"2025-08-27 19:34:36,485+0530","service":"FyersDataSocket"}
{"level":"ERROR","location":"[On_message:1442] data_ws","message":"'exch_feed_time'","timestamp":"2025-08-27 19:34:38,461+0530","service":"FyersDataSocket","exception":"Traceback (most recent call last):\n  File \"C:\\Python311\\Lib\\site-packages\\fyers_apiv3\\FyersWebsocket\\data_ws.py\", line 1433, in On_message\n    self.OnMessage(message)\n  File \"d:\\FyiersApiAutomation\\websocket\\fyers_websocket_ohlc.py\", line 38, in onmessage\n    ms = message['exch_feed_time']\n         ~~~~~~~^^^^^^^^^^^^^^^^^^\nKeyError: 'exch_feed_time'","exception_name":"KeyError"}
{"level":"ERROR","location":"[On_message:1443] data_ws","message":"KeyError: The key 'exch_feed_time' is missing in the response.","timestamp":"2025-08-27 19:34:38,465+0530","service":"FyersDataSocket"}
{"level":"ERROR","location":"[On_message:1442] data_ws","message":"'exch_feed_time'","timestamp":"2025-08-27 19:35:19,946+0530","service":"FyersDataSocket","exception":"Traceback (most recent call last):\n  File \"C:\\Python311\\Lib\\site-packages\\fyers_apiv3\\FyersWebsocket\\data_ws.py\", line 1433, in On_message\n    self.OnMessage(message)\n  File \"d:\\FyiersApiAutomation\\websocket\\fyers_websocket_ohlc.py\", line 38, in onmessage\n    ms = message['exch_feed_time']\n         ~~~~~~~^^^^^^^^^^^^^^^^^^\nKeyError: 'exch_feed_time'","exception_name":"KeyError"}
{"level":"ERROR","location":"[On_message:1443] data_ws","message":"KeyError: The key 'exch_feed_time' is missing in the response.","timestamp":"2025-08-27 19:35:19,946+0530","service":"FyersDataSocket"}
{"level":"ERROR","location":"[On_message:1442] data_ws","message":"'exch_feed_time'","timestamp":"2025-08-27 19:35:20,384+0530","service":"FyersDataSocket","exception":"Traceback (most recent call last):\n  File \"C:\\Python311\\Lib\\site-packages\\fyers_apiv3\\FyersWebsocket\\data_ws.py\", line 1433, in On_message\n    self.OnMessage(message)\n  File \"d:\\FyiersApiAutomation\\websocket\\fyers_websocket_ohlc.py\", line 38, in onmessage\n    ms = message['exch_feed_time']\n         ~~~~~~~^^^^^^^^^^^^^^^^^^\nKeyError: 'exch_feed_time'","exception_name":"KeyError"}
{"level":"ERROR","location":"[On_message:1443] data_ws","message":"KeyError: The key 'exch_feed_time' is missing in the response.","timestamp":"2025-08-27 19:35:20,384+0530","service":"FyersDataSocket"}
{"level":"ERROR","location":"[On_message:1442] data_ws","message":"'exch_feed_time'","timestamp":"2025-08-27 19:35:22,084+0530","service":"FyersDataSocket","exception":"Traceback (most recent call last):\n  File \"C:\\Python311\\Lib\\site-packages\\fyers_apiv3\\FyersWebsocket\\data_ws.py\", line 1433, in On_message\n    self.OnMessage(message)\n  File \"d:\\FyiersApiAutomation\\websocket\\fyers_websocket_ohlc.py\", line 38, in onmessage\n    ms = message['exch_feed_time']\n         ~~~~~~~^^^^^^^^^^^^^^^^^^\nKeyError: 'exch_feed_time'","exception_name":"KeyError"}
{"level":"ERROR","location":"[On_message:1443] data_ws","message":"KeyError: The key 'exch_feed_time' is missing in the response.","timestamp":"2025-08-27 19:35:22,084+0530","service":"FyersDataSocket"}
{"level":"ERROR","location":"[<lambda>:1663] data_ws","message":"Connection to remote host was lost.","timestamp":"2025-08-27 20:42:41,203+0530","service":"FyersDataSocket"}
{"level":"ERROR","location":"[<lambda>:1663] data_ws","message":"[Errno 11001] getaddrinfo failed","timestamp":"2025-08-27 20:42:46,206+0530","service":"FyersDataSocket"}
{"level":"ERROR","location":"[symbol_to_hsmtoken:126] data_ws","message":"HTTPSConnectionPool(host='api-t1.fyers.in', port=443): Max retries exceeded with url: /data/symbol-token (Caused by NameResolutionError(\"<urllib3.connection.HTTPSConnection object at 0x0000020F6EFF2990>: Failed to resolve 'api-t1.fyers.in' ([Errno 11001] getaddrinfo failed)\"))","timestamp":"2025-08-27 20:42:48,209+0530","service":"FyersDataSocket","exception":"Traceback (most recent call last):\n  File \"C:\\Python311\\Lib\\site-packages\\websocket\\_app.py\", line 428, in setSock\n    dispatcher.read(self.sock.sock, read, check)\n  File \"C:\\Python311\\Lib\\site-packages\\websocket\\_app.py\", line 99, in read\n    if not read_callback():\n           ^^^^^^^^^^^^^^^\n  File \"C:\\Python311\\Lib\\site-packages\\websocket\\_app.py\", line 442, in read\n    raise e\n  File \"C:\\Python311\\Lib\\site-packages\\websocket\\_app.py\", line 437, in read\n    op_code, frame = self.sock.recv_data_frame(True)\n                     ^^^^^^^^^^^^^^^^^^^^^^^^^^^^^^^\n  File \"C:\\Python311\\Lib\\site-packages\\websocket\\_core.py\", line 406, in recv_data_frame\n    frame = self.recv_frame()\n            ^^^^^^^^^^^^^^^^^\n  File \"C:\\Python311\\Lib\\site-packages\\websocket\\_core.py\", line 445, in recv_frame\n    return self.frame_buffer.recv_frame()\n           ^^^^^^^^^^^^^^^^^^^^^^^^^^^^^^\n  File \"C:\\Python311\\Lib\\site-packages\\websocket\\_abnf.py\", line 338, in recv_frame\n    self.recv_header()\n  File \"C:\\Python311\\Lib\\site-packages\\websocket\\_abnf.py\", line 294, in recv_header\n    header = self.recv_strict(2)\n             ^^^^^^^^^^^^^^^^^^^\n  File \"C:\\Python311\\Lib\\site-packages\\websocket\\_abnf.py\", line 373, in recv_strict\n    bytes_ = self.recv(min(16384, shortage))\n             ^^^^^^^^^^^^^^^^^^^^^^^^^^^^^^^\n  File \"C:\\Python311\\Lib\\site-packages\\websocket\\_core.py\", line 529, in _recv\n    return recv(self.sock, bufsize)\n           ^^^^^^^^^^^^^^^^^^^^^^^^\n  File \"C:\\Python311\\Lib\\site-packages\\websocket\\_socket.py\", line 122, in recv\n    raise WebSocketConnectionClosedException(\nwebsocket._exceptions.WebSocketConnectionClosedException: Connection to remote host was lost.\n\nDuring handling of the above exception, another exception occurred:\n\nTraceback (most recent call last):\n  File \"C:\\Python311\\Lib\\site-packages\\urllib3\\connection.py\", line 203, in _new_conn\n    sock = connection.create_connection(\n           ^^^^^^^^^^^^^^^^^^^^^^^^^^^^^\n  File \"C:\\Python311\\Lib\\site-packages\\urllib3\\util\\connection.py\", line 60, in create_connection\n    for res in socket.getaddrinfo(host, port, family, socket.SOCK_STREAM):\n               ^^^^^^^^^^^^^^^^^^^^^^^^^^^^^^^^^^^^^^^^^^^^^^^^^^^^^^^^^^\n  File \"C:\\Python311\\Lib\\socket.py\", line 962, in getaddrinfo\n    for res in _socket.getaddrinfo(host, port, family, type, proto, flags):\n               ^^^^^^^^^^^^^^^^^^^^^^^^^^^^^^^^^^^^^^^^^^^^^^^^^^^^^^^^^^^\nsocket.gaierror: [Errno 11001] getaddrinfo failed\n\nThe above exception was the direct cause of the following exception:\n\nTraceback (most recent call last):\n  File \"C:\\Python311\\Lib\\site-packages\\urllib3\\connectionpool.py\", line 790, in urlopen\n    response = self._make_request(\n               ^^^^^^^^^^^^^^^^^^^\n  File \"C:\\Python311\\Lib\\site-packages\\urllib3\\connectionpool.py\", line 491, in _make_request\n    raise new_e\n  File \"C:\\Python311\\Lib\\site-packages\\urllib3\\connectionpool.py\", line 467, in _make_request\n    self._validate_conn(conn)\n  File \"C:\\Python311\\Lib\\site-packages\\urllib3\\connectionpool.py\", line 1092, in _validate_conn\n    conn.connect()\n  File \"C:\\Python311\\Lib\\site-packages\\urllib3\\connection.py\", line 611, in connect\n    self.sock = sock = self._new_conn()\n                       ^^^^^^^^^^^^^^^^\n  File \"C:\\Python311\\Lib\\site-packages\\urllib3\\connection.py\", line 210, in _new_conn\n    raise NameResolutionError(self.host, self, e) from e\nurllib3.exceptions.NameResolutionError: <urllib3.connection.HTTPSConnection object at 0x0000020F6EFF2990>: Failed to resolve 'api-t1.fyers.in' ([Errno 11001] getaddrinfo failed)\n\nThe above exception was the direct cause of the following exception:\n\nTraceback (most recent call last):\n  File \"C:\\Python311\\Lib\\site-packages\\requests\\adapters.py\", line 486, in send\n    resp = conn.urlopen(\n           ^^^^^^^^^^^^^\n  File \"C:\\Python311\\Lib\\site-packages\\urllib3\\connectionpool.py\", line 844, in urlopen\n    retries = retries.increment(\n              ^^^^^^^^^^^^^^^^^^\n  File \"C:\\Python311\\Lib\\site-packages\\urllib3\\util\\retry.py\", line 515, in increment\n    raise MaxRetryError(_pool, url, reason) from reason  # type: ignore[arg-type]\n    ^^^^^^^^^^^^^^^^^^^^^^^^^^^^^^^^^^^^^^^^^^^^^^^^^^^\nurllib3.exceptions.MaxRetryError: HTTPSConnectionPool(host='api-t1.fyers.in', port=443): Max retries exceeded with url: /data/symbol-token (Caused by NameResolutionError(\"<urllib3.connection.HTTPSConnection object at 0x0000020F6EFF2990>: Failed to resolve 'api-t1.fyers.in' ([Errno 11001] getaddrinfo failed)\"))\n\nDuring handling of the above exception, another exception occurred:\n\nTraceback (most recent call last):\n  File \"C:\\Python311\\Lib\\site-packages\\fyers_apiv3\\FyersWebsocket\\data_ws.py\", line 63, in symbol_to_hsmtoken\n    response = requests.post(\n               ^^^^^^^^^^^^^^\n  File \"C:\\Python311\\Lib\\site-packages\\requests\\api.py\", line 115, in post\n    return request(\"post\", url, data=data, json=json, **kwargs)\n           ^^^^^^^^^^^^^^^^^^^^^^^^^^^^^^^^^^^^^^^^^^^^^^^^^^^^\n  File \"C:\\Python311\\Lib\\site-packages\\requests\\api.py\", line 59, in request\n    return session.request(method=method, url=url, **kwargs)\n           ^^^^^^^^^^^^^^^^^^^^^^^^^^^^^^^^^^^^^^^^^^^^^^^^^\n  File \"C:\\Python311\\Lib\\site-packages\\requests\\sessions.py\", line 589, in request\n    resp = self.send(prep, **send_kwargs)\n           ^^^^^^^^^^^^^^^^^^^^^^^^^^^^^^\n  File \"C:\\Python311\\Lib\\site-packages\\requests\\sessions.py\", line 703, in send\n    r = adapter.send(request, **kwargs)\n        ^^^^^^^^^^^^^^^^^^^^^^^^^^^^^^^\n  File \"C:\\Python311\\Lib\\site-packages\\requests\\adapters.py\", line 519, in send\n    raise ConnectionError(e, request=request)\nrequests.exceptions.ConnectionError: HTTPSConnectionPool(host='api-t1.fyers.in', port=443): Max retries exceeded with url: /data/symbol-token (Caused by NameResolutionError(\"<urllib3.connection.HTTPSConnection object at 0x0000020F6EFF2990>: Failed to resolve 'api-t1.fyers.in' ([Errno 11001] getaddrinfo failed)\"))","exception_name":"ConnectionError"}
{"level":"ERROR","location":"[__symbol_conversion:1374] data_ws","message":"'NoneType' object is not subscriptable","timestamp":"2025-08-27 20:42:48,235+0530","service":"FyersDataSocket","exception":"Traceback (most recent call last):\n  File \"C:\\Python311\\Lib\\site-packages\\websocket\\_app.py\", line 428, in setSock\n    dispatcher.read(self.sock.sock, read, check)\n  File \"C:\\Python311\\Lib\\site-packages\\websocket\\_app.py\", line 99, in read\n    if not read_callback():\n           ^^^^^^^^^^^^^^^\n  File \"C:\\Python311\\Lib\\site-packages\\websocket\\_app.py\", line 442, in read\n    raise e\n  File \"C:\\Python311\\Lib\\site-packages\\websocket\\_app.py\", line 437, in read\n    op_code, frame = self.sock.recv_data_frame(True)\n                     ^^^^^^^^^^^^^^^^^^^^^^^^^^^^^^^\n  File \"C:\\Python311\\Lib\\site-packages\\websocket\\_core.py\", line 406, in recv_data_frame\n    frame = self.recv_frame()\n            ^^^^^^^^^^^^^^^^^\n  File \"C:\\Python311\\Lib\\site-packages\\websocket\\_core.py\", line 445, in recv_frame\n    return self.frame_buffer.recv_frame()\n           ^^^^^^^^^^^^^^^^^^^^^^^^^^^^^^\n  File \"C:\\Python311\\Lib\\site-packages\\websocket\\_abnf.py\", line 338, in recv_frame\n    self.recv_header()\n  File \"C:\\Python311\\Lib\\site-packages\\websocket\\_abnf.py\", line 294, in recv_header\n    header = self.recv_strict(2)\n             ^^^^^^^^^^^^^^^^^^^\n  File \"C:\\Python311\\Lib\\site-packages\\websocket\\_abnf.py\", line 373, in recv_strict\n    bytes_ = self.recv(min(16384, shortage))\n             ^^^^^^^^^^^^^^^^^^^^^^^^^^^^^^^\n  File \"C:\\Python311\\Lib\\site-packages\\websocket\\_core.py\", line 529, in _recv\n    return recv(self.sock, bufsize)\n           ^^^^^^^^^^^^^^^^^^^^^^^^\n  File \"C:\\Python311\\Lib\\site-packages\\websocket\\_socket.py\", line 122, in recv\n    raise WebSocketConnectionClosedException(\nwebsocket._exceptions.WebSocketConnectionClosedException: Connection to remote host was lost.\n\nDuring handling of the above exception, another exception occurred:\n\nTraceback (most recent call last):\n  File \"C:\\Python311\\Lib\\site-packages\\fyers_apiv3\\FyersWebsocket\\data_ws.py\", line 1333, in __symbol_conversion\n    if symbol_value[3] != \"\":\n       ~~~~~~~~~~~~^^^\nTypeError: 'NoneType' object is not subscriptable","exception_name":"TypeError"}
{"level":"ERROR","location":"[<lambda>:1663] data_ws","message":"[Errno 11001] getaddrinfo failed","timestamp":"2025-08-27 20:42:51,209+0530","service":"FyersDataSocket"}
{"level":"ERROR","location":"[symbol_to_hsmtoken:126] data_ws","message":"HTTPSConnectionPool(host='api-t1.fyers.in', port=443): Max retries exceeded with url: /data/symbol-token (Caused by NameResolutionError(\"<urllib3.connection.HTTPSConnection object at 0x0000020F6F410910>: Failed to resolve 'api-t1.fyers.in' ([Errno 11001] getaddrinfo failed)\"))","timestamp":"2025-08-27 20:42:53,210+0530","service":"FyersDataSocket","exception":"Traceback (most recent call last):\n  File \"C:\\Python311\\Lib\\site-packages\\websocket\\_http.py\", line 155, in _get_addrinfo_list\n    addrinfo_list = socket.getaddrinfo(\n                    ^^^^^^^^^^^^^^^^^^^\n  File \"C:\\Python311\\Lib\\socket.py\", line 962, in getaddrinfo\n    for res in _socket.getaddrinfo(host, port, family, type, proto, flags):\n               ^^^^^^^^^^^^^^^^^^^^^^^^^^^^^^^^^^^^^^^^^^^^^^^^^^^^^^^^^^^\nsocket.gaierror: [Errno 11001] getaddrinfo failed\n\nDuring handling of the above exception, another exception occurred:\n\nTraceback (most recent call last):\n  File \"C:\\Python311\\Lib\\site-packages\\websocket\\_app.py\", line 412, in setSock\n    self.sock.connect(\n  File \"C:\\Python311\\Lib\\site-packages\\websocket\\_core.py\", line 249, in connect\n    self.sock, addrs = connect(url, self.sock_opt, proxy_info(**options),\n                       ^^^^^^^^^^^^^^^^^^^^^^^^^^^^^^^^^^^^^^^^^^^^^^^^^^\n  File \"C:\\Python311\\Lib\\site-packages\\websocket\\_http.py\", line 122, in connect\n    addrinfo_list, need_tunnel, auth = _get_addrinfo_list(\n                                       ^^^^^^^^^^^^^^^^^^^\n  File \"C:\\Python311\\Lib\\site-packages\\websocket\\_http.py\", line 167, in _get_addrinfo_list\n    raise WebSocketAddressException(e)\nwebsocket._exceptions.WebSocketAddressException: [Errno 11001] getaddrinfo failed\n\nDuring handling of the above exception, another exception occurred:\n\nTraceback (most recent call last):\n  File \"C:\\Python311\\Lib\\site-packages\\urllib3\\connection.py\", line 203, in _new_conn\n    sock = connection.create_connection(\n           ^^^^^^^^^^^^^^^^^^^^^^^^^^^^^\n  File \"C:\\Python311\\Lib\\site-packages\\urllib3\\util\\connection.py\", line 60, in create_connection\n    for res in socket.getaddrinfo(host, port, family, socket.SOCK_STREAM):\n               ^^^^^^^^^^^^^^^^^^^^^^^^^^^^^^^^^^^^^^^^^^^^^^^^^^^^^^^^^^\n  File \"C:\\Python311\\Lib\\socket.py\", line 962, in getaddrinfo\n    for res in _socket.getaddrinfo(host, port, family, type, proto, flags):\n               ^^^^^^^^^^^^^^^^^^^^^^^^^^^^^^^^^^^^^^^^^^^^^^^^^^^^^^^^^^^\nsocket.gaierror: [Errno 11001] getaddrinfo failed\n\nThe above exception was the direct cause of the following exception:\n\nTraceback (most recent call last):\n  File \"C:\\Python311\\Lib\\site-packages\\urllib3\\connectionpool.py\", line 790, in urlopen\n    response = self._make_request(\n               ^^^^^^^^^^^^^^^^^^^\n  File \"C:\\Python311\\Lib\\site-packages\\urllib3\\connectionpool.py\", line 491, in _make_request\n    raise new_e\n  File \"C:\\Python311\\Lib\\site-packages\\urllib3\\connectionpool.py\", line 467, in _make_request\n    self._validate_conn(conn)\n  File \"C:\\Python311\\Lib\\site-packages\\urllib3\\connectionpool.py\", line 1092, in _validate_conn\n    conn.connect()\n  File \"C:\\Python311\\Lib\\site-packages\\urllib3\\connection.py\", line 611, in connect\n    self.sock = sock = self._new_conn()\n                       ^^^^^^^^^^^^^^^^\n  File \"C:\\Python311\\Lib\\site-packages\\urllib3\\connection.py\", line 210, in _new_conn\n    raise NameResolutionError(self.host, self, e) from e\nurllib3.exceptions.NameResolutionError: <urllib3.connection.HTTPSConnection object at 0x0000020F6F410910>: Failed to resolve 'api-t1.fyers.in' ([Errno 11001] getaddrinfo failed)\n\nThe above exception was the direct cause of the following exception:\n\nTraceback (most recent call last):\n  File \"C:\\Python311\\Lib\\site-packages\\requests\\adapters.py\", line 486, in send\n    resp = conn.urlopen(\n           ^^^^^^^^^^^^^\n  File \"C:\\Python311\\Lib\\site-packages\\urllib3\\connectionpool.py\", line 844, in urlopen\n    retries = retries.increment(\n              ^^^^^^^^^^^^^^^^^^\n  File \"C:\\Python311\\Lib\\site-packages\\urllib3\\util\\retry.py\", line 515, in increment\n    raise MaxRetryError(_pool, url, reason) from reason  # type: ignore[arg-type]\n    ^^^^^^^^^^^^^^^^^^^^^^^^^^^^^^^^^^^^^^^^^^^^^^^^^^^\nurllib3.exceptions.MaxRetryError: HTTPSConnectionPool(host='api-t1.fyers.in', port=443): Max retries exceeded with url: /data/symbol-token (Caused by NameResolutionError(\"<urllib3.connection.HTTPSConnection object at 0x0000020F6F410910>: Failed to resolve 'api-t1.fyers.in' ([Errno 11001] getaddrinfo failed)\"))\n\nDuring handling of the above exception, another exception occurred:\n\nTraceback (most recent call last):\n  File \"C:\\Python311\\Lib\\site-packages\\fyers_apiv3\\FyersWebsocket\\data_ws.py\", line 63, in symbol_to_hsmtoken\n    response = requests.post(\n               ^^^^^^^^^^^^^^\n  File \"C:\\Python311\\Lib\\site-packages\\requests\\api.py\", line 115, in post\n    return request(\"post\", url, data=data, json=json, **kwargs)\n           ^^^^^^^^^^^^^^^^^^^^^^^^^^^^^^^^^^^^^^^^^^^^^^^^^^^^\n  File \"C:\\Python311\\Lib\\site-packages\\requests\\api.py\", line 59, in request\n    return session.request(method=method, url=url, **kwargs)\n           ^^^^^^^^^^^^^^^^^^^^^^^^^^^^^^^^^^^^^^^^^^^^^^^^^\n  File \"C:\\Python311\\Lib\\site-packages\\requests\\sessions.py\", line 589, in request\n    resp = self.send(prep, **send_kwargs)\n           ^^^^^^^^^^^^^^^^^^^^^^^^^^^^^^\n  File \"C:\\Python311\\Lib\\site-packages\\requests\\sessions.py\", line 703, in send\n    r = adapter.send(request, **kwargs)\n        ^^^^^^^^^^^^^^^^^^^^^^^^^^^^^^^\n  File \"C:\\Python311\\Lib\\site-packages\\requests\\adapters.py\", line 519, in send\n    raise ConnectionError(e, request=request)\nrequests.exceptions.ConnectionError: HTTPSConnectionPool(host='api-t1.fyers.in', port=443): Max retries exceeded with url: /data/symbol-token (Caused by NameResolutionError(\"<urllib3.connection.HTTPSConnection object at 0x0000020F6F410910>: Failed to resolve 'api-t1.fyers.in' ([Errno 11001] getaddrinfo failed)\"))","exception_name":"ConnectionError"}
{"level":"ERROR","location":"[__symbol_conversion:1374] data_ws","message":"'NoneType' object is not subscriptable","timestamp":"2025-08-27 20:42:53,220+0530","service":"FyersDataSocket","exception":"Traceback (most recent call last):\n  File \"C:\\Python311\\Lib\\site-packages\\websocket\\_http.py\", line 155, in _get_addrinfo_list\n    addrinfo_list = socket.getaddrinfo(\n                    ^^^^^^^^^^^^^^^^^^^\n  File \"C:\\Python311\\Lib\\socket.py\", line 962, in getaddrinfo\n    for res in _socket.getaddrinfo(host, port, family, type, proto, flags):\n               ^^^^^^^^^^^^^^^^^^^^^^^^^^^^^^^^^^^^^^^^^^^^^^^^^^^^^^^^^^^\nsocket.gaierror: [Errno 11001] getaddrinfo failed\n\nDuring handling of the above exception, another exception occurred:\n\nTraceback (most recent call last):\n  File \"C:\\Python311\\Lib\\site-packages\\websocket\\_app.py\", line 412, in setSock\n    self.sock.connect(\n  File \"C:\\Python311\\Lib\\site-packages\\websocket\\_core.py\", line 249, in connect\n    self.sock, addrs = connect(url, self.sock_opt, proxy_info(**options),\n                       ^^^^^^^^^^^^^^^^^^^^^^^^^^^^^^^^^^^^^^^^^^^^^^^^^^\n  File \"C:\\Python311\\Lib\\site-packages\\websocket\\_http.py\", line 122, in connect\n    addrinfo_list, need_tunnel, auth = _get_addrinfo_list(\n                                       ^^^^^^^^^^^^^^^^^^^\n  File \"C:\\Python311\\Lib\\site-packages\\websocket\\_http.py\", line 167, in _get_addrinfo_list\n    raise WebSocketAddressException(e)\nwebsocket._exceptions.WebSocketAddressException: [Errno 11001] getaddrinfo failed\n\nDuring handling of the above exception, another exception occurred:\n\nTraceback (most recent call last):\n  File \"C:\\Python311\\Lib\\site-packages\\fyers_apiv3\\FyersWebsocket\\data_ws.py\", line 1333, in __symbol_conversion\n    if symbol_value[3] != \"\":\n       ~~~~~~~~~~~~^^^\nTypeError: 'NoneType' object is not subscriptable","exception_name":"TypeError"}
{"level":"ERROR","location":"[<lambda>:1663] data_ws","message":"[Errno 11001] getaddrinfo failed","timestamp":"2025-08-27 20:42:56,212+0530","service":"FyersDataSocket"}
{"level":"ERROR","location":"[symbol_to_hsmtoken:126] data_ws","message":"HTTPSConnectionPool(host='api-t1.fyers.in', port=443): Max retries exceeded with url: /data/symbol-token (Caused by NameResolutionError(\"<urllib3.connection.HTTPSConnection object at 0x0000020F6EFF29D0>: Failed to resolve 'api-t1.fyers.in' ([Errno 11001] getaddrinfo failed)\"))","timestamp":"2025-08-27 20:42:58,223+0530","service":"FyersDataSocket","exception":"Traceback (most recent call last):\n  File \"C:\\Python311\\Lib\\site-packages\\websocket\\_http.py\", line 155, in _get_addrinfo_list\n    addrinfo_list = socket.getaddrinfo(\n                    ^^^^^^^^^^^^^^^^^^^\n  File \"C:\\Python311\\Lib\\socket.py\", line 962, in getaddrinfo\n    for res in _socket.getaddrinfo(host, port, family, type, proto, flags):\n               ^^^^^^^^^^^^^^^^^^^^^^^^^^^^^^^^^^^^^^^^^^^^^^^^^^^^^^^^^^^\nsocket.gaierror: [Errno 11001] getaddrinfo failed\n\nDuring handling of the above exception, another exception occurred:\n\nTraceback (most recent call last):\n  File \"C:\\Python311\\Lib\\site-packages\\websocket\\_app.py\", line 412, in setSock\n    self.sock.connect(\n  File \"C:\\Python311\\Lib\\site-packages\\websocket\\_core.py\", line 249, in connect\n    self.sock, addrs = connect(url, self.sock_opt, proxy_info(**options),\n                       ^^^^^^^^^^^^^^^^^^^^^^^^^^^^^^^^^^^^^^^^^^^^^^^^^^\n  File \"C:\\Python311\\Lib\\site-packages\\websocket\\_http.py\", line 122, in connect\n    addrinfo_list, need_tunnel, auth = _get_addrinfo_list(\n                                       ^^^^^^^^^^^^^^^^^^^\n  File \"C:\\Python311\\Lib\\site-packages\\websocket\\_http.py\", line 167, in _get_addrinfo_list\n    raise WebSocketAddressException(e)\nwebsocket._exceptions.WebSocketAddressException: [Errno 11001] getaddrinfo failed\n\nDuring handling of the above exception, another exception occurred:\n\nTraceback (most recent call last):\n  File \"C:\\Python311\\Lib\\site-packages\\urllib3\\connection.py\", line 203, in _new_conn\n    sock = connection.create_connection(\n           ^^^^^^^^^^^^^^^^^^^^^^^^^^^^^\n  File \"C:\\Python311\\Lib\\site-packages\\urllib3\\util\\connection.py\", line 60, in create_connection\n    for res in socket.getaddrinfo(host, port, family, socket.SOCK_STREAM):\n               ^^^^^^^^^^^^^^^^^^^^^^^^^^^^^^^^^^^^^^^^^^^^^^^^^^^^^^^^^^\n  File \"C:\\Python311\\Lib\\socket.py\", line 962, in getaddrinfo\n    for res in _socket.getaddrinfo(host, port, family, type, proto, flags):\n               ^^^^^^^^^^^^^^^^^^^^^^^^^^^^^^^^^^^^^^^^^^^^^^^^^^^^^^^^^^^\nsocket.gaierror: [Errno 11001] getaddrinfo failed\n\nThe above exception was the direct cause of the following exception:\n\nTraceback (most recent call last):\n  File \"C:\\Python311\\Lib\\site-packages\\urllib3\\connectionpool.py\", line 790, in urlopen\n    response = self._make_request(\n               ^^^^^^^^^^^^^^^^^^^\n  File \"C:\\Python311\\Lib\\site-packages\\urllib3\\connectionpool.py\", line 491, in _make_request\n    raise new_e\n  File \"C:\\Python311\\Lib\\site-packages\\urllib3\\connectionpool.py\", line 467, in _make_request\n    self._validate_conn(conn)\n  File \"C:\\Python311\\Lib\\site-packages\\urllib3\\connectionpool.py\", line 1092, in _validate_conn\n    conn.connect()\n  File \"C:\\Python311\\Lib\\site-packages\\urllib3\\connection.py\", line 611, in connect\n    self.sock = sock = self._new_conn()\n                       ^^^^^^^^^^^^^^^^\n  File \"C:\\Python311\\Lib\\site-packages\\urllib3\\connection.py\", line 210, in _new_conn\n    raise NameResolutionError(self.host, self, e) from e\nurllib3.exceptions.NameResolutionError: <urllib3.connection.HTTPSConnection object at 0x0000020F6EFF29D0>: Failed to resolve 'api-t1.fyers.in' ([Errno 11001] getaddrinfo failed)\n\nThe above exception was the direct cause of the following exception:\n\nTraceback (most recent call last):\n  File \"C:\\Python311\\Lib\\site-packages\\requests\\adapters.py\", line 486, in send\n    resp = conn.urlopen(\n           ^^^^^^^^^^^^^\n  File \"C:\\Python311\\Lib\\site-packages\\urllib3\\connectionpool.py\", line 844, in urlopen\n    retries = retries.increment(\n              ^^^^^^^^^^^^^^^^^^\n  File \"C:\\Python311\\Lib\\site-packages\\urllib3\\util\\retry.py\", line 515, in increment\n    raise MaxRetryError(_pool, url, reason) from reason  # type: ignore[arg-type]\n    ^^^^^^^^^^^^^^^^^^^^^^^^^^^^^^^^^^^^^^^^^^^^^^^^^^^\nurllib3.exceptions.MaxRetryError: HTTPSConnectionPool(host='api-t1.fyers.in', port=443): Max retries exceeded with url: /data/symbol-token (Caused by NameResolutionError(\"<urllib3.connection.HTTPSConnection object at 0x0000020F6EFF29D0>: Failed to resolve 'api-t1.fyers.in' ([Errno 11001] getaddrinfo failed)\"))\n\nDuring handling of the above exception, another exception occurred:\n\nTraceback (most recent call last):\n  File \"C:\\Python311\\Lib\\site-packages\\fyers_apiv3\\FyersWebsocket\\data_ws.py\", line 63, in symbol_to_hsmtoken\n    response = requests.post(\n               ^^^^^^^^^^^^^^\n  File \"C:\\Python311\\Lib\\site-packages\\requests\\api.py\", line 115, in post\n    return request(\"post\", url, data=data, json=json, **kwargs)\n           ^^^^^^^^^^^^^^^^^^^^^^^^^^^^^^^^^^^^^^^^^^^^^^^^^^^^\n  File \"C:\\Python311\\Lib\\site-packages\\requests\\api.py\", line 59, in request\n    return session.request(method=method, url=url, **kwargs)\n           ^^^^^^^^^^^^^^^^^^^^^^^^^^^^^^^^^^^^^^^^^^^^^^^^^\n  File \"C:\\Python311\\Lib\\site-packages\\requests\\sessions.py\", line 589, in request\n    resp = self.send(prep, **send_kwargs)\n           ^^^^^^^^^^^^^^^^^^^^^^^^^^^^^^\n  File \"C:\\Python311\\Lib\\site-packages\\requests\\sessions.py\", line 703, in send\n    r = adapter.send(request, **kwargs)\n        ^^^^^^^^^^^^^^^^^^^^^^^^^^^^^^^\n  File \"C:\\Python311\\Lib\\site-packages\\requests\\adapters.py\", line 519, in send\n    raise ConnectionError(e, request=request)\nrequests.exceptions.ConnectionError: HTTPSConnectionPool(host='api-t1.fyers.in', port=443): Max retries exceeded with url: /data/symbol-token (Caused by NameResolutionError(\"<urllib3.connection.HTTPSConnection object at 0x0000020F6EFF29D0>: Failed to resolve 'api-t1.fyers.in' ([Errno 11001] getaddrinfo failed)\"))","exception_name":"ConnectionError"}
{"level":"ERROR","location":"[__symbol_conversion:1374] data_ws","message":"'NoneType' object is not subscriptable","timestamp":"2025-08-27 20:42:58,226+0530","service":"FyersDataSocket","exception":"Traceback (most recent call last):\n  File \"C:\\Python311\\Lib\\site-packages\\websocket\\_http.py\", line 155, in _get_addrinfo_list\n    addrinfo_list = socket.getaddrinfo(\n                    ^^^^^^^^^^^^^^^^^^^\n  File \"C:\\Python311\\Lib\\socket.py\", line 962, in getaddrinfo\n    for res in _socket.getaddrinfo(host, port, family, type, proto, flags):\n               ^^^^^^^^^^^^^^^^^^^^^^^^^^^^^^^^^^^^^^^^^^^^^^^^^^^^^^^^^^^\nsocket.gaierror: [Errno 11001] getaddrinfo failed\n\nDuring handling of the above exception, another exception occurred:\n\nTraceback (most recent call last):\n  File \"C:\\Python311\\Lib\\site-packages\\websocket\\_app.py\", line 412, in setSock\n    self.sock.connect(\n  File \"C:\\Python311\\Lib\\site-packages\\websocket\\_core.py\", line 249, in connect\n    self.sock, addrs = connect(url, self.sock_opt, proxy_info(**options),\n                       ^^^^^^^^^^^^^^^^^^^^^^^^^^^^^^^^^^^^^^^^^^^^^^^^^^\n  File \"C:\\Python311\\Lib\\site-packages\\websocket\\_http.py\", line 122, in connect\n    addrinfo_list, need_tunnel, auth = _get_addrinfo_list(\n                                       ^^^^^^^^^^^^^^^^^^^\n  File \"C:\\Python311\\Lib\\site-packages\\websocket\\_http.py\", line 167, in _get_addrinfo_list\n    raise WebSocketAddressException(e)\nwebsocket._exceptions.WebSocketAddressException: [Errno 11001] getaddrinfo failed\n\nDuring handling of the above exception, another exception occurred:\n\nTraceback (most recent call last):\n  File \"C:\\Python311\\Lib\\site-packages\\fyers_apiv3\\FyersWebsocket\\data_ws.py\", line 1333, in __symbol_conversion\n    if symbol_value[3] != \"\":\n       ~~~~~~~~~~~~^^^\nTypeError: 'NoneType' object is not subscriptable","exception_name":"TypeError"}
{"level":"ERROR","location":"[<lambda>:1663] data_ws","message":"[Errno 11001] getaddrinfo failed","timestamp":"2025-08-27 20:43:01,216+0530","service":"FyersDataSocket"}
{"level":"ERROR","location":"[symbol_to_hsmtoken:126] data_ws","message":"HTTPSConnectionPool(host='api-t1.fyers.in', port=443): Max retries exceeded with url: /data/symbol-token (Caused by NameResolutionError(\"<urllib3.connection.HTTPSConnection object at 0x0000020F6F410890>: Failed to resolve 'api-t1.fyers.in' ([Errno 11001] getaddrinfo failed)\"))","timestamp":"2025-08-27 20:43:03,217+0530","service":"FyersDataSocket","exception":"Traceback (most recent call last):\n  File \"C:\\Python311\\Lib\\site-packages\\websocket\\_http.py\", line 155, in _get_addrinfo_list\n    addrinfo_list = socket.getaddrinfo(\n                    ^^^^^^^^^^^^^^^^^^^\n  File \"C:\\Python311\\Lib\\socket.py\", line 962, in getaddrinfo\n    for res in _socket.getaddrinfo(host, port, family, type, proto, flags):\n               ^^^^^^^^^^^^^^^^^^^^^^^^^^^^^^^^^^^^^^^^^^^^^^^^^^^^^^^^^^^\nsocket.gaierror: [Errno 11001] getaddrinfo failed\n\nDuring handling of the above exception, another exception occurred:\n\nTraceback (most recent call last):\n  File \"C:\\Python311\\Lib\\site-packages\\websocket\\_app.py\", line 412, in setSock\n    self.sock.connect(\n  File \"C:\\Python311\\Lib\\site-packages\\websocket\\_core.py\", line 249, in connect\n    self.sock, addrs = connect(url, self.sock_opt, proxy_info(**options),\n                       ^^^^^^^^^^^^^^^^^^^^^^^^^^^^^^^^^^^^^^^^^^^^^^^^^^\n  File \"C:\\Python311\\Lib\\site-packages\\websocket\\_http.py\", line 122, in connect\n    addrinfo_list, need_tunnel, auth = _get_addrinfo_list(\n                                       ^^^^^^^^^^^^^^^^^^^\n  File \"C:\\Python311\\Lib\\site-packages\\websocket\\_http.py\", line 167, in _get_addrinfo_list\n    raise WebSocketAddressException(e)\nwebsocket._exceptions.WebSocketAddressException: [Errno 11001] getaddrinfo failed\n\nDuring handling of the above exception, another exception occurred:\n\nTraceback (most recent call last):\n  File \"C:\\Python311\\Lib\\site-packages\\urllib3\\connection.py\", line 203, in _new_conn\n    sock = connection.create_connection(\n           ^^^^^^^^^^^^^^^^^^^^^^^^^^^^^\n  File \"C:\\Python311\\Lib\\site-packages\\urllib3\\util\\connection.py\", line 60, in create_connection\n    for res in socket.getaddrinfo(host, port, family, socket.SOCK_STREAM):\n               ^^^^^^^^^^^^^^^^^^^^^^^^^^^^^^^^^^^^^^^^^^^^^^^^^^^^^^^^^^\n  File \"C:\\Python311\\Lib\\socket.py\", line 962, in getaddrinfo\n    for res in _socket.getaddrinfo(host, port, family, type, proto, flags):\n               ^^^^^^^^^^^^^^^^^^^^^^^^^^^^^^^^^^^^^^^^^^^^^^^^^^^^^^^^^^^\nsocket.gaierror: [Errno 11001] getaddrinfo failed\n\nThe above exception was the direct cause of the following exception:\n\nTraceback (most recent call last):\n  File \"C:\\Python311\\Lib\\site-packages\\urllib3\\connectionpool.py\", line 790, in urlopen\n    response = self._make_request(\n               ^^^^^^^^^^^^^^^^^^^\n  File \"C:\\Python311\\Lib\\site-packages\\urllib3\\connectionpool.py\", line 491, in _make_request\n    raise new_e\n  File \"C:\\Python311\\Lib\\site-packages\\urllib3\\connectionpool.py\", line 467, in _make_request\n    self._validate_conn(conn)\n  File \"C:\\Python311\\Lib\\site-packages\\urllib3\\connectionpool.py\", line 1092, in _validate_conn\n    conn.connect()\n  File \"C:\\Python311\\Lib\\site-packages\\urllib3\\connection.py\", line 611, in connect\n    self.sock = sock = self._new_conn()\n                       ^^^^^^^^^^^^^^^^\n  File \"C:\\Python311\\Lib\\site-packages\\urllib3\\connection.py\", line 210, in _new_conn\n    raise NameResolutionError(self.host, self, e) from e\nurllib3.exceptions.NameResolutionError: <urllib3.connection.HTTPSConnection object at 0x0000020F6F410890>: Failed to resolve 'api-t1.fyers.in' ([Errno 11001] getaddrinfo failed)\n\nThe above exception was the direct cause of the following exception:\n\nTraceback (most recent call last):\n  File \"C:\\Python311\\Lib\\site-packages\\requests\\adapters.py\", line 486, in send\n    resp = conn.urlopen(\n           ^^^^^^^^^^^^^\n  File \"C:\\Python311\\Lib\\site-packages\\urllib3\\connectionpool.py\", line 844, in urlopen\n    retries = retries.increment(\n              ^^^^^^^^^^^^^^^^^^\n  File \"C:\\Python311\\Lib\\site-packages\\urllib3\\util\\retry.py\", line 515, in increment\n    raise MaxRetryError(_pool, url, reason) from reason  # type: ignore[arg-type]\n    ^^^^^^^^^^^^^^^^^^^^^^^^^^^^^^^^^^^^^^^^^^^^^^^^^^^\nurllib3.exceptions.MaxRetryError: HTTPSConnectionPool(host='api-t1.fyers.in', port=443): Max retries exceeded with url: /data/symbol-token (Caused by NameResolutionError(\"<urllib3.connection.HTTPSConnection object at 0x0000020F6F410890>: Failed to resolve 'api-t1.fyers.in' ([Errno 11001] getaddrinfo failed)\"))\n\nDuring handling of the above exception, another exception occurred:\n\nTraceback (most recent call last):\n  File \"C:\\Python311\\Lib\\site-packages\\fyers_apiv3\\FyersWebsocket\\data_ws.py\", line 63, in symbol_to_hsmtoken\n    response = requests.post(\n               ^^^^^^^^^^^^^^\n  File \"C:\\Python311\\Lib\\site-packages\\requests\\api.py\", line 115, in post\n    return request(\"post\", url, data=data, json=json, **kwargs)\n           ^^^^^^^^^^^^^^^^^^^^^^^^^^^^^^^^^^^^^^^^^^^^^^^^^^^^\n  File \"C:\\Python311\\Lib\\site-packages\\requests\\api.py\", line 59, in request\n    return session.request(method=method, url=url, **kwargs)\n           ^^^^^^^^^^^^^^^^^^^^^^^^^^^^^^^^^^^^^^^^^^^^^^^^^\n  File \"C:\\Python311\\Lib\\site-packages\\requests\\sessions.py\", line 589, in request\n    resp = self.send(prep, **send_kwargs)\n           ^^^^^^^^^^^^^^^^^^^^^^^^^^^^^^\n  File \"C:\\Python311\\Lib\\site-packages\\requests\\sessions.py\", line 703, in send\n    r = adapter.send(request, **kwargs)\n        ^^^^^^^^^^^^^^^^^^^^^^^^^^^^^^^\n  File \"C:\\Python311\\Lib\\site-packages\\requests\\adapters.py\", line 519, in send\n    raise ConnectionError(e, request=request)\nrequests.exceptions.ConnectionError: HTTPSConnectionPool(host='api-t1.fyers.in', port=443): Max retries exceeded with url: /data/symbol-token (Caused by NameResolutionError(\"<urllib3.connection.HTTPSConnection object at 0x0000020F6F410890>: Failed to resolve 'api-t1.fyers.in' ([Errno 11001] getaddrinfo failed)\"))","exception_name":"ConnectionError"}
{"level":"ERROR","location":"[__symbol_conversion:1374] data_ws","message":"'NoneType' object is not subscriptable","timestamp":"2025-08-27 20:43:03,217+0530","service":"FyersDataSocket","exception":"Traceback (most recent call last):\n  File \"C:\\Python311\\Lib\\site-packages\\websocket\\_http.py\", line 155, in _get_addrinfo_list\n    addrinfo_list = socket.getaddrinfo(\n                    ^^^^^^^^^^^^^^^^^^^\n  File \"C:\\Python311\\Lib\\socket.py\", line 962, in getaddrinfo\n    for res in _socket.getaddrinfo(host, port, family, type, proto, flags):\n               ^^^^^^^^^^^^^^^^^^^^^^^^^^^^^^^^^^^^^^^^^^^^^^^^^^^^^^^^^^^\nsocket.gaierror: [Errno 11001] getaddrinfo failed\n\nDuring handling of the above exception, another exception occurred:\n\nTraceback (most recent call last):\n  File \"C:\\Python311\\Lib\\site-packages\\websocket\\_app.py\", line 412, in setSock\n    self.sock.connect(\n  File \"C:\\Python311\\Lib\\site-packages\\websocket\\_core.py\", line 249, in connect\n    self.sock, addrs = connect(url, self.sock_opt, proxy_info(**options),\n                       ^^^^^^^^^^^^^^^^^^^^^^^^^^^^^^^^^^^^^^^^^^^^^^^^^^\n  File \"C:\\Python311\\Lib\\site-packages\\websocket\\_http.py\", line 122, in connect\n    addrinfo_list, need_tunnel, auth = _get_addrinfo_list(\n                                       ^^^^^^^^^^^^^^^^^^^\n  File \"C:\\Python311\\Lib\\site-packages\\websocket\\_http.py\", line 167, in _get_addrinfo_list\n    raise WebSocketAddressException(e)\nwebsocket._exceptions.WebSocketAddressException: [Errno 11001] getaddrinfo failed\n\nDuring handling of the above exception, another exception occurred:\n\nTraceback (most recent call last):\n  File \"C:\\Python311\\Lib\\site-packages\\fyers_apiv3\\FyersWebsocket\\data_ws.py\", line 1333, in __symbol_conversion\n    if symbol_value[3] != \"\":\n       ~~~~~~~~~~~~^^^\nTypeError: 'NoneType' object is not subscriptable","exception_name":"TypeError"}
{"level":"ERROR","location":"[<lambda>:1663] data_ws","message":"[Errno 11001] getaddrinfo failed","timestamp":"2025-08-27 20:43:06,218+0530","service":"FyersDataSocket"}
{"level":"ERROR","location":"[symbol_to_hsmtoken:126] data_ws","message":"HTTPSConnectionPool(host='api-t1.fyers.in', port=443): Max retries exceeded with url: /data/symbol-token (Caused by NameResolutionError(\"<urllib3.connection.HTTPSConnection object at 0x0000020F6F429350>: Failed to resolve 'api-t1.fyers.in' ([Errno 11001] getaddrinfo failed)\"))","timestamp":"2025-08-27 20:43:08,219+0530","service":"FyersDataSocket","exception":"Traceback (most recent call last):\n  File \"C:\\Python311\\Lib\\site-packages\\websocket\\_http.py\", line 155, in _get_addrinfo_list\n    addrinfo_list = socket.getaddrinfo(\n                    ^^^^^^^^^^^^^^^^^^^\n  File \"C:\\Python311\\Lib\\socket.py\", line 962, in getaddrinfo\n    for res in _socket.getaddrinfo(host, port, family, type, proto, flags):\n               ^^^^^^^^^^^^^^^^^^^^^^^^^^^^^^^^^^^^^^^^^^^^^^^^^^^^^^^^^^^\nsocket.gaierror: [Errno 11001] getaddrinfo failed\n\nDuring handling of the above exception, another exception occurred:\n\nTraceback (most recent call last):\n  File \"C:\\Python311\\Lib\\site-packages\\websocket\\_app.py\", line 412, in setSock\n    self.sock.connect(\n  File \"C:\\Python311\\Lib\\site-packages\\websocket\\_core.py\", line 249, in connect\n    self.sock, addrs = connect(url, self.sock_opt, proxy_info(**options),\n                       ^^^^^^^^^^^^^^^^^^^^^^^^^^^^^^^^^^^^^^^^^^^^^^^^^^\n  File \"C:\\Python311\\Lib\\site-packages\\websocket\\_http.py\", line 122, in connect\n    addrinfo_list, need_tunnel, auth = _get_addrinfo_list(\n                                       ^^^^^^^^^^^^^^^^^^^\n  File \"C:\\Python311\\Lib\\site-packages\\websocket\\_http.py\", line 167, in _get_addrinfo_list\n    raise WebSocketAddressException(e)\nwebsocket._exceptions.WebSocketAddressException: [Errno 11001] getaddrinfo failed\n\nDuring handling of the above exception, another exception occurred:\n\nTraceback (most recent call last):\n  File \"C:\\Python311\\Lib\\site-packages\\urllib3\\connection.py\", line 203, in _new_conn\n    sock = connection.create_connection(\n           ^^^^^^^^^^^^^^^^^^^^^^^^^^^^^\n  File \"C:\\Python311\\Lib\\site-packages\\urllib3\\util\\connection.py\", line 60, in create_connection\n    for res in socket.getaddrinfo(host, port, family, socket.SOCK_STREAM):\n               ^^^^^^^^^^^^^^^^^^^^^^^^^^^^^^^^^^^^^^^^^^^^^^^^^^^^^^^^^^\n  File \"C:\\Python311\\Lib\\socket.py\", line 962, in getaddrinfo\n    for res in _socket.getaddrinfo(host, port, family, type, proto, flags):\n               ^^^^^^^^^^^^^^^^^^^^^^^^^^^^^^^^^^^^^^^^^^^^^^^^^^^^^^^^^^^\nsocket.gaierror: [Errno 11001] getaddrinfo failed\n\nThe above exception was the direct cause of the following exception:\n\nTraceback (most recent call last):\n  File \"C:\\Python311\\Lib\\site-packages\\urllib3\\connectionpool.py\", line 790, in urlopen\n    response = self._make_request(\n               ^^^^^^^^^^^^^^^^^^^\n  File \"C:\\Python311\\Lib\\site-packages\\urllib3\\connectionpool.py\", line 491, in _make_request\n    raise new_e\n  File \"C:\\Python311\\Lib\\site-packages\\urllib3\\connectionpool.py\", line 467, in _make_request\n    self._validate_conn(conn)\n  File \"C:\\Python311\\Lib\\site-packages\\urllib3\\connectionpool.py\", line 1092, in _validate_conn\n    conn.connect()\n  File \"C:\\Python311\\Lib\\site-packages\\urllib3\\connection.py\", line 611, in connect\n    self.sock = sock = self._new_conn()\n                       ^^^^^^^^^^^^^^^^\n  File \"C:\\Python311\\Lib\\site-packages\\urllib3\\connection.py\", line 210, in _new_conn\n    raise NameResolutionError(self.host, self, e) from e\nurllib3.exceptions.NameResolutionError: <urllib3.connection.HTTPSConnection object at 0x0000020F6F429350>: Failed to resolve 'api-t1.fyers.in' ([Errno 11001] getaddrinfo failed)\n\nThe above exception was the direct cause of the following exception:\n\nTraceback (most recent call last):\n  File \"C:\\Python311\\Lib\\site-packages\\requests\\adapters.py\", line 486, in send\n    resp = conn.urlopen(\n           ^^^^^^^^^^^^^\n  File \"C:\\Python311\\Lib\\site-packages\\urllib3\\connectionpool.py\", line 844, in urlopen\n    retries = retries.increment(\n              ^^^^^^^^^^^^^^^^^^\n  File \"C:\\Python311\\Lib\\site-packages\\urllib3\\util\\retry.py\", line 515, in increment\n    raise MaxRetryError(_pool, url, reason) from reason  # type: ignore[arg-type]\n    ^^^^^^^^^^^^^^^^^^^^^^^^^^^^^^^^^^^^^^^^^^^^^^^^^^^\nurllib3.exceptions.MaxRetryError: HTTPSConnectionPool(host='api-t1.fyers.in', port=443): Max retries exceeded with url: /data/symbol-token (Caused by NameResolutionError(\"<urllib3.connection.HTTPSConnection object at 0x0000020F6F429350>: Failed to resolve 'api-t1.fyers.in' ([Errno 11001] getaddrinfo failed)\"))\n\nDuring handling of the above exception, another exception occurred:\n\nTraceback (most recent call last):\n  File \"C:\\Python311\\Lib\\site-packages\\fyers_apiv3\\FyersWebsocket\\data_ws.py\", line 63, in symbol_to_hsmtoken\n    response = requests.post(\n               ^^^^^^^^^^^^^^\n  File \"C:\\Python311\\Lib\\site-packages\\requests\\api.py\", line 115, in post\n    return request(\"post\", url, data=data, json=json, **kwargs)\n           ^^^^^^^^^^^^^^^^^^^^^^^^^^^^^^^^^^^^^^^^^^^^^^^^^^^^\n  File \"C:\\Python311\\Lib\\site-packages\\requests\\api.py\", line 59, in request\n    return session.request(method=method, url=url, **kwargs)\n           ^^^^^^^^^^^^^^^^^^^^^^^^^^^^^^^^^^^^^^^^^^^^^^^^^\n  File \"C:\\Python311\\Lib\\site-packages\\requests\\sessions.py\", line 589, in request\n    resp = self.send(prep, **send_kwargs)\n           ^^^^^^^^^^^^^^^^^^^^^^^^^^^^^^\n  File \"C:\\Python311\\Lib\\site-packages\\requests\\sessions.py\", line 703, in send\n    r = adapter.send(request, **kwargs)\n        ^^^^^^^^^^^^^^^^^^^^^^^^^^^^^^^\n  File \"C:\\Python311\\Lib\\site-packages\\requests\\adapters.py\", line 519, in send\n    raise ConnectionError(e, request=request)\nrequests.exceptions.ConnectionError: HTTPSConnectionPool(host='api-t1.fyers.in', port=443): Max retries exceeded with url: /data/symbol-token (Caused by NameResolutionError(\"<urllib3.connection.HTTPSConnection object at 0x0000020F6F429350>: Failed to resolve 'api-t1.fyers.in' ([Errno 11001] getaddrinfo failed)\"))","exception_name":"ConnectionError"}
{"level":"ERROR","location":"[__symbol_conversion:1374] data_ws","message":"'NoneType' object is not subscriptable","timestamp":"2025-08-27 20:43:08,225+0530","service":"FyersDataSocket","exception":"Traceback (most recent call last):\n  File \"C:\\Python311\\Lib\\site-packages\\websocket\\_http.py\", line 155, in _get_addrinfo_list\n    addrinfo_list = socket.getaddrinfo(\n                    ^^^^^^^^^^^^^^^^^^^\n  File \"C:\\Python311\\Lib\\socket.py\", line 962, in getaddrinfo\n    for res in _socket.getaddrinfo(host, port, family, type, proto, flags):\n               ^^^^^^^^^^^^^^^^^^^^^^^^^^^^^^^^^^^^^^^^^^^^^^^^^^^^^^^^^^^\nsocket.gaierror: [Errno 11001] getaddrinfo failed\n\nDuring handling of the above exception, another exception occurred:\n\nTraceback (most recent call last):\n  File \"C:\\Python311\\Lib\\site-packages\\websocket\\_app.py\", line 412, in setSock\n    self.sock.connect(\n  File \"C:\\Python311\\Lib\\site-packages\\websocket\\_core.py\", line 249, in connect\n    self.sock, addrs = connect(url, self.sock_opt, proxy_info(**options),\n                       ^^^^^^^^^^^^^^^^^^^^^^^^^^^^^^^^^^^^^^^^^^^^^^^^^^\n  File \"C:\\Python311\\Lib\\site-packages\\websocket\\_http.py\", line 122, in connect\n    addrinfo_list, need_tunnel, auth = _get_addrinfo_list(\n                                       ^^^^^^^^^^^^^^^^^^^\n  File \"C:\\Python311\\Lib\\site-packages\\websocket\\_http.py\", line 167, in _get_addrinfo_list\n    raise WebSocketAddressException(e)\nwebsocket._exceptions.WebSocketAddressException: [Errno 11001] getaddrinfo failed\n\nDuring handling of the above exception, another exception occurred:\n\nTraceback (most recent call last):\n  File \"C:\\Python311\\Lib\\site-packages\\fyers_apiv3\\FyersWebsocket\\data_ws.py\", line 1333, in __symbol_conversion\n    if symbol_value[3] != \"\":\n       ~~~~~~~~~~~~^^^\nTypeError: 'NoneType' object is not subscriptable","exception_name":"TypeError"}
{"level":"ERROR","location":"[On_message:1442] data_ws","message":"'exch_feed_time'","timestamp":"2025-08-28 11:38:21,902+0530","service":"FyersDataSocket","exception":"Traceback (most recent call last):\n  File \"C:\\Python311\\Lib\\site-packages\\fyers_apiv3\\FyersWebsocket\\data_ws.py\", line 1433, in On_message\n    self.OnMessage(message)\n  File \"d:\\FyiersApiAutomation\\websocket\\fyers_websocket_ohlc.py\", line 38, in onmessage\n    ms = message['exch_feed_time']\n         ~~~~~~~^^^^^^^^^^^^^^^^^^\nKeyError: 'exch_feed_time'","exception_name":"KeyError"}
{"level":"ERROR","location":"[On_message:1443] data_ws","message":"KeyError: The key 'exch_feed_time' is missing in the response.","timestamp":"2025-08-28 11:38:21,923+0530","service":"FyersDataSocket"}
{"level":"ERROR","location":"[On_message:1442] data_ws","message":"'exch_feed_time'","timestamp":"2025-08-28 11:38:22,125+0530","service":"FyersDataSocket","exception":"Traceback (most recent call last):\n  File \"C:\\Python311\\Lib\\site-packages\\fyers_apiv3\\FyersWebsocket\\data_ws.py\", line 1433, in On_message\n    self.OnMessage(message)\n  File \"d:\\FyiersApiAutomation\\websocket\\fyers_websocket_ohlc.py\", line 38, in onmessage\n    ms = message['exch_feed_time']\n         ~~~~~~~^^^^^^^^^^^^^^^^^^\nKeyError: 'exch_feed_time'","exception_name":"KeyError"}
{"level":"ERROR","location":"[On_message:1443] data_ws","message":"KeyError: The key 'exch_feed_time' is missing in the response.","timestamp":"2025-08-28 11:38:22,125+0530","service":"FyersDataSocket"}
{"level":"ERROR","location":"[On_message:1442] data_ws","message":"'exch_feed_time'","timestamp":"2025-08-28 11:38:24,400+0530","service":"FyersDataSocket","exception":"Traceback (most recent call last):\n  File \"C:\\Python311\\Lib\\site-packages\\fyers_apiv3\\FyersWebsocket\\data_ws.py\", line 1433, in On_message\n    self.OnMessage(message)\n  File \"d:\\FyiersApiAutomation\\websocket\\fyers_websocket_ohlc.py\", line 38, in onmessage\n    ms = message['exch_feed_time']\n         ~~~~~~~^^^^^^^^^^^^^^^^^^\nKeyError: 'exch_feed_time'","exception_name":"KeyError"}
{"level":"ERROR","location":"[On_message:1443] data_ws","message":"KeyError: The key 'exch_feed_time' is missing in the response.","timestamp":"2025-08-28 11:38:24,400+0530","service":"FyersDataSocket"}
{"level":"ERROR","location":"[On_message:1442] data_ws","message":"'symbol'","timestamp":"2025-08-28 11:41:42,476+0530","service":"FyersDataSocket","exception":"Traceback (most recent call last):\n  File \"C:\\Python311\\Lib\\site-packages\\fyers_apiv3\\FyersWebsocket\\data_ws.py\", line 1433, in On_message\n    self.OnMessage(message)\n  File \"d:\\FyiersApiAutomation\\websocket\\fyers_websocket_ltp.py\", line 14, in onmessage\n    print(\"Symbol:\",message['symbol'],  \"Volume: \",message['total_vol_traded'])\n                    ~~~~~~~^^^^^^^^^^\nKeyError: 'symbol'","exception_name":"KeyError"}
{"level":"ERROR","location":"[On_message:1443] data_ws","message":"KeyError: The key 'symbol' is missing in the response.","timestamp":"2025-08-28 11:41:42,480+0530","service":"FyersDataSocket"}
{"level":"ERROR","location":"[On_message:1442] data_ws","message":"'symbol'","timestamp":"2025-08-28 11:41:42,840+0530","service":"FyersDataSocket","exception":"Traceback (most recent call last):\n  File \"C:\\Python311\\Lib\\site-packages\\fyers_apiv3\\FyersWebsocket\\data_ws.py\", line 1433, in On_message\n    self.OnMessage(message)\n  File \"d:\\FyiersApiAutomation\\websocket\\fyers_websocket_ltp.py\", line 14, in onmessage\n    print(\"Symbol:\",message['symbol'],  \"Volume: \",message['total_vol_traded'])\n                    ~~~~~~~^^^^^^^^^^\nKeyError: 'symbol'","exception_name":"KeyError"}
{"level":"ERROR","location":"[On_message:1443] data_ws","message":"KeyError: The key 'symbol' is missing in the response.","timestamp":"2025-08-28 11:41:42,840+0530","service":"FyersDataSocket"}
{"level":"ERROR","location":"[On_message:1442] data_ws","message":"'symbol'","timestamp":"2025-08-28 11:41:44,988+0530","service":"FyersDataSocket","exception":"Traceback (most recent call last):\n  File \"C:\\Python311\\Lib\\site-packages\\fyers_apiv3\\FyersWebsocket\\data_ws.py\", line 1433, in On_message\n    self.OnMessage(message)\n  File \"d:\\FyiersApiAutomation\\websocket\\fyers_websocket_ltp.py\", line 14, in onmessage\n    print(\"Symbol:\",message['symbol'],  \"Volume: \",message['total_vol_traded'])\n                    ~~~~~~~^^^^^^^^^^\nKeyError: 'symbol'","exception_name":"KeyError"}
{"level":"ERROR","location":"[On_message:1443] data_ws","message":"KeyError: The key 'symbol' is missing in the response.","timestamp":"2025-08-28 11:41:44,988+0530","service":"FyersDataSocket"}
{"level":"ERROR","location":"[On_message:1442] data_ws","message":"'total_vol_traded'","timestamp":"2025-08-28 11:41:45,036+0530","service":"FyersDataSocket","exception":"Traceback (most recent call last):\n  File \"C:\\Python311\\Lib\\site-packages\\fyers_apiv3\\FyersWebsocket\\data_ws.py\", line 1433, in On_message\n    self.OnMessage(message)\n  File \"d:\\FyiersApiAutomation\\websocket\\fyers_websocket_ltp.py\", line 14, in onmessage\n    print(\"Symbol:\",message['symbol'],  \"Volume: \",message['total_vol_traded'])\n                                                   ~~~~~~~^^^^^^^^^^^^^^^^^^^^\nKeyError: 'total_vol_traded'","exception_name":"KeyError"}
{"level":"ERROR","location":"[On_message:1443] data_ws","message":"KeyError: The key 'total_vol_traded' is missing in the response.","timestamp":"2025-08-28 11:41:45,036+0530","service":"FyersDataSocket"}
{"level":"ERROR","location":"[On_message:1442] data_ws","message":"'total_vol_traded'","timestamp":"2025-08-28 11:41:45,589+0530","service":"FyersDataSocket","exception":"Traceback (most recent call last):\n  File \"C:\\Python311\\Lib\\site-packages\\fyers_apiv3\\FyersWebsocket\\data_ws.py\", line 1433, in On_message\n    self.OnMessage(message)\n  File \"d:\\FyiersApiAutomation\\websocket\\fyers_websocket_ltp.py\", line 14, in onmessage\n    print(\"Symbol:\",message['symbol'],  \"Volume: \",message['total_vol_traded'])\n                                                   ~~~~~~~^^^^^^^^^^^^^^^^^^^^\nKeyError: 'total_vol_traded'","exception_name":"KeyError"}
{"level":"ERROR","location":"[On_message:1443] data_ws","message":"KeyError: The key 'total_vol_traded' is missing in the response.","timestamp":"2025-08-28 11:41:45,589+0530","service":"FyersDataSocket"}
{"level":"ERROR","location":"[On_message:1442] data_ws","message":"'total_vol_traded'","timestamp":"2025-08-28 11:41:45,917+0530","service":"FyersDataSocket","exception":"Traceback (most recent call last):\n  File \"C:\\Python311\\Lib\\site-packages\\fyers_apiv3\\FyersWebsocket\\data_ws.py\", line 1433, in On_message\n    self.OnMessage(message)\n  File \"d:\\FyiersApiAutomation\\websocket\\fyers_websocket_ltp.py\", line 14, in onmessage\n    print(\"Symbol:\",message['symbol'],  \"Volume: \",message['total_vol_traded'])\n                                                   ~~~~~~~^^^^^^^^^^^^^^^^^^^^\nKeyError: 'total_vol_traded'","exception_name":"KeyError"}
{"level":"ERROR","location":"[On_message:1443] data_ws","message":"KeyError: The key 'total_vol_traded' is missing in the response.","timestamp":"2025-08-28 11:41:45,917+0530","service":"FyersDataSocket"}
{"level":"ERROR","location":"[On_message:1442] data_ws","message":"'total_vol_traded'","timestamp":"2025-08-28 11:41:46,254+0530","service":"FyersDataSocket","exception":"Traceback (most recent call last):\n  File \"C:\\Python311\\Lib\\site-packages\\fyers_apiv3\\FyersWebsocket\\data_ws.py\", line 1433, in On_message\n    self.OnMessage(message)\n  File \"d:\\FyiersApiAutomation\\websocket\\fyers_websocket_ltp.py\", line 14, in onmessage\n    print(\"Symbol:\",message['symbol'],  \"Volume: \",message['total_vol_traded'])\n                                                   ~~~~~~~^^^^^^^^^^^^^^^^^^^^\nKeyError: 'total_vol_traded'","exception_name":"KeyError"}
{"level":"ERROR","location":"[On_message:1443] data_ws","message":"KeyError: The key 'total_vol_traded' is missing in the response.","timestamp":"2025-08-28 11:41:46,254+0530","service":"FyersDataSocket"}
{"level":"ERROR","location":"[On_message:1442] data_ws","message":"'total_vol_traded'","timestamp":"2025-08-28 11:41:47,129+0530","service":"FyersDataSocket","exception":"Traceback (most recent call last):\n  File \"C:\\Python311\\Lib\\site-packages\\fyers_apiv3\\FyersWebsocket\\data_ws.py\", line 1433, in On_message\n    self.OnMessage(message)\n  File \"d:\\FyiersApiAutomation\\websocket\\fyers_websocket_ltp.py\", line 14, in onmessage\n    print(\"Symbol:\",message['symbol'],  \"Volume: \",message['total_vol_traded'])\n                                                   ~~~~~~~^^^^^^^^^^^^^^^^^^^^\nKeyError: 'total_vol_traded'","exception_name":"KeyError"}
{"level":"ERROR","location":"[On_message:1443] data_ws","message":"KeyError: The key 'total_vol_traded' is missing in the response.","timestamp":"2025-08-28 11:41:47,129+0530","service":"FyersDataSocket"}
{"level":"ERROR","location":"[On_message:1442] data_ws","message":"'total_vol_traded'","timestamp":"2025-08-28 11:41:47,714+0530","service":"FyersDataSocket","exception":"Traceback (most recent call last):\n  File \"C:\\Python311\\Lib\\site-packages\\fyers_apiv3\\FyersWebsocket\\data_ws.py\", line 1433, in On_message\n    self.OnMessage(message)\n  File \"d:\\FyiersApiAutomation\\websocket\\fyers_websocket_ltp.py\", line 14, in onmessage\n    print(\"Symbol:\",message['symbol'],  \"Volume: \",message['total_vol_traded'])\n                                                   ~~~~~~~^^^^^^^^^^^^^^^^^^^^\nKeyError: 'total_vol_traded'","exception_name":"KeyError"}
{"level":"ERROR","location":"[On_message:1443] data_ws","message":"KeyError: The key 'total_vol_traded' is missing in the response.","timestamp":"2025-08-28 11:41:47,715+0530","service":"FyersDataSocket"}
{"level":"ERROR","location":"[On_message:1442] data_ws","message":"'total_vol_traded'","timestamp":"2025-08-28 11:41:48,123+0530","service":"FyersDataSocket","exception":"Traceback (most recent call last):\n  File \"C:\\Python311\\Lib\\site-packages\\fyers_apiv3\\FyersWebsocket\\data_ws.py\", line 1433, in On_message\n    self.OnMessage(message)\n  File \"d:\\FyiersApiAutomation\\websocket\\fyers_websocket_ltp.py\", line 14, in onmessage\n    print(\"Symbol:\",message['symbol'],  \"Volume: \",message['total_vol_traded'])\n                                                   ~~~~~~~^^^^^^^^^^^^^^^^^^^^\nKeyError: 'total_vol_traded'","exception_name":"KeyError"}
{"level":"ERROR","location":"[On_message:1443] data_ws","message":"KeyError: The key 'total_vol_traded' is missing in the response.","timestamp":"2025-08-28 11:41:48,123+0530","service":"FyersDataSocket"}
{"level":"ERROR","location":"[On_message:1442] data_ws","message":"'total_vol_traded'","timestamp":"2025-08-28 11:41:49,143+0530","service":"FyersDataSocket","exception":"Traceback (most recent call last):\n  File \"C:\\Python311\\Lib\\site-packages\\fyers_apiv3\\FyersWebsocket\\data_ws.py\", line 1433, in On_message\n    self.OnMessage(message)\n  File \"d:\\FyiersApiAutomation\\websocket\\fyers_websocket_ltp.py\", line 14, in onmessage\n    print(\"Symbol:\",message['symbol'],  \"Volume: \",message['total_vol_traded'])\n                                                   ~~~~~~~^^^^^^^^^^^^^^^^^^^^\nKeyError: 'total_vol_traded'","exception_name":"KeyError"}
{"level":"ERROR","location":"[On_message:1443] data_ws","message":"KeyError: The key 'total_vol_traded' is missing in the response.","timestamp":"2025-08-28 11:41:49,143+0530","service":"FyersDataSocket"}
{"level":"ERROR","location":"[On_message:1442] data_ws","message":"'total_vol_traded'","timestamp":"2025-08-28 11:41:49,549+0530","service":"FyersDataSocket","exception":"Traceback (most recent call last):\n  File \"C:\\Python311\\Lib\\site-packages\\fyers_apiv3\\FyersWebsocket\\data_ws.py\", line 1433, in On_message\n    self.OnMessage(message)\n  File \"d:\\FyiersApiAutomation\\websocket\\fyers_websocket_ltp.py\", line 14, in onmessage\n    print(\"Symbol:\",message['symbol'],  \"Volume: \",message['total_vol_traded'])\n                                                   ~~~~~~~^^^^^^^^^^^^^^^^^^^^\nKeyError: 'total_vol_traded'","exception_name":"KeyError"}
{"level":"ERROR","location":"[On_message:1443] data_ws","message":"KeyError: The key 'total_vol_traded' is missing in the response.","timestamp":"2025-08-28 11:41:49,549+0530","service":"FyersDataSocket"}
{"level":"ERROR","location":"[On_message:1442] data_ws","message":"'total_vol_traded'","timestamp":"2025-08-28 11:41:50,054+0530","service":"FyersDataSocket","exception":"Traceback (most recent call last):\n  File \"C:\\Python311\\Lib\\site-packages\\fyers_apiv3\\FyersWebsocket\\data_ws.py\", line 1433, in On_message\n    self.OnMessage(message)\n  File \"d:\\FyiersApiAutomation\\websocket\\fyers_websocket_ltp.py\", line 14, in onmessage\n    print(\"Symbol:\",message['symbol'],  \"Volume: \",message['total_vol_traded'])\n                                                   ~~~~~~~^^^^^^^^^^^^^^^^^^^^\nKeyError: 'total_vol_traded'","exception_name":"KeyError"}
{"level":"ERROR","location":"[On_message:1443] data_ws","message":"KeyError: The key 'total_vol_traded' is missing in the response.","timestamp":"2025-08-28 11:41:50,054+0530","service":"FyersDataSocket"}
{"level":"ERROR","location":"[On_message:1442] data_ws","message":"'total_vol_traded'","timestamp":"2025-08-28 11:41:50,670+0530","service":"FyersDataSocket","exception":"Traceback (most recent call last):\n  File \"C:\\Python311\\Lib\\site-packages\\fyers_apiv3\\FyersWebsocket\\data_ws.py\", line 1433, in On_message\n    self.OnMessage(message)\n  File \"d:\\FyiersApiAutomation\\websocket\\fyers_websocket_ltp.py\", line 14, in onmessage\n    print(\"Symbol:\",message['symbol'],  \"Volume: \",message['total_vol_traded'])\n                                                   ~~~~~~~^^^^^^^^^^^^^^^^^^^^\nKeyError: 'total_vol_traded'","exception_name":"KeyError"}
{"level":"ERROR","location":"[On_message:1443] data_ws","message":"KeyError: The key 'total_vol_traded' is missing in the response.","timestamp":"2025-08-28 11:41:50,670+0530","service":"FyersDataSocket"}
{"level":"ERROR","location":"[On_message:1442] data_ws","message":"'total_vol_traded'","timestamp":"2025-08-28 11:41:51,236+0530","service":"FyersDataSocket","exception":"Traceback (most recent call last):\n  File \"C:\\Python311\\Lib\\site-packages\\fyers_apiv3\\FyersWebsocket\\data_ws.py\", line 1433, in On_message\n    self.OnMessage(message)\n  File \"d:\\FyiersApiAutomation\\websocket\\fyers_websocket_ltp.py\", line 14, in onmessage\n    print(\"Symbol:\",message['symbol'],  \"Volume: \",message['total_vol_traded'])\n                                                   ~~~~~~~^^^^^^^^^^^^^^^^^^^^\nKeyError: 'total_vol_traded'","exception_name":"KeyError"}
{"level":"ERROR","location":"[On_message:1443] data_ws","message":"KeyError: The key 'total_vol_traded' is missing in the response.","timestamp":"2025-08-28 11:41:51,238+0530","service":"FyersDataSocket"}
{"level":"ERROR","location":"[On_message:1442] data_ws","message":"'total_vol_traded'","timestamp":"2025-08-28 11:41:51,704+0530","service":"FyersDataSocket","exception":"Traceback (most recent call last):\n  File \"C:\\Python311\\Lib\\site-packages\\fyers_apiv3\\FyersWebsocket\\data_ws.py\", line 1433, in On_message\n    self.OnMessage(message)\n  File \"d:\\FyiersApiAutomation\\websocket\\fyers_websocket_ltp.py\", line 14, in onmessage\n    print(\"Symbol:\",message['symbol'],  \"Volume: \",message['total_vol_traded'])\n                                                   ~~~~~~~^^^^^^^^^^^^^^^^^^^^\nKeyError: 'total_vol_traded'","exception_name":"KeyError"}
{"level":"ERROR","location":"[On_message:1443] data_ws","message":"KeyError: The key 'total_vol_traded' is missing in the response.","timestamp":"2025-08-28 11:41:51,707+0530","service":"FyersDataSocket"}
{"level":"ERROR","location":"[On_message:1442] data_ws","message":"'total_vol_traded'","timestamp":"2025-08-28 11:41:52,016+0530","service":"FyersDataSocket","exception":"Traceback (most recent call last):\n  File \"C:\\Python311\\Lib\\site-packages\\fyers_apiv3\\FyersWebsocket\\data_ws.py\", line 1433, in On_message\n    self.OnMessage(message)\n  File \"d:\\FyiersApiAutomation\\websocket\\fyers_websocket_ltp.py\", line 14, in onmessage\n    print(\"Symbol:\",message['symbol'],  \"Volume: \",message['total_vol_traded'])\n                                                   ~~~~~~~^^^^^^^^^^^^^^^^^^^^\nKeyError: 'total_vol_traded'","exception_name":"KeyError"}
{"level":"ERROR","location":"[On_message:1443] data_ws","message":"KeyError: The key 'total_vol_traded' is missing in the response.","timestamp":"2025-08-28 11:41:52,019+0530","service":"FyersDataSocket"}
{"level":"ERROR","location":"[On_message:1442] data_ws","message":"'total_vol_traded'","timestamp":"2025-08-28 11:41:52,427+0530","service":"FyersDataSocket","exception":"Traceback (most recent call last):\n  File \"C:\\Python311\\Lib\\site-packages\\fyers_apiv3\\FyersWebsocket\\data_ws.py\", line 1433, in On_message\n    self.OnMessage(message)\n  File \"d:\\FyiersApiAutomation\\websocket\\fyers_websocket_ltp.py\", line 14, in onmessage\n    print(\"Symbol:\",message['symbol'],  \"Volume: \",message['total_vol_traded'])\n                                                   ~~~~~~~^^^^^^^^^^^^^^^^^^^^\nKeyError: 'total_vol_traded'","exception_name":"KeyError"}
{"level":"ERROR","location":"[On_message:1443] data_ws","message":"KeyError: The key 'total_vol_traded' is missing in the response.","timestamp":"2025-08-28 11:41:52,429+0530","service":"FyersDataSocket"}
{"level":"ERROR","location":"[On_message:1442] data_ws","message":"'symbol'","timestamp":"2025-08-28 11:42:06,150+0530","service":"FyersDataSocket","exception":"Traceback (most recent call last):\n  File \"C:\\Python311\\Lib\\site-packages\\fyers_apiv3\\FyersWebsocket\\data_ws.py\", line 1433, in On_message\n    self.OnMessage(message)\n  File \"d:\\FyiersApiAutomation\\websocket\\fyers_websocket_ltp.py\", line 14, in onmessage\n    print(\"Symbol:\",message['symbol'],  \"Volume: \",message['total_vol_traded'])\n                    ~~~~~~~^^^^^^^^^^\nKeyError: 'symbol'","exception_name":"KeyError"}
{"level":"ERROR","location":"[On_message:1443] data_ws","message":"KeyError: The key 'symbol' is missing in the response.","timestamp":"2025-08-28 11:42:06,157+0530","service":"FyersDataSocket"}
{"level":"ERROR","location":"[On_message:1442] data_ws","message":"'symbol'","timestamp":"2025-08-28 11:42:06,950+0530","service":"FyersDataSocket","exception":"Traceback (most recent call last):\n  File \"C:\\Python311\\Lib\\site-packages\\fyers_apiv3\\FyersWebsocket\\data_ws.py\", line 1433, in On_message\n    self.OnMessage(message)\n  File \"d:\\FyiersApiAutomation\\websocket\\fyers_websocket_ltp.py\", line 14, in onmessage\n    print(\"Symbol:\",message['symbol'],  \"Volume: \",message['total_vol_traded'])\n                    ~~~~~~~^^^^^^^^^^\nKeyError: 'symbol'","exception_name":"KeyError"}
{"level":"ERROR","location":"[On_message:1443] data_ws","message":"KeyError: The key 'symbol' is missing in the response.","timestamp":"2025-08-28 11:42:06,951+0530","service":"FyersDataSocket"}
{"level":"ERROR","location":"[On_message:1442] data_ws","message":"'symbol'","timestamp":"2025-08-28 11:42:08,541+0530","service":"FyersDataSocket","exception":"Traceback (most recent call last):\n  File \"C:\\Python311\\Lib\\site-packages\\fyers_apiv3\\FyersWebsocket\\data_ws.py\", line 1433, in On_message\n    self.OnMessage(message)\n  File \"d:\\FyiersApiAutomation\\websocket\\fyers_websocket_ltp.py\", line 14, in onmessage\n    print(\"Symbol:\",message['symbol'],  \"Volume: \",message['total_vol_traded'])\n                    ~~~~~~~^^^^^^^^^^\nKeyError: 'symbol'","exception_name":"KeyError"}
{"level":"ERROR","location":"[On_message:1443] data_ws","message":"KeyError: The key 'symbol' is missing in the response.","timestamp":"2025-08-28 11:42:08,545+0530","service":"FyersDataSocket"}
{"level":"ERROR","location":"[On_message:1442] data_ws","message":"'total_vol_traded'","timestamp":"2025-08-28 11:42:08,649+0530","service":"FyersDataSocket","exception":"Traceback (most recent call last):\n  File \"C:\\Python311\\Lib\\site-packages\\fyers_apiv3\\FyersWebsocket\\data_ws.py\", line 1433, in On_message\n    self.OnMessage(message)\n  File \"d:\\FyiersApiAutomation\\websocket\\fyers_websocket_ltp.py\", line 14, in onmessage\n    print(\"Symbol:\",message['symbol'],  \"Volume: \",message['total_vol_traded'])\n                                                   ~~~~~~~^^^^^^^^^^^^^^^^^^^^\nKeyError: 'total_vol_traded'","exception_name":"KeyError"}
{"level":"ERROR","location":"[On_message:1443] data_ws","message":"KeyError: The key 'total_vol_traded' is missing in the response.","timestamp":"2025-08-28 11:42:08,649+0530","service":"FyersDataSocket"}
{"level":"ERROR","location":"[On_message:1442] data_ws","message":"'total_vol_traded'","timestamp":"2025-08-28 11:42:09,106+0530","service":"FyersDataSocket","exception":"Traceback (most recent call last):\n  File \"C:\\Python311\\Lib\\site-packages\\fyers_apiv3\\FyersWebsocket\\data_ws.py\", line 1433, in On_message\n    self.OnMessage(message)\n  File \"d:\\FyiersApiAutomation\\websocket\\fyers_websocket_ltp.py\", line 14, in onmessage\n    print(\"Symbol:\",message['symbol'],  \"Volume: \",message['total_vol_traded'])\n                                                   ~~~~~~~^^^^^^^^^^^^^^^^^^^^\nKeyError: 'total_vol_traded'","exception_name":"KeyError"}
{"level":"ERROR","location":"[On_message:1443] data_ws","message":"KeyError: The key 'total_vol_traded' is missing in the response.","timestamp":"2025-08-28 11:42:09,106+0530","service":"FyersDataSocket"}
{"level":"ERROR","location":"[On_message:1442] data_ws","message":"'total_vol_traded'","timestamp":"2025-08-28 11:42:09,602+0530","service":"FyersDataSocket","exception":"Traceback (most recent call last):\n  File \"C:\\Python311\\Lib\\site-packages\\fyers_apiv3\\FyersWebsocket\\data_ws.py\", line 1433, in On_message\n    self.OnMessage(message)\n  File \"d:\\FyiersApiAutomation\\websocket\\fyers_websocket_ltp.py\", line 14, in onmessage\n    print(\"Symbol:\",message['symbol'],  \"Volume: \",message['total_vol_traded'])\n                                                   ~~~~~~~^^^^^^^^^^^^^^^^^^^^\nKeyError: 'total_vol_traded'","exception_name":"KeyError"}
{"level":"ERROR","location":"[On_message:1443] data_ws","message":"KeyError: The key 'total_vol_traded' is missing in the response.","timestamp":"2025-08-28 11:42:09,606+0530","service":"FyersDataSocket"}
{"level":"ERROR","location":"[On_message:1442] data_ws","message":"'total_vol_traded'","timestamp":"2025-08-28 11:42:09,924+0530","service":"FyersDataSocket","exception":"Traceback (most recent call last):\n  File \"C:\\Python311\\Lib\\site-packages\\fyers_apiv3\\FyersWebsocket\\data_ws.py\", line 1433, in On_message\n    self.OnMessage(message)\n  File \"d:\\FyiersApiAutomation\\websocket\\fyers_websocket_ltp.py\", line 14, in onmessage\n    print(\"Symbol:\",message['symbol'],  \"Volume: \",message['total_vol_traded'])\n                                                   ~~~~~~~^^^^^^^^^^^^^^^^^^^^\nKeyError: 'total_vol_traded'","exception_name":"KeyError"}
{"level":"ERROR","location":"[On_message:1443] data_ws","message":"KeyError: The key 'total_vol_traded' is missing in the response.","timestamp":"2025-08-28 11:42:09,924+0530","service":"FyersDataSocket"}
{"level":"ERROR","location":"[On_message:1442] data_ws","message":"'total_vol_traded'","timestamp":"2025-08-28 11:42:10,306+0530","service":"FyersDataSocket","exception":"Traceback (most recent call last):\n  File \"C:\\Python311\\Lib\\site-packages\\fyers_apiv3\\FyersWebsocket\\data_ws.py\", line 1433, in On_message\n    self.OnMessage(message)\n  File \"d:\\FyiersApiAutomation\\websocket\\fyers_websocket_ltp.py\", line 14, in onmessage\n    print(\"Symbol:\",message['symbol'],  \"Volume: \",message['total_vol_traded'])\n                                                   ~~~~~~~^^^^^^^^^^^^^^^^^^^^\nKeyError: 'total_vol_traded'","exception_name":"KeyError"}
{"level":"ERROR","location":"[On_message:1443] data_ws","message":"KeyError: The key 'total_vol_traded' is missing in the response.","timestamp":"2025-08-28 11:42:10,311+0530","service":"FyersDataSocket"}
{"level":"ERROR","location":"[On_message:1442] data_ws","message":"'total_vol_traded'","timestamp":"2025-08-28 11:42:11,580+0530","service":"FyersDataSocket","exception":"Traceback (most recent call last):\n  File \"C:\\Python311\\Lib\\site-packages\\fyers_apiv3\\FyersWebsocket\\data_ws.py\", line 1433, in On_message\n    self.OnMessage(message)\n  File \"d:\\FyiersApiAutomation\\websocket\\fyers_websocket_ltp.py\", line 14, in onmessage\n    print(\"Symbol:\",message['symbol'],  \"Volume: \",message['total_vol_traded'])\n                                                   ~~~~~~~^^^^^^^^^^^^^^^^^^^^\nKeyError: 'total_vol_traded'","exception_name":"KeyError"}
{"level":"ERROR","location":"[On_message:1443] data_ws","message":"KeyError: The key 'total_vol_traded' is missing in the response.","timestamp":"2025-08-28 11:42:11,580+0530","service":"FyersDataSocket"}
{"level":"ERROR","location":"[On_message:1442] data_ws","message":"'total_vol_traded'","timestamp":"2025-08-28 11:42:12,182+0530","service":"FyersDataSocket","exception":"Traceback (most recent call last):\n  File \"C:\\Python311\\Lib\\site-packages\\fyers_apiv3\\FyersWebsocket\\data_ws.py\", line 1433, in On_message\n    self.OnMessage(message)\n  File \"d:\\FyiersApiAutomation\\websocket\\fyers_websocket_ltp.py\", line 14, in onmessage\n    print(\"Symbol:\",message['symbol'],  \"Volume: \",message['total_vol_traded'])\n                                                   ~~~~~~~^^^^^^^^^^^^^^^^^^^^\nKeyError: 'total_vol_traded'","exception_name":"KeyError"}
{"level":"ERROR","location":"[On_message:1443] data_ws","message":"KeyError: The key 'total_vol_traded' is missing in the response.","timestamp":"2025-08-28 11:42:12,182+0530","service":"FyersDataSocket"}
{"level":"ERROR","location":"[On_message:1442] data_ws","message":"'total_vol_traded'","timestamp":"2025-08-28 11:42:12,897+0530","service":"FyersDataSocket","exception":"Traceback (most recent call last):\n  File \"C:\\Python311\\Lib\\site-packages\\fyers_apiv3\\FyersWebsocket\\data_ws.py\", line 1433, in On_message\n    self.OnMessage(message)\n  File \"d:\\FyiersApiAutomation\\websocket\\fyers_websocket_ltp.py\", line 14, in onmessage\n    print(\"Symbol:\",message['symbol'],  \"Volume: \",message['total_vol_traded'])\n                                                   ~~~~~~~^^^^^^^^^^^^^^^^^^^^\nKeyError: 'total_vol_traded'","exception_name":"KeyError"}
{"level":"ERROR","location":"[On_message:1443] data_ws","message":"KeyError: The key 'total_vol_traded' is missing in the response.","timestamp":"2025-08-28 11:42:12,897+0530","service":"FyersDataSocket"}
{"level":"ERROR","location":"[On_message:1442] data_ws","message":"'total_vol_traded'","timestamp":"2025-08-28 11:42:13,614+0530","service":"FyersDataSocket","exception":"Traceback (most recent call last):\n  File \"C:\\Python311\\Lib\\site-packages\\fyers_apiv3\\FyersWebsocket\\data_ws.py\", line 1433, in On_message\n    self.OnMessage(message)\n  File \"d:\\FyiersApiAutomation\\websocket\\fyers_websocket_ltp.py\", line 14, in onmessage\n    print(\"Symbol:\",message['symbol'],  \"Volume: \",message['total_vol_traded'])\n                                                   ~~~~~~~^^^^^^^^^^^^^^^^^^^^\nKeyError: 'total_vol_traded'","exception_name":"KeyError"}
{"level":"ERROR","location":"[On_message:1443] data_ws","message":"KeyError: The key 'total_vol_traded' is missing in the response.","timestamp":"2025-08-28 11:42:13,614+0530","service":"FyersDataSocket"}
{"level":"ERROR","location":"[On_message:1442] data_ws","message":"'total_vol_traded'","timestamp":"2025-08-28 11:42:14,070+0530","service":"FyersDataSocket","exception":"Traceback (most recent call last):\n  File \"C:\\Python311\\Lib\\site-packages\\fyers_apiv3\\FyersWebsocket\\data_ws.py\", line 1433, in On_message\n    self.OnMessage(message)\n  File \"d:\\FyiersApiAutomation\\websocket\\fyers_websocket_ltp.py\", line 14, in onmessage\n    print(\"Symbol:\",message['symbol'],  \"Volume: \",message['total_vol_traded'])\n                                                   ~~~~~~~^^^^^^^^^^^^^^^^^^^^\nKeyError: 'total_vol_traded'","exception_name":"KeyError"}
{"level":"ERROR","location":"[On_message:1443] data_ws","message":"KeyError: The key 'total_vol_traded' is missing in the response.","timestamp":"2025-08-28 11:42:14,070+0530","service":"FyersDataSocket"}
{"level":"ERROR","location":"[On_message:1442] data_ws","message":"'total_vol_traded'","timestamp":"2025-08-28 11:42:14,537+0530","service":"FyersDataSocket","exception":"Traceback (most recent call last):\n  File \"C:\\Python311\\Lib\\site-packages\\fyers_apiv3\\FyersWebsocket\\data_ws.py\", line 1433, in On_message\n    self.OnMessage(message)\n  File \"d:\\FyiersApiAutomation\\websocket\\fyers_websocket_ltp.py\", line 14, in onmessage\n    print(\"Symbol:\",message['symbol'],  \"Volume: \",message['total_vol_traded'])\n                                                   ~~~~~~~^^^^^^^^^^^^^^^^^^^^\nKeyError: 'total_vol_traded'","exception_name":"KeyError"}
{"level":"ERROR","location":"[On_message:1443] data_ws","message":"KeyError: The key 'total_vol_traded' is missing in the response.","timestamp":"2025-08-28 11:42:14,545+0530","service":"FyersDataSocket"}
{"level":"ERROR","location":"[On_message:1442] data_ws","message":"'total_vol_traded'","timestamp":"2025-08-28 11:42:15,305+0530","service":"FyersDataSocket","exception":"Traceback (most recent call last):\n  File \"C:\\Python311\\Lib\\site-packages\\fyers_apiv3\\FyersWebsocket\\data_ws.py\", line 1433, in On_message\n    self.OnMessage(message)\n  File \"d:\\FyiersApiAutomation\\websocket\\fyers_websocket_ltp.py\", line 14, in onmessage\n    print(\"Symbol:\",message['symbol'],  \"Volume: \",message['total_vol_traded'])\n                                                   ~~~~~~~^^^^^^^^^^^^^^^^^^^^\nKeyError: 'total_vol_traded'","exception_name":"KeyError"}
{"level":"ERROR","location":"[On_message:1443] data_ws","message":"KeyError: The key 'total_vol_traded' is missing in the response.","timestamp":"2025-08-28 11:42:15,305+0530","service":"FyersDataSocket"}
{"level":"ERROR","location":"[On_message:1442] data_ws","message":"'total_vol_traded'","timestamp":"2025-08-28 11:42:15,875+0530","service":"FyersDataSocket","exception":"Traceback (most recent call last):\n  File \"C:\\Python311\\Lib\\site-packages\\fyers_apiv3\\FyersWebsocket\\data_ws.py\", line 1433, in On_message\n    self.OnMessage(message)\n  File \"d:\\FyiersApiAutomation\\websocket\\fyers_websocket_ltp.py\", line 14, in onmessage\n    print(\"Symbol:\",message['symbol'],  \"Volume: \",message['total_vol_traded'])\n                                                   ~~~~~~~^^^^^^^^^^^^^^^^^^^^\nKeyError: 'total_vol_traded'","exception_name":"KeyError"}
{"level":"ERROR","location":"[On_message:1443] data_ws","message":"KeyError: The key 'total_vol_traded' is missing in the response.","timestamp":"2025-08-28 11:42:15,876+0530","service":"FyersDataSocket"}
{"level":"ERROR","location":"[On_message:1442] data_ws","message":"'total_vol_traded'","timestamp":"2025-08-28 11:42:16,101+0530","service":"FyersDataSocket","exception":"Traceback (most recent call last):\n  File \"C:\\Python311\\Lib\\site-packages\\fyers_apiv3\\FyersWebsocket\\data_ws.py\", line 1433, in On_message\n    self.OnMessage(message)\n  File \"d:\\FyiersApiAutomation\\websocket\\fyers_websocket_ltp.py\", line 14, in onmessage\n    print(\"Symbol:\",message['symbol'],  \"Volume: \",message['total_vol_traded'])\n                                                   ~~~~~~~^^^^^^^^^^^^^^^^^^^^\nKeyError: 'total_vol_traded'","exception_name":"KeyError"}
{"level":"ERROR","location":"[On_message:1443] data_ws","message":"KeyError: The key 'total_vol_traded' is missing in the response.","timestamp":"2025-08-28 11:42:16,101+0530","service":"FyersDataSocket"}
{"level":"ERROR","location":"[On_message:1442] data_ws","message":"'total_vol_traded'","timestamp":"2025-08-28 11:42:16,588+0530","service":"FyersDataSocket","exception":"Traceback (most recent call last):\n  File \"C:\\Python311\\Lib\\site-packages\\fyers_apiv3\\FyersWebsocket\\data_ws.py\", line 1433, in On_message\n    self.OnMessage(message)\n  File \"d:\\FyiersApiAutomation\\websocket\\fyers_websocket_ltp.py\", line 14, in onmessage\n    print(\"Symbol:\",message['symbol'],  \"Volume: \",message['total_vol_traded'])\n                                                   ~~~~~~~^^^^^^^^^^^^^^^^^^^^\nKeyError: 'total_vol_traded'","exception_name":"KeyError"}
{"level":"ERROR","location":"[On_message:1443] data_ws","message":"KeyError: The key 'total_vol_traded' is missing in the response.","timestamp":"2025-08-28 11:42:16,588+0530","service":"FyersDataSocket"}
{"level":"ERROR","location":"[On_message:1442] data_ws","message":"'symbol'","timestamp":"2025-08-28 11:44:16,097+0530","service":"FyersDataSocket","exception":"Traceback (most recent call last):\n  File \"C:\\Python311\\Lib\\site-packages\\fyers_apiv3\\FyersWebsocket\\data_ws.py\", line 1433, in On_message\n    self.OnMessage(message)\n  File \"d:\\FyiersApiAutomation\\websocket\\fyers_websocket_ltp.py\", line 14, in onmessage\n    print(\"Symbol:\",message['symbol'],  \"Volume: \",message['total_vol_traded'])\n                    ~~~~~~~^^^^^^^^^^\nKeyError: 'symbol'","exception_name":"KeyError"}
{"level":"ERROR","location":"[On_message:1443] data_ws","message":"KeyError: The key 'symbol' is missing in the response.","timestamp":"2025-08-28 11:44:16,099+0530","service":"FyersDataSocket"}
{"level":"ERROR","location":"[On_message:1442] data_ws","message":"'symbol'","timestamp":"2025-08-28 11:44:16,277+0530","service":"FyersDataSocket","exception":"Traceback (most recent call last):\n  File \"C:\\Python311\\Lib\\site-packages\\fyers_apiv3\\FyersWebsocket\\data_ws.py\", line 1433, in On_message\n    self.OnMessage(message)\n  File \"d:\\FyiersApiAutomation\\websocket\\fyers_websocket_ltp.py\", line 14, in onmessage\n    print(\"Symbol:\",message['symbol'],  \"Volume: \",message['total_vol_traded'])\n                    ~~~~~~~^^^^^^^^^^\nKeyError: 'symbol'","exception_name":"KeyError"}
{"level":"ERROR","location":"[On_message:1443] data_ws","message":"KeyError: The key 'symbol' is missing in the response.","timestamp":"2025-08-28 11:44:16,280+0530","service":"FyersDataSocket"}
{"level":"ERROR","location":"[On_message:1442] data_ws","message":"'symbol'","timestamp":"2025-08-28 11:44:18,087+0530","service":"FyersDataSocket","exception":"Traceback (most recent call last):\n  File \"C:\\Python311\\Lib\\site-packages\\fyers_apiv3\\FyersWebsocket\\data_ws.py\", line 1433, in On_message\n    self.OnMessage(message)\n  File \"d:\\FyiersApiAutomation\\websocket\\fyers_websocket_ltp.py\", line 14, in onmessage\n    print(\"Symbol:\",message['symbol'],  \"Volume: \",message['total_vol_traded'])\n                    ~~~~~~~^^^^^^^^^^\nKeyError: 'symbol'","exception_name":"KeyError"}
{"level":"ERROR","location":"[On_message:1443] data_ws","message":"KeyError: The key 'symbol' is missing in the response.","timestamp":"2025-08-28 11:44:18,102+0530","service":"FyersDataSocket"}
{"level":"ERROR","location":"[On_message:1442] data_ws","message":"'total_vol_traded'","timestamp":"2025-08-28 11:44:18,175+0530","service":"FyersDataSocket","exception":"Traceback (most recent call last):\n  File \"C:\\Python311\\Lib\\site-packages\\fyers_apiv3\\FyersWebsocket\\data_ws.py\", line 1433, in On_message\n    self.OnMessage(message)\n  File \"d:\\FyiersApiAutomation\\websocket\\fyers_websocket_ltp.py\", line 14, in onmessage\n    print(\"Symbol:\",message['symbol'],  \"Volume: \",message['total_vol_traded'])\n                                                   ~~~~~~~^^^^^^^^^^^^^^^^^^^^\nKeyError: 'total_vol_traded'","exception_name":"KeyError"}
{"level":"ERROR","location":"[On_message:1443] data_ws","message":"KeyError: The key 'total_vol_traded' is missing in the response.","timestamp":"2025-08-28 11:44:18,175+0530","service":"FyersDataSocket"}
{"level":"ERROR","location":"[On_message:1442] data_ws","message":"'total_vol_traded'","timestamp":"2025-08-28 11:44:18,478+0530","service":"FyersDataSocket","exception":"Traceback (most recent call last):\n  File \"C:\\Python311\\Lib\\site-packages\\fyers_apiv3\\FyersWebsocket\\data_ws.py\", line 1433, in On_message\n    self.OnMessage(message)\n  File \"d:\\FyiersApiAutomation\\websocket\\fyers_websocket_ltp.py\", line 14, in onmessage\n    print(\"Symbol:\",message['symbol'],  \"Volume: \",message['total_vol_traded'])\n                                                   ~~~~~~~^^^^^^^^^^^^^^^^^^^^\nKeyError: 'total_vol_traded'","exception_name":"KeyError"}
{"level":"ERROR","location":"[On_message:1443] data_ws","message":"KeyError: The key 'total_vol_traded' is missing in the response.","timestamp":"2025-08-28 11:44:18,478+0530","service":"FyersDataSocket"}
{"level":"ERROR","location":"[On_message:1442] data_ws","message":"'total_vol_traded'","timestamp":"2025-08-28 11:44:18,885+0530","service":"FyersDataSocket","exception":"Traceback (most recent call last):\n  File \"C:\\Python311\\Lib\\site-packages\\fyers_apiv3\\FyersWebsocket\\data_ws.py\", line 1433, in On_message\n    self.OnMessage(message)\n  File \"d:\\FyiersApiAutomation\\websocket\\fyers_websocket_ltp.py\", line 14, in onmessage\n    print(\"Symbol:\",message['symbol'],  \"Volume: \",message['total_vol_traded'])\n                                                   ~~~~~~~^^^^^^^^^^^^^^^^^^^^\nKeyError: 'total_vol_traded'","exception_name":"KeyError"}
{"level":"ERROR","location":"[On_message:1443] data_ws","message":"KeyError: The key 'total_vol_traded' is missing in the response.","timestamp":"2025-08-28 11:44:18,885+0530","service":"FyersDataSocket"}
{"level":"ERROR","location":"[On_message:1442] data_ws","message":"'total_vol_traded'","timestamp":"2025-08-28 11:44:19,772+0530","service":"FyersDataSocket","exception":"Traceback (most recent call last):\n  File \"C:\\Python311\\Lib\\site-packages\\fyers_apiv3\\FyersWebsocket\\data_ws.py\", line 1433, in On_message\n    self.OnMessage(message)\n  File \"d:\\FyiersApiAutomation\\websocket\\fyers_websocket_ltp.py\", line 14, in onmessage\n    print(\"Symbol:\",message['symbol'],  \"Volume: \",message['total_vol_traded'])\n                                                   ~~~~~~~^^^^^^^^^^^^^^^^^^^^\nKeyError: 'total_vol_traded'","exception_name":"KeyError"}
{"level":"ERROR","location":"[On_message:1443] data_ws","message":"KeyError: The key 'total_vol_traded' is missing in the response.","timestamp":"2025-08-28 11:44:19,772+0530","service":"FyersDataSocket"}
{"level":"ERROR","location":"[On_message:1442] data_ws","message":"'total_vol_traded'","timestamp":"2025-08-28 11:44:20,903+0530","service":"FyersDataSocket","exception":"Traceback (most recent call last):\n  File \"C:\\Python311\\Lib\\site-packages\\fyers_apiv3\\FyersWebsocket\\data_ws.py\", line 1433, in On_message\n    self.OnMessage(message)\n  File \"d:\\FyiersApiAutomation\\websocket\\fyers_websocket_ltp.py\", line 14, in onmessage\n    print(\"Symbol:\",message['symbol'],  \"Volume: \",message['total_vol_traded'])\n                                                   ~~~~~~~^^^^^^^^^^^^^^^^^^^^\nKeyError: 'total_vol_traded'","exception_name":"KeyError"}
{"level":"ERROR","location":"[On_message:1443] data_ws","message":"KeyError: The key 'total_vol_traded' is missing in the response.","timestamp":"2025-08-28 11:44:20,903+0530","service":"FyersDataSocket"}
{"level":"ERROR","location":"[On_message:1442] data_ws","message":"'total_vol_traded'","timestamp":"2025-08-28 11:44:20,967+0530","service":"FyersDataSocket","exception":"Traceback (most recent call last):\n  File \"C:\\Python311\\Lib\\site-packages\\fyers_apiv3\\FyersWebsocket\\data_ws.py\", line 1433, in On_message\n    self.OnMessage(message)\n  File \"d:\\FyiersApiAutomation\\websocket\\fyers_websocket_ltp.py\", line 14, in onmessage\n    print(\"Symbol:\",message['symbol'],  \"Volume: \",message['total_vol_traded'])\n                                                   ~~~~~~~^^^^^^^^^^^^^^^^^^^^\nKeyError: 'total_vol_traded'","exception_name":"KeyError"}
{"level":"ERROR","location":"[On_message:1443] data_ws","message":"KeyError: The key 'total_vol_traded' is missing in the response.","timestamp":"2025-08-28 11:44:20,967+0530","service":"FyersDataSocket"}
{"level":"ERROR","location":"[On_message:1442] data_ws","message":"'total_vol_traded'","timestamp":"2025-08-28 11:44:21,458+0530","service":"FyersDataSocket","exception":"Traceback (most recent call last):\n  File \"C:\\Python311\\Lib\\site-packages\\fyers_apiv3\\FyersWebsocket\\data_ws.py\", line 1433, in On_message\n    self.OnMessage(message)\n  File \"d:\\FyiersApiAutomation\\websocket\\fyers_websocket_ltp.py\", line 14, in onmessage\n    print(\"Symbol:\",message['symbol'],  \"Volume: \",message['total_vol_traded'])\n                                                   ~~~~~~~^^^^^^^^^^^^^^^^^^^^\nKeyError: 'total_vol_traded'","exception_name":"KeyError"}
{"level":"ERROR","location":"[On_message:1443] data_ws","message":"KeyError: The key 'total_vol_traded' is missing in the response.","timestamp":"2025-08-28 11:44:21,458+0530","service":"FyersDataSocket"}
{"level":"ERROR","location":"[On_message:1442] data_ws","message":"'total_vol_traded'","timestamp":"2025-08-28 11:44:22,432+0530","service":"FyersDataSocket","exception":"Traceback (most recent call last):\n  File \"C:\\Python311\\Lib\\site-packages\\fyers_apiv3\\FyersWebsocket\\data_ws.py\", line 1433, in On_message\n    self.OnMessage(message)\n  File \"d:\\FyiersApiAutomation\\websocket\\fyers_websocket_ltp.py\", line 14, in onmessage\n    print(\"Symbol:\",message['symbol'],  \"Volume: \",message['total_vol_traded'])\n                                                   ~~~~~~~^^^^^^^^^^^^^^^^^^^^\nKeyError: 'total_vol_traded'","exception_name":"KeyError"}
{"level":"ERROR","location":"[On_message:1443] data_ws","message":"KeyError: The key 'total_vol_traded' is missing in the response.","timestamp":"2025-08-28 11:44:22,444+0530","service":"FyersDataSocket"}
{"level":"ERROR","location":"[On_message:1442] data_ws","message":"'total_vol_traded'","timestamp":"2025-08-28 11:44:22,488+0530","service":"FyersDataSocket","exception":"Traceback (most recent call last):\n  File \"C:\\Python311\\Lib\\site-packages\\fyers_apiv3\\FyersWebsocket\\data_ws.py\", line 1433, in On_message\n    self.OnMessage(message)\n  File \"d:\\FyiersApiAutomation\\websocket\\fyers_websocket_ltp.py\", line 14, in onmessage\n    print(\"Symbol:\",message['symbol'],  \"Volume: \",message['total_vol_traded'])\n                                                   ~~~~~~~^^^^^^^^^^^^^^^^^^^^\nKeyError: 'total_vol_traded'","exception_name":"KeyError"}
{"level":"ERROR","location":"[On_message:1443] data_ws","message":"KeyError: The key 'total_vol_traded' is missing in the response.","timestamp":"2025-08-28 11:44:22,493+0530","service":"FyersDataSocket"}
{"level":"ERROR","location":"[On_message:1442] data_ws","message":"'total_vol_traded'","timestamp":"2025-08-28 11:44:23,252+0530","service":"FyersDataSocket","exception":"Traceback (most recent call last):\n  File \"C:\\Python311\\Lib\\site-packages\\fyers_apiv3\\FyersWebsocket\\data_ws.py\", line 1433, in On_message\n    self.OnMessage(message)\n  File \"d:\\FyiersApiAutomation\\websocket\\fyers_websocket_ltp.py\", line 14, in onmessage\n    print(\"Symbol:\",message['symbol'],  \"Volume: \",message['total_vol_traded'])\n                                                   ~~~~~~~^^^^^^^^^^^^^^^^^^^^\nKeyError: 'total_vol_traded'","exception_name":"KeyError"}
{"level":"ERROR","location":"[On_message:1443] data_ws","message":"KeyError: The key 'total_vol_traded' is missing in the response.","timestamp":"2025-08-28 11:44:23,252+0530","service":"FyersDataSocket"}
{"level":"ERROR","location":"[On_message:1442] data_ws","message":"'total_vol_traded'","timestamp":"2025-08-28 11:44:23,287+0530","service":"FyersDataSocket","exception":"Traceback (most recent call last):\n  File \"C:\\Python311\\Lib\\site-packages\\fyers_apiv3\\FyersWebsocket\\data_ws.py\", line 1433, in On_message\n    self.OnMessage(message)\n  File \"d:\\FyiersApiAutomation\\websocket\\fyers_websocket_ltp.py\", line 14, in onmessage\n    print(\"Symbol:\",message['symbol'],  \"Volume: \",message['total_vol_traded'])\n                                                   ~~~~~~~^^^^^^^^^^^^^^^^^^^^\nKeyError: 'total_vol_traded'","exception_name":"KeyError"}
{"level":"ERROR","location":"[On_message:1443] data_ws","message":"KeyError: The key 'total_vol_traded' is missing in the response.","timestamp":"2025-08-28 11:44:23,291+0530","service":"FyersDataSocket"}
{"level":"ERROR","location":"[On_message:1442] data_ws","message":"'total_vol_traded'","timestamp":"2025-08-28 11:44:24,174+0530","service":"FyersDataSocket","exception":"Traceback (most recent call last):\n  File \"C:\\Python311\\Lib\\site-packages\\fyers_apiv3\\FyersWebsocket\\data_ws.py\", line 1433, in On_message\n    self.OnMessage(message)\n  File \"d:\\FyiersApiAutomation\\websocket\\fyers_websocket_ltp.py\", line 14, in onmessage\n    print(\"Symbol:\",message['symbol'],  \"Volume: \",message['total_vol_traded'])\n                                                   ~~~~~~~^^^^^^^^^^^^^^^^^^^^\nKeyError: 'total_vol_traded'","exception_name":"KeyError"}
{"level":"ERROR","location":"[On_message:1443] data_ws","message":"KeyError: The key 'total_vol_traded' is missing in the response.","timestamp":"2025-08-28 11:44:24,174+0530","service":"FyersDataSocket"}
{"level":"ERROR","location":"[On_message:1442] data_ws","message":"'total_vol_traded'","timestamp":"2025-08-28 11:44:24,653+0530","service":"FyersDataSocket","exception":"Traceback (most recent call last):\n  File \"C:\\Python311\\Lib\\site-packages\\fyers_apiv3\\FyersWebsocket\\data_ws.py\", line 1433, in On_message\n    self.OnMessage(message)\n  File \"d:\\FyiersApiAutomation\\websocket\\fyers_websocket_ltp.py\", line 14, in onmessage\n    print(\"Symbol:\",message['symbol'],  \"Volume: \",message['total_vol_traded'])\n                                                   ~~~~~~~^^^^^^^^^^^^^^^^^^^^\nKeyError: 'total_vol_traded'","exception_name":"KeyError"}
{"level":"ERROR","location":"[On_message:1443] data_ws","message":"KeyError: The key 'total_vol_traded' is missing in the response.","timestamp":"2025-08-28 11:44:24,655+0530","service":"FyersDataSocket"}
{"level":"ERROR","location":"[On_message:1442] data_ws","message":"'total_vol_traded'","timestamp":"2025-08-28 11:44:25,196+0530","service":"FyersDataSocket","exception":"Traceback (most recent call last):\n  File \"C:\\Python311\\Lib\\site-packages\\fyers_apiv3\\FyersWebsocket\\data_ws.py\", line 1433, in On_message\n    self.OnMessage(message)\n  File \"d:\\FyiersApiAutomation\\websocket\\fyers_websocket_ltp.py\", line 14, in onmessage\n    print(\"Symbol:\",message['symbol'],  \"Volume: \",message['total_vol_traded'])\n                                                   ~~~~~~~^^^^^^^^^^^^^^^^^^^^\nKeyError: 'total_vol_traded'","exception_name":"KeyError"}
{"level":"ERROR","location":"[On_message:1443] data_ws","message":"KeyError: The key 'total_vol_traded' is missing in the response.","timestamp":"2025-08-28 11:44:25,196+0530","service":"FyersDataSocket"}
{"level":"ERROR","location":"[On_message:1442] data_ws","message":"'total_vol_traded'","timestamp":"2025-08-28 11:44:25,858+0530","service":"FyersDataSocket","exception":"Traceback (most recent call last):\n  File \"C:\\Python311\\Lib\\site-packages\\fyers_apiv3\\FyersWebsocket\\data_ws.py\", line 1433, in On_message\n    self.OnMessage(message)\n  File \"d:\\FyiersApiAutomation\\websocket\\fyers_websocket_ltp.py\", line 14, in onmessage\n    print(\"Symbol:\",message['symbol'],  \"Volume: \",message['total_vol_traded'])\n                                                   ~~~~~~~^^^^^^^^^^^^^^^^^^^^\nKeyError: 'total_vol_traded'","exception_name":"KeyError"}
{"level":"ERROR","location":"[On_message:1443] data_ws","message":"KeyError: The key 'total_vol_traded' is missing in the response.","timestamp":"2025-08-28 11:44:25,858+0530","service":"FyersDataSocket"}
{"level":"ERROR","location":"[On_message:1442] data_ws","message":"'total_vol_traded'","timestamp":"2025-08-28 11:44:27,250+0530","service":"FyersDataSocket","exception":"Traceback (most recent call last):\n  File \"C:\\Python311\\Lib\\site-packages\\fyers_apiv3\\FyersWebsocket\\data_ws.py\", line 1433, in On_message\n    self.OnMessage(message)\n  File \"d:\\FyiersApiAutomation\\websocket\\fyers_websocket_ltp.py\", line 14, in onmessage\n    print(\"Symbol:\",message['symbol'],  \"Volume: \",message['total_vol_traded'])\n                                                   ~~~~~~~^^^^^^^^^^^^^^^^^^^^\nKeyError: 'total_vol_traded'","exception_name":"KeyError"}
{"level":"ERROR","location":"[On_message:1443] data_ws","message":"KeyError: The key 'total_vol_traded' is missing in the response.","timestamp":"2025-08-28 11:44:27,250+0530","service":"FyersDataSocket"}
{"level":"ERROR","location":"[On_message:1442] data_ws","message":"'total_vol_traded'","timestamp":"2025-08-28 11:44:28,470+0530","service":"FyersDataSocket","exception":"Traceback (most recent call last):\n  File \"C:\\Python311\\Lib\\site-packages\\fyers_apiv3\\FyersWebsocket\\data_ws.py\", line 1433, in On_message\n    self.OnMessage(message)\n  File \"d:\\FyiersApiAutomation\\websocket\\fyers_websocket_ltp.py\", line 14, in onmessage\n    print(\"Symbol:\",message['symbol'],  \"Volume: \",message['total_vol_traded'])\n                                                   ~~~~~~~^^^^^^^^^^^^^^^^^^^^\nKeyError: 'total_vol_traded'","exception_name":"KeyError"}
{"level":"ERROR","location":"[On_message:1443] data_ws","message":"KeyError: The key 'total_vol_traded' is missing in the response.","timestamp":"2025-08-28 11:44:28,487+0530","service":"FyersDataSocket"}
{"level":"ERROR","location":"[On_message:1442] data_ws","message":"'total_vol_traded'","timestamp":"2025-08-28 11:44:28,542+0530","service":"FyersDataSocket","exception":"Traceback (most recent call last):\n  File \"C:\\Python311\\Lib\\site-packages\\fyers_apiv3\\FyersWebsocket\\data_ws.py\", line 1433, in On_message\n    self.OnMessage(message)\n  File \"d:\\FyiersApiAutomation\\websocket\\fyers_websocket_ltp.py\", line 14, in onmessage\n    print(\"Symbol:\",message['symbol'],  \"Volume: \",message['total_vol_traded'])\n                                                   ~~~~~~~^^^^^^^^^^^^^^^^^^^^\nKeyError: 'total_vol_traded'","exception_name":"KeyError"}
{"level":"ERROR","location":"[On_message:1443] data_ws","message":"KeyError: The key 'total_vol_traded' is missing in the response.","timestamp":"2025-08-28 11:44:28,542+0530","service":"FyersDataSocket"}
{"level":"ERROR","location":"[On_message:1442] data_ws","message":"'total_vol_traded'","timestamp":"2025-08-28 11:44:28,887+0530","service":"FyersDataSocket","exception":"Traceback (most recent call last):\n  File \"C:\\Python311\\Lib\\site-packages\\fyers_apiv3\\FyersWebsocket\\data_ws.py\", line 1433, in On_message\n    self.OnMessage(message)\n  File \"d:\\FyiersApiAutomation\\websocket\\fyers_websocket_ltp.py\", line 14, in onmessage\n    print(\"Symbol:\",message['symbol'],  \"Volume: \",message['total_vol_traded'])\n                                                   ~~~~~~~^^^^^^^^^^^^^^^^^^^^\nKeyError: 'total_vol_traded'","exception_name":"KeyError"}
{"level":"ERROR","location":"[On_message:1443] data_ws","message":"KeyError: The key 'total_vol_traded' is missing in the response.","timestamp":"2025-08-28 11:44:28,897+0530","service":"FyersDataSocket"}
{"level":"ERROR","location":"[On_message:1442] data_ws","message":"'total_vol_traded'","timestamp":"2025-08-28 11:44:29,399+0530","service":"FyersDataSocket","exception":"Traceback (most recent call last):\n  File \"C:\\Python311\\Lib\\site-packages\\fyers_apiv3\\FyersWebsocket\\data_ws.py\", line 1433, in On_message\n    self.OnMessage(message)\n  File \"d:\\FyiersApiAutomation\\websocket\\fyers_websocket_ltp.py\", line 14, in onmessage\n    print(\"Symbol:\",message['symbol'],  \"Volume: \",message['total_vol_traded'])\n                                                   ~~~~~~~^^^^^^^^^^^^^^^^^^^^\nKeyError: 'total_vol_traded'","exception_name":"KeyError"}
{"level":"ERROR","location":"[On_message:1443] data_ws","message":"KeyError: The key 'total_vol_traded' is missing in the response.","timestamp":"2025-08-28 11:44:29,399+0530","service":"FyersDataSocket"}
{"level":"ERROR","location":"[On_message:1442] data_ws","message":"'total_vol_traded'","timestamp":"2025-08-28 11:44:31,143+0530","service":"FyersDataSocket","exception":"Traceback (most recent call last):\n  File \"C:\\Python311\\Lib\\site-packages\\fyers_apiv3\\FyersWebsocket\\data_ws.py\", line 1433, in On_message\n    self.OnMessage(message)\n  File \"d:\\FyiersApiAutomation\\websocket\\fyers_websocket_ltp.py\", line 14, in onmessage\n    print(\"Symbol:\",message['symbol'],  \"Volume: \",message['total_vol_traded'])\n                                                   ~~~~~~~^^^^^^^^^^^^^^^^^^^^\nKeyError: 'total_vol_traded'","exception_name":"KeyError"}
{"level":"ERROR","location":"[On_message:1443] data_ws","message":"KeyError: The key 'total_vol_traded' is missing in the response.","timestamp":"2025-08-28 11:44:31,147+0530","service":"FyersDataSocket"}
{"level":"ERROR","location":"[On_message:1442] data_ws","message":"'total_vol_traded'","timestamp":"2025-08-28 11:44:31,952+0530","service":"FyersDataSocket","exception":"Traceback (most recent call last):\n  File \"C:\\Python311\\Lib\\site-packages\\fyers_apiv3\\FyersWebsocket\\data_ws.py\", line 1433, in On_message\n    self.OnMessage(message)\n  File \"d:\\FyiersApiAutomation\\websocket\\fyers_websocket_ltp.py\", line 14, in onmessage\n    print(\"Symbol:\",message['symbol'],  \"Volume: \",message['total_vol_traded'])\n                                                   ~~~~~~~^^^^^^^^^^^^^^^^^^^^\nKeyError: 'total_vol_traded'","exception_name":"KeyError"}
{"level":"ERROR","location":"[On_message:1443] data_ws","message":"KeyError: The key 'total_vol_traded' is missing in the response.","timestamp":"2025-08-28 11:44:31,968+0530","service":"FyersDataSocket"}
{"level":"ERROR","location":"[On_message:1442] data_ws","message":"'total_vol_traded'","timestamp":"2025-08-28 11:44:32,874+0530","service":"FyersDataSocket","exception":"Traceback (most recent call last):\n  File \"C:\\Python311\\Lib\\site-packages\\fyers_apiv3\\FyersWebsocket\\data_ws.py\", line 1433, in On_message\n    self.OnMessage(message)\n  File \"d:\\FyiersApiAutomation\\websocket\\fyers_websocket_ltp.py\", line 14, in onmessage\n    print(\"Symbol:\",message['symbol'],  \"Volume: \",message['total_vol_traded'])\n                                                   ~~~~~~~^^^^^^^^^^^^^^^^^^^^\nKeyError: 'total_vol_traded'","exception_name":"KeyError"}
{"level":"ERROR","location":"[On_message:1443] data_ws","message":"KeyError: The key 'total_vol_traded' is missing in the response.","timestamp":"2025-08-28 11:44:32,889+0530","service":"FyersDataSocket"}
{"level":"ERROR","location":"[On_message:1442] data_ws","message":"'total_vol_traded'","timestamp":"2025-08-28 11:44:33,188+0530","service":"FyersDataSocket","exception":"Traceback (most recent call last):\n  File \"C:\\Python311\\Lib\\site-packages\\fyers_apiv3\\FyersWebsocket\\data_ws.py\", line 1433, in On_message\n    self.OnMessage(message)\n  File \"d:\\FyiersApiAutomation\\websocket\\fyers_websocket_ltp.py\", line 14, in onmessage\n    print(\"Symbol:\",message['symbol'],  \"Volume: \",message['total_vol_traded'])\n                                                   ~~~~~~~^^^^^^^^^^^^^^^^^^^^\nKeyError: 'total_vol_traded'","exception_name":"KeyError"}
{"level":"ERROR","location":"[On_message:1443] data_ws","message":"KeyError: The key 'total_vol_traded' is missing in the response.","timestamp":"2025-08-28 11:44:33,188+0530","service":"FyersDataSocket"}
{"level":"ERROR","location":"[On_message:1442] data_ws","message":"'total_vol_traded'","timestamp":"2025-08-28 11:44:33,296+0530","service":"FyersDataSocket","exception":"Traceback (most recent call last):\n  File \"C:\\Python311\\Lib\\site-packages\\fyers_apiv3\\FyersWebsocket\\data_ws.py\", line 1433, in On_message\n    self.OnMessage(message)\n  File \"d:\\FyiersApiAutomation\\websocket\\fyers_websocket_ltp.py\", line 14, in onmessage\n    print(\"Symbol:\",message['symbol'],  \"Volume: \",message['total_vol_traded'])\n                                                   ~~~~~~~^^^^^^^^^^^^^^^^^^^^\nKeyError: 'total_vol_traded'","exception_name":"KeyError"}
{"level":"ERROR","location":"[On_message:1443] data_ws","message":"KeyError: The key 'total_vol_traded' is missing in the response.","timestamp":"2025-08-28 11:44:33,296+0530","service":"FyersDataSocket"}
{"level":"ERROR","location":"[On_message:1442] data_ws","message":"'total_vol_traded'","timestamp":"2025-08-28 11:44:34,102+0530","service":"FyersDataSocket","exception":"Traceback (most recent call last):\n  File \"C:\\Python311\\Lib\\site-packages\\fyers_apiv3\\FyersWebsocket\\data_ws.py\", line 1433, in On_message\n    self.OnMessage(message)\n  File \"d:\\FyiersApiAutomation\\websocket\\fyers_websocket_ltp.py\", line 14, in onmessage\n    print(\"Symbol:\",message['symbol'],  \"Volume: \",message['total_vol_traded'])\n                                                   ~~~~~~~^^^^^^^^^^^^^^^^^^^^\nKeyError: 'total_vol_traded'","exception_name":"KeyError"}
{"level":"ERROR","location":"[On_message:1443] data_ws","message":"KeyError: The key 'total_vol_traded' is missing in the response.","timestamp":"2025-08-28 11:44:34,110+0530","service":"FyersDataSocket"}
{"level":"ERROR","location":"[On_message:1442] data_ws","message":"'total_vol_traded'","timestamp":"2025-08-28 11:44:34,518+0530","service":"FyersDataSocket","exception":"Traceback (most recent call last):\n  File \"C:\\Python311\\Lib\\site-packages\\fyers_apiv3\\FyersWebsocket\\data_ws.py\", line 1433, in On_message\n    self.OnMessage(message)\n  File \"d:\\FyiersApiAutomation\\websocket\\fyers_websocket_ltp.py\", line 14, in onmessage\n    print(\"Symbol:\",message['symbol'],  \"Volume: \",message['total_vol_traded'])\n                                                   ~~~~~~~^^^^^^^^^^^^^^^^^^^^\nKeyError: 'total_vol_traded'","exception_name":"KeyError"}
{"level":"ERROR","location":"[On_message:1443] data_ws","message":"KeyError: The key 'total_vol_traded' is missing in the response.","timestamp":"2025-08-28 11:44:34,518+0530","service":"FyersDataSocket"}
{"level":"ERROR","location":"[On_message:1442] data_ws","message":"'total_vol_traded'","timestamp":"2025-08-28 11:44:34,924+0530","service":"FyersDataSocket","exception":"Traceback (most recent call last):\n  File \"C:\\Python311\\Lib\\site-packages\\fyers_apiv3\\FyersWebsocket\\data_ws.py\", line 1433, in On_message\n    self.OnMessage(message)\n  File \"d:\\FyiersApiAutomation\\websocket\\fyers_websocket_ltp.py\", line 14, in onmessage\n    print(\"Symbol:\",message['symbol'],  \"Volume: \",message['total_vol_traded'])\n                                                   ~~~~~~~^^^^^^^^^^^^^^^^^^^^\nKeyError: 'total_vol_traded'","exception_name":"KeyError"}
{"level":"ERROR","location":"[On_message:1443] data_ws","message":"KeyError: The key 'total_vol_traded' is missing in the response.","timestamp":"2025-08-28 11:44:34,924+0530","service":"FyersDataSocket"}
{"level":"ERROR","location":"[On_message:1442] data_ws","message":"'total_vol_traded'","timestamp":"2025-08-28 11:44:35,330+0530","service":"FyersDataSocket","exception":"Traceback (most recent call last):\n  File \"C:\\Python311\\Lib\\site-packages\\fyers_apiv3\\FyersWebsocket\\data_ws.py\", line 1433, in On_message\n    self.OnMessage(message)\n  File \"d:\\FyiersApiAutomation\\websocket\\fyers_websocket_ltp.py\", line 14, in onmessage\n    print(\"Symbol:\",message['symbol'],  \"Volume: \",message['total_vol_traded'])\n                                                   ~~~~~~~^^^^^^^^^^^^^^^^^^^^\nKeyError: 'total_vol_traded'","exception_name":"KeyError"}
{"level":"ERROR","location":"[On_message:1443] data_ws","message":"KeyError: The key 'total_vol_traded' is missing in the response.","timestamp":"2025-08-28 11:44:35,330+0530","service":"FyersDataSocket"}
{"level":"ERROR","location":"[On_message:1442] data_ws","message":"'total_vol_traded'","timestamp":"2025-08-28 11:44:36,153+0530","service":"FyersDataSocket","exception":"Traceback (most recent call last):\n  File \"C:\\Python311\\Lib\\site-packages\\fyers_apiv3\\FyersWebsocket\\data_ws.py\", line 1433, in On_message\n    self.OnMessage(message)\n  File \"d:\\FyiersApiAutomation\\websocket\\fyers_websocket_ltp.py\", line 14, in onmessage\n    print(\"Symbol:\",message['symbol'],  \"Volume: \",message['total_vol_traded'])\n                                                   ~~~~~~~^^^^^^^^^^^^^^^^^^^^\nKeyError: 'total_vol_traded'","exception_name":"KeyError"}
{"level":"ERROR","location":"[On_message:1443] data_ws","message":"KeyError: The key 'total_vol_traded' is missing in the response.","timestamp":"2025-08-28 11:44:36,153+0530","service":"FyersDataSocket"}
{"level":"ERROR","location":"[On_message:1442] data_ws","message":"'total_vol_traded'","timestamp":"2025-08-28 11:44:37,396+0530","service":"FyersDataSocket","exception":"Traceback (most recent call last):\n  File \"C:\\Python311\\Lib\\site-packages\\fyers_apiv3\\FyersWebsocket\\data_ws.py\", line 1433, in On_message\n    self.OnMessage(message)\n  File \"d:\\FyiersApiAutomation\\websocket\\fyers_websocket_ltp.py\", line 14, in onmessage\n    print(\"Symbol:\",message['symbol'],  \"Volume: \",message['total_vol_traded'])\n                                                   ~~~~~~~^^^^^^^^^^^^^^^^^^^^\nKeyError: 'total_vol_traded'","exception_name":"KeyError"}
{"level":"ERROR","location":"[On_message:1443] data_ws","message":"KeyError: The key 'total_vol_traded' is missing in the response.","timestamp":"2025-08-28 11:44:37,398+0530","service":"FyersDataSocket"}
{"level":"ERROR","location":"[On_message:1442] data_ws","message":"'total_vol_traded'","timestamp":"2025-08-28 11:44:37,905+0530","service":"FyersDataSocket","exception":"Traceback (most recent call last):\n  File \"C:\\Python311\\Lib\\site-packages\\fyers_apiv3\\FyersWebsocket\\data_ws.py\", line 1433, in On_message\n    self.OnMessage(message)\n  File \"d:\\FyiersApiAutomation\\websocket\\fyers_websocket_ltp.py\", line 14, in onmessage\n    print(\"Symbol:\",message['symbol'],  \"Volume: \",message['total_vol_traded'])\n                                                   ~~~~~~~^^^^^^^^^^^^^^^^^^^^\nKeyError: 'total_vol_traded'","exception_name":"KeyError"}
{"level":"ERROR","location":"[On_message:1443] data_ws","message":"KeyError: The key 'total_vol_traded' is missing in the response.","timestamp":"2025-08-28 11:44:37,907+0530","service":"FyersDataSocket"}
{"level":"ERROR","location":"[On_message:1442] data_ws","message":"'total_vol_traded'","timestamp":"2025-08-28 11:44:38,618+0530","service":"FyersDataSocket","exception":"Traceback (most recent call last):\n  File \"C:\\Python311\\Lib\\site-packages\\fyers_apiv3\\FyersWebsocket\\data_ws.py\", line 1433, in On_message\n    self.OnMessage(message)\n  File \"d:\\FyiersApiAutomation\\websocket\\fyers_websocket_ltp.py\", line 14, in onmessage\n    print(\"Symbol:\",message['symbol'],  \"Volume: \",message['total_vol_traded'])\n                                                   ~~~~~~~^^^^^^^^^^^^^^^^^^^^\nKeyError: 'total_vol_traded'","exception_name":"KeyError"}
{"level":"ERROR","location":"[On_message:1443] data_ws","message":"KeyError: The key 'total_vol_traded' is missing in the response.","timestamp":"2025-08-28 11:44:38,626+0530","service":"FyersDataSocket"}
{"level":"ERROR","location":"[On_message:1442] data_ws","message":"'total_vol_traded'","timestamp":"2025-08-28 11:44:39,127+0530","service":"FyersDataSocket","exception":"Traceback (most recent call last):\n  File \"C:\\Python311\\Lib\\site-packages\\fyers_apiv3\\FyersWebsocket\\data_ws.py\", line 1433, in On_message\n    self.OnMessage(message)\n  File \"d:\\FyiersApiAutomation\\websocket\\fyers_websocket_ltp.py\", line 14, in onmessage\n    print(\"Symbol:\",message['symbol'],  \"Volume: \",message['total_vol_traded'])\n                                                   ~~~~~~~^^^^^^^^^^^^^^^^^^^^\nKeyError: 'total_vol_traded'","exception_name":"KeyError"}
{"level":"ERROR","location":"[On_message:1443] data_ws","message":"KeyError: The key 'total_vol_traded' is missing in the response.","timestamp":"2025-08-28 11:44:39,135+0530","service":"FyersDataSocket"}
{"level":"ERROR","location":"[On_message:1442] data_ws","message":"'total_vol_traded'","timestamp":"2025-08-28 11:44:39,329+0530","service":"FyersDataSocket","exception":"Traceback (most recent call last):\n  File \"C:\\Python311\\Lib\\site-packages\\fyers_apiv3\\FyersWebsocket\\data_ws.py\", line 1433, in On_message\n    self.OnMessage(message)\n  File \"d:\\FyiersApiAutomation\\websocket\\fyers_websocket_ltp.py\", line 14, in onmessage\n    print(\"Symbol:\",message['symbol'],  \"Volume: \",message['total_vol_traded'])\n                                                   ~~~~~~~^^^^^^^^^^^^^^^^^^^^\nKeyError: 'total_vol_traded'","exception_name":"KeyError"}
{"level":"ERROR","location":"[On_message:1443] data_ws","message":"KeyError: The key 'total_vol_traded' is missing in the response.","timestamp":"2025-08-28 11:44:39,342+0530","service":"FyersDataSocket"}
{"level":"ERROR","location":"[On_message:1442] data_ws","message":"'total_vol_traded'","timestamp":"2025-08-28 11:44:40,546+0530","service":"FyersDataSocket","exception":"Traceback (most recent call last):\n  File \"C:\\Python311\\Lib\\site-packages\\fyers_apiv3\\FyersWebsocket\\data_ws.py\", line 1433, in On_message\n    self.OnMessage(message)\n  File \"d:\\FyiersApiAutomation\\websocket\\fyers_websocket_ltp.py\", line 14, in onmessage\n    print(\"Symbol:\",message['symbol'],  \"Volume: \",message['total_vol_traded'])\n                                                   ~~~~~~~^^^^^^^^^^^^^^^^^^^^\nKeyError: 'total_vol_traded'","exception_name":"KeyError"}
{"level":"ERROR","location":"[On_message:1443] data_ws","message":"KeyError: The key 'total_vol_traded' is missing in the response.","timestamp":"2025-08-28 11:44:40,546+0530","service":"FyersDataSocket"}
{"level":"ERROR","location":"[On_message:1442] data_ws","message":"'total_vol_traded'","timestamp":"2025-08-28 11:44:40,946+0530","service":"FyersDataSocket","exception":"Traceback (most recent call last):\n  File \"C:\\Python311\\Lib\\site-packages\\fyers_apiv3\\FyersWebsocket\\data_ws.py\", line 1433, in On_message\n    self.OnMessage(message)\n  File \"d:\\FyiersApiAutomation\\websocket\\fyers_websocket_ltp.py\", line 14, in onmessage\n    print(\"Symbol:\",message['symbol'],  \"Volume: \",message['total_vol_traded'])\n                                                   ~~~~~~~^^^^^^^^^^^^^^^^^^^^\nKeyError: 'total_vol_traded'","exception_name":"KeyError"}
{"level":"ERROR","location":"[On_message:1443] data_ws","message":"KeyError: The key 'total_vol_traded' is missing in the response.","timestamp":"2025-08-28 11:44:40,961+0530","service":"FyersDataSocket"}
{"level":"ERROR","location":"[On_message:1442] data_ws","message":"'total_vol_traded'","timestamp":"2025-08-28 11:44:41,379+0530","service":"FyersDataSocket","exception":"Traceback (most recent call last):\n  File \"C:\\Python311\\Lib\\site-packages\\fyers_apiv3\\FyersWebsocket\\data_ws.py\", line 1433, in On_message\n    self.OnMessage(message)\n  File \"d:\\FyiersApiAutomation\\websocket\\fyers_websocket_ltp.py\", line 14, in onmessage\n    print(\"Symbol:\",message['symbol'],  \"Volume: \",message['total_vol_traded'])\n                                                   ~~~~~~~^^^^^^^^^^^^^^^^^^^^\nKeyError: 'total_vol_traded'","exception_name":"KeyError"}
{"level":"ERROR","location":"[On_message:1443] data_ws","message":"KeyError: The key 'total_vol_traded' is missing in the response.","timestamp":"2025-08-28 11:44:41,379+0530","service":"FyersDataSocket"}
{"level":"ERROR","location":"[On_message:1442] data_ws","message":"'total_vol_traded'","timestamp":"2025-08-28 11:44:42,305+0530","service":"FyersDataSocket","exception":"Traceback (most recent call last):\n  File \"C:\\Python311\\Lib\\site-packages\\fyers_apiv3\\FyersWebsocket\\data_ws.py\", line 1433, in On_message\n    self.OnMessage(message)\n  File \"d:\\FyiersApiAutomation\\websocket\\fyers_websocket_ltp.py\", line 14, in onmessage\n    print(\"Symbol:\",message['symbol'],  \"Volume: \",message['total_vol_traded'])\n                                                   ~~~~~~~^^^^^^^^^^^^^^^^^^^^\nKeyError: 'total_vol_traded'","exception_name":"KeyError"}
{"level":"ERROR","location":"[On_message:1443] data_ws","message":"KeyError: The key 'total_vol_traded' is missing in the response.","timestamp":"2025-08-28 11:44:42,309+0530","service":"FyersDataSocket"}
{"level":"ERROR","location":"[On_message:1442] data_ws","message":"'total_vol_traded'","timestamp":"2025-08-28 11:44:43,129+0530","service":"FyersDataSocket","exception":"Traceback (most recent call last):\n  File \"C:\\Python311\\Lib\\site-packages\\fyers_apiv3\\FyersWebsocket\\data_ws.py\", line 1433, in On_message\n    self.OnMessage(message)\n  File \"d:\\FyiersApiAutomation\\websocket\\fyers_websocket_ltp.py\", line 14, in onmessage\n    print(\"Symbol:\",message['symbol'],  \"Volume: \",message['total_vol_traded'])\n                                                   ~~~~~~~^^^^^^^^^^^^^^^^^^^^\nKeyError: 'total_vol_traded'","exception_name":"KeyError"}
{"level":"ERROR","location":"[On_message:1443] data_ws","message":"KeyError: The key 'total_vol_traded' is missing in the response.","timestamp":"2025-08-28 11:44:43,129+0530","service":"FyersDataSocket"}
{"level":"ERROR","location":"[On_message:1442] data_ws","message":"'total_vol_traded'","timestamp":"2025-08-28 11:44:43,409+0530","service":"FyersDataSocket","exception":"Traceback (most recent call last):\n  File \"C:\\Python311\\Lib\\site-packages\\fyers_apiv3\\FyersWebsocket\\data_ws.py\", line 1433, in On_message\n    self.OnMessage(message)\n  File \"d:\\FyiersApiAutomation\\websocket\\fyers_websocket_ltp.py\", line 14, in onmessage\n    print(\"Symbol:\",message['symbol'],  \"Volume: \",message['total_vol_traded'])\n                                                   ~~~~~~~^^^^^^^^^^^^^^^^^^^^\nKeyError: 'total_vol_traded'","exception_name":"KeyError"}
{"level":"ERROR","location":"[On_message:1443] data_ws","message":"KeyError: The key 'total_vol_traded' is missing in the response.","timestamp":"2025-08-28 11:44:43,409+0530","service":"FyersDataSocket"}
{"level":"ERROR","location":"[On_message:1442] data_ws","message":"'total_vol_traded'","timestamp":"2025-08-28 11:44:43,816+0530","service":"FyersDataSocket","exception":"Traceback (most recent call last):\n  File \"C:\\Python311\\Lib\\site-packages\\fyers_apiv3\\FyersWebsocket\\data_ws.py\", line 1433, in On_message\n    self.OnMessage(message)\n  File \"d:\\FyiersApiAutomation\\websocket\\fyers_websocket_ltp.py\", line 14, in onmessage\n    print(\"Symbol:\",message['symbol'],  \"Volume: \",message['total_vol_traded'])\n                                                   ~~~~~~~^^^^^^^^^^^^^^^^^^^^\nKeyError: 'total_vol_traded'","exception_name":"KeyError"}
{"level":"ERROR","location":"[On_message:1443] data_ws","message":"KeyError: The key 'total_vol_traded' is missing in the response.","timestamp":"2025-08-28 11:44:43,816+0530","service":"FyersDataSocket"}
{"level":"ERROR","location":"[On_message:1442] data_ws","message":"'total_vol_traded'","timestamp":"2025-08-28 11:44:44,636+0530","service":"FyersDataSocket","exception":"Traceback (most recent call last):\n  File \"C:\\Python311\\Lib\\site-packages\\fyers_apiv3\\FyersWebsocket\\data_ws.py\", line 1433, in On_message\n    self.OnMessage(message)\n  File \"d:\\FyiersApiAutomation\\websocket\\fyers_websocket_ltp.py\", line 14, in onmessage\n    print(\"Symbol:\",message['symbol'],  \"Volume: \",message['total_vol_traded'])\n                                                   ~~~~~~~^^^^^^^^^^^^^^^^^^^^\nKeyError: 'total_vol_traded'","exception_name":"KeyError"}
{"level":"ERROR","location":"[On_message:1443] data_ws","message":"KeyError: The key 'total_vol_traded' is missing in the response.","timestamp":"2025-08-28 11:44:44,638+0530","service":"FyersDataSocket"}
{"level":"ERROR","location":"[On_message:1442] data_ws","message":"'total_vol_traded'","timestamp":"2025-08-28 11:44:45,691+0530","service":"FyersDataSocket","exception":"Traceback (most recent call last):\n  File \"C:\\Python311\\Lib\\site-packages\\fyers_apiv3\\FyersWebsocket\\data_ws.py\", line 1433, in On_message\n    self.OnMessage(message)\n  File \"d:\\FyiersApiAutomation\\websocket\\fyers_websocket_ltp.py\", line 14, in onmessage\n    print(\"Symbol:\",message['symbol'],  \"Volume: \",message['total_vol_traded'])\n                                                   ~~~~~~~^^^^^^^^^^^^^^^^^^^^\nKeyError: 'total_vol_traded'","exception_name":"KeyError"}
{"level":"ERROR","location":"[On_message:1443] data_ws","message":"KeyError: The key 'total_vol_traded' is missing in the response.","timestamp":"2025-08-28 11:44:45,691+0530","service":"FyersDataSocket"}
{"level":"ERROR","location":"[On_message:1442] data_ws","message":"'total_vol_traded'","timestamp":"2025-08-28 11:44:45,747+0530","service":"FyersDataSocket","exception":"Traceback (most recent call last):\n  File \"C:\\Python311\\Lib\\site-packages\\fyers_apiv3\\FyersWebsocket\\data_ws.py\", line 1433, in On_message\n    self.OnMessage(message)\n  File \"d:\\FyiersApiAutomation\\websocket\\fyers_websocket_ltp.py\", line 14, in onmessage\n    print(\"Symbol:\",message['symbol'],  \"Volume: \",message['total_vol_traded'])\n                                                   ~~~~~~~^^^^^^^^^^^^^^^^^^^^\nKeyError: 'total_vol_traded'","exception_name":"KeyError"}
{"level":"ERROR","location":"[On_message:1443] data_ws","message":"KeyError: The key 'total_vol_traded' is missing in the response.","timestamp":"2025-08-28 11:44:45,750+0530","service":"FyersDataSocket"}
{"level":"ERROR","location":"[On_message:1442] data_ws","message":"'total_vol_traded'","timestamp":"2025-08-28 11:44:46,813+0530","service":"FyersDataSocket","exception":"Traceback (most recent call last):\n  File \"C:\\Python311\\Lib\\site-packages\\fyers_apiv3\\FyersWebsocket\\data_ws.py\", line 1433, in On_message\n    self.OnMessage(message)\n  File \"d:\\FyiersApiAutomation\\websocket\\fyers_websocket_ltp.py\", line 14, in onmessage\n    print(\"Symbol:\",message['symbol'],  \"Volume: \",message['total_vol_traded'])\n                                                   ~~~~~~~^^^^^^^^^^^^^^^^^^^^\nKeyError: 'total_vol_traded'","exception_name":"KeyError"}
{"level":"ERROR","location":"[On_message:1443] data_ws","message":"KeyError: The key 'total_vol_traded' is missing in the response.","timestamp":"2025-08-28 11:44:46,813+0530","service":"FyersDataSocket"}
{"level":"ERROR","location":"[On_message:1442] data_ws","message":"'total_vol_traded'","timestamp":"2025-08-28 11:44:47,261+0530","service":"FyersDataSocket","exception":"Traceback (most recent call last):\n  File \"C:\\Python311\\Lib\\site-packages\\fyers_apiv3\\FyersWebsocket\\data_ws.py\", line 1433, in On_message\n    self.OnMessage(message)\n  File \"d:\\FyiersApiAutomation\\websocket\\fyers_websocket_ltp.py\", line 14, in onmessage\n    print(\"Symbol:\",message['symbol'],  \"Volume: \",message['total_vol_traded'])\n                                                   ~~~~~~~^^^^^^^^^^^^^^^^^^^^\nKeyError: 'total_vol_traded'","exception_name":"KeyError"}
{"level":"ERROR","location":"[On_message:1443] data_ws","message":"KeyError: The key 'total_vol_traded' is missing in the response.","timestamp":"2025-08-28 11:44:47,261+0530","service":"FyersDataSocket"}
{"level":"ERROR","location":"[On_message:1442] data_ws","message":"'total_vol_traded'","timestamp":"2025-08-28 11:44:47,384+0530","service":"FyersDataSocket","exception":"Traceback (most recent call last):\n  File \"C:\\Python311\\Lib\\site-packages\\fyers_apiv3\\FyersWebsocket\\data_ws.py\", line 1433, in On_message\n    self.OnMessage(message)\n  File \"d:\\FyiersApiAutomation\\websocket\\fyers_websocket_ltp.py\", line 14, in onmessage\n    print(\"Symbol:\",message['symbol'],  \"Volume: \",message['total_vol_traded'])\n                                                   ~~~~~~~^^^^^^^^^^^^^^^^^^^^\nKeyError: 'total_vol_traded'","exception_name":"KeyError"}
{"level":"ERROR","location":"[On_message:1443] data_ws","message":"KeyError: The key 'total_vol_traded' is missing in the response.","timestamp":"2025-08-28 11:44:47,392+0530","service":"FyersDataSocket"}
{"level":"ERROR","location":"[On_message:1442] data_ws","message":"'symbol'","timestamp":"2025-08-28 11:45:11,687+0530","service":"FyersDataSocket","exception":"Traceback (most recent call last):\n  File \"C:\\Python311\\Lib\\site-packages\\fyers_apiv3\\FyersWebsocket\\data_ws.py\", line 1433, in On_message\n    self.OnMessage(message)\n  File \"d:\\FyiersApiAutomation\\websocket\\fyers_websocket_ltp.py\", line 14, in onmessage\n    print(\"Symbol:\",message['symbol'],  \"Volume: \",message['total_vol_traded'])\n                    ~~~~~~~^^^^^^^^^^\nKeyError: 'symbol'","exception_name":"KeyError"}
{"level":"ERROR","location":"[On_message:1443] data_ws","message":"KeyError: The key 'symbol' is missing in the response.","timestamp":"2025-08-28 11:45:11,687+0530","service":"FyersDataSocket"}
{"level":"ERROR","location":"[On_message:1442] data_ws","message":"'symbol'","timestamp":"2025-08-28 11:45:11,820+0530","service":"FyersDataSocket","exception":"Traceback (most recent call last):\n  File \"C:\\Python311\\Lib\\site-packages\\fyers_apiv3\\FyersWebsocket\\data_ws.py\", line 1433, in On_message\n    self.OnMessage(message)\n  File \"d:\\FyiersApiAutomation\\websocket\\fyers_websocket_ltp.py\", line 14, in onmessage\n    print(\"Symbol:\",message['symbol'],  \"Volume: \",message['total_vol_traded'])\n                    ~~~~~~~^^^^^^^^^^\nKeyError: 'symbol'","exception_name":"KeyError"}
{"level":"ERROR","location":"[On_message:1443] data_ws","message":"KeyError: The key 'symbol' is missing in the response.","timestamp":"2025-08-28 11:45:11,820+0530","service":"FyersDataSocket"}
{"level":"ERROR","location":"[On_message:1442] data_ws","message":"'symbol'","timestamp":"2025-08-28 11:45:13,782+0530","service":"FyersDataSocket","exception":"Traceback (most recent call last):\n  File \"C:\\Python311\\Lib\\site-packages\\fyers_apiv3\\FyersWebsocket\\data_ws.py\", line 1433, in On_message\n    self.OnMessage(message)\n  File \"d:\\FyiersApiAutomation\\websocket\\fyers_websocket_ltp.py\", line 14, in onmessage\n    print(\"Symbol:\",message['symbol'],  \"Volume: \",message['total_vol_traded'])\n                    ~~~~~~~^^^^^^^^^^\nKeyError: 'symbol'","exception_name":"KeyError"}
{"level":"ERROR","location":"[On_message:1443] data_ws","message":"KeyError: The key 'symbol' is missing in the response.","timestamp":"2025-08-28 11:45:13,797+0530","service":"FyersDataSocket"}
{"level":"ERROR","location":"[On_message:1442] data_ws","message":"'total_vol_traded'","timestamp":"2025-08-28 11:45:13,930+0530","service":"FyersDataSocket","exception":"Traceback (most recent call last):\n  File \"C:\\Python311\\Lib\\site-packages\\fyers_apiv3\\FyersWebsocket\\data_ws.py\", line 1433, in On_message\n    self.OnMessage(message)\n  File \"d:\\FyiersApiAutomation\\websocket\\fyers_websocket_ltp.py\", line 14, in onmessage\n    print(\"Symbol:\",message['symbol'],  \"Volume: \",message['total_vol_traded'])\n                                                   ~~~~~~~^^^^^^^^^^^^^^^^^^^^\nKeyError: 'total_vol_traded'","exception_name":"KeyError"}
{"level":"ERROR","location":"[On_message:1443] data_ws","message":"KeyError: The key 'total_vol_traded' is missing in the response.","timestamp":"2025-08-28 11:45:13,930+0530","service":"FyersDataSocket"}
{"level":"ERROR","location":"[On_message:1442] data_ws","message":"'total_vol_traded'","timestamp":"2025-08-28 11:45:14,336+0530","service":"FyersDataSocket","exception":"Traceback (most recent call last):\n  File \"C:\\Python311\\Lib\\site-packages\\fyers_apiv3\\FyersWebsocket\\data_ws.py\", line 1433, in On_message\n    self.OnMessage(message)\n  File \"d:\\FyiersApiAutomation\\websocket\\fyers_websocket_ltp.py\", line 14, in onmessage\n    print(\"Symbol:\",message['symbol'],  \"Volume: \",message['total_vol_traded'])\n                                                   ~~~~~~~^^^^^^^^^^^^^^^^^^^^\nKeyError: 'total_vol_traded'","exception_name":"KeyError"}
{"level":"ERROR","location":"[On_message:1443] data_ws","message":"KeyError: The key 'total_vol_traded' is missing in the response.","timestamp":"2025-08-28 11:45:14,336+0530","service":"FyersDataSocket"}
{"level":"ERROR","location":"[On_message:1442] data_ws","message":"'total_vol_traded'","timestamp":"2025-08-28 11:45:14,750+0530","service":"FyersDataSocket","exception":"Traceback (most recent call last):\n  File \"C:\\Python311\\Lib\\site-packages\\fyers_apiv3\\FyersWebsocket\\data_ws.py\", line 1433, in On_message\n    self.OnMessage(message)\n  File \"d:\\FyiersApiAutomation\\websocket\\fyers_websocket_ltp.py\", line 14, in onmessage\n    print(\"Symbol:\",message['symbol'],  \"Volume: \",message['total_vol_traded'])\n                                                   ~~~~~~~^^^^^^^^^^^^^^^^^^^^\nKeyError: 'total_vol_traded'","exception_name":"KeyError"}
{"level":"ERROR","location":"[On_message:1443] data_ws","message":"KeyError: The key 'total_vol_traded' is missing in the response.","timestamp":"2025-08-28 11:45:14,762+0530","service":"FyersDataSocket"}
{"level":"ERROR","location":"[On_message:1442] data_ws","message":"'total_vol_traded'","timestamp":"2025-08-28 11:45:15,887+0530","service":"FyersDataSocket","exception":"Traceback (most recent call last):\n  File \"C:\\Python311\\Lib\\site-packages\\fyers_apiv3\\FyersWebsocket\\data_ws.py\", line 1433, in On_message\n    self.OnMessage(message)\n  File \"d:\\FyiersApiAutomation\\websocket\\fyers_websocket_ltp.py\", line 14, in onmessage\n    print(\"Symbol:\",message['symbol'],  \"Volume: \",message['total_vol_traded'])\n                                                   ~~~~~~~^^^^^^^^^^^^^^^^^^^^\nKeyError: 'total_vol_traded'","exception_name":"KeyError"}
{"level":"ERROR","location":"[On_message:1443] data_ws","message":"KeyError: The key 'total_vol_traded' is missing in the response.","timestamp":"2025-08-28 11:45:15,902+0530","service":"FyersDataSocket"}
{"level":"ERROR","location":"[On_message:1442] data_ws","message":"'total_vol_traded'","timestamp":"2025-08-28 11:45:16,969+0530","service":"FyersDataSocket","exception":"Traceback (most recent call last):\n  File \"C:\\Python311\\Lib\\site-packages\\fyers_apiv3\\FyersWebsocket\\data_ws.py\", line 1433, in On_message\n    self.OnMessage(message)\n  File \"d:\\FyiersApiAutomation\\websocket\\fyers_websocket_ltp.py\", line 14, in onmessage\n    print(\"Symbol:\",message['symbol'],  \"Volume: \",message['total_vol_traded'])\n                                                   ~~~~~~~^^^^^^^^^^^^^^^^^^^^\nKeyError: 'total_vol_traded'","exception_name":"KeyError"}
{"level":"ERROR","location":"[On_message:1443] data_ws","message":"KeyError: The key 'total_vol_traded' is missing in the response.","timestamp":"2025-08-28 11:45:16,969+0530","service":"FyersDataSocket"}
{"level":"ERROR","location":"[On_message:1442] data_ws","message":"'total_vol_traded'","timestamp":"2025-08-28 11:45:17,537+0530","service":"FyersDataSocket","exception":"Traceback (most recent call last):\n  File \"C:\\Python311\\Lib\\site-packages\\fyers_apiv3\\FyersWebsocket\\data_ws.py\", line 1433, in On_message\n    self.OnMessage(message)\n  File \"d:\\FyiersApiAutomation\\websocket\\fyers_websocket_ltp.py\", line 14, in onmessage\n    print(\"Symbol:\",message['symbol'],  \"Volume: \",message['total_vol_traded'])\n                                                   ~~~~~~~^^^^^^^^^^^^^^^^^^^^\nKeyError: 'total_vol_traded'","exception_name":"KeyError"}
{"level":"ERROR","location":"[On_message:1443] data_ws","message":"KeyError: The key 'total_vol_traded' is missing in the response.","timestamp":"2025-08-28 11:45:17,537+0530","service":"FyersDataSocket"}
{"level":"ERROR","location":"[On_message:1442] data_ws","message":"'total_vol_traded'","timestamp":"2025-08-28 11:45:17,979+0530","service":"FyersDataSocket","exception":"Traceback (most recent call last):\n  File \"C:\\Python311\\Lib\\site-packages\\fyers_apiv3\\FyersWebsocket\\data_ws.py\", line 1433, in On_message\n    self.OnMessage(message)\n  File \"d:\\FyiersApiAutomation\\websocket\\fyers_websocket_ltp.py\", line 14, in onmessage\n    print(\"Symbol:\",message['symbol'],  \"Volume: \",message['total_vol_traded'])\n                                                   ~~~~~~~^^^^^^^^^^^^^^^^^^^^\nKeyError: 'total_vol_traded'","exception_name":"KeyError"}
{"level":"ERROR","location":"[On_message:1443] data_ws","message":"KeyError: The key 'total_vol_traded' is missing in the response.","timestamp":"2025-08-28 11:45:17,979+0530","service":"FyersDataSocket"}
{"level":"ERROR","location":"[On_message:1442] data_ws","message":"'total_vol_traded'","timestamp":"2025-08-28 11:45:18,494+0530","service":"FyersDataSocket","exception":"Traceback (most recent call last):\n  File \"C:\\Python311\\Lib\\site-packages\\fyers_apiv3\\FyersWebsocket\\data_ws.py\", line 1433, in On_message\n    self.OnMessage(message)\n  File \"d:\\FyiersApiAutomation\\websocket\\fyers_websocket_ltp.py\", line 14, in onmessage\n    print(\"Symbol:\",message['symbol'],  \"Volume: \",message['total_vol_traded'])\n                                                   ~~~~~~~^^^^^^^^^^^^^^^^^^^^\nKeyError: 'total_vol_traded'","exception_name":"KeyError"}
{"level":"ERROR","location":"[On_message:1443] data_ws","message":"KeyError: The key 'total_vol_traded' is missing in the response.","timestamp":"2025-08-28 11:45:18,494+0530","service":"FyersDataSocket"}
{"level":"ERROR","location":"[On_message:1442] data_ws","message":"'total_vol_traded'","timestamp":"2025-08-28 11:45:18,953+0530","service":"FyersDataSocket","exception":"Traceback (most recent call last):\n  File \"C:\\Python311\\Lib\\site-packages\\fyers_apiv3\\FyersWebsocket\\data_ws.py\", line 1433, in On_message\n    self.OnMessage(message)\n  File \"d:\\FyiersApiAutomation\\websocket\\fyers_websocket_ltp.py\", line 14, in onmessage\n    print(\"Symbol:\",message['symbol'],  \"Volume: \",message['total_vol_traded'])\n                                                   ~~~~~~~^^^^^^^^^^^^^^^^^^^^\nKeyError: 'total_vol_traded'","exception_name":"KeyError"}
{"level":"ERROR","location":"[On_message:1443] data_ws","message":"KeyError: The key 'total_vol_traded' is missing in the response.","timestamp":"2025-08-28 11:45:18,968+0530","service":"FyersDataSocket"}
{"level":"ERROR","location":"[On_message:1442] data_ws","message":"'total_vol_traded'","timestamp":"2025-08-28 11:45:19,272+0530","service":"FyersDataSocket","exception":"Traceback (most recent call last):\n  File \"C:\\Python311\\Lib\\site-packages\\fyers_apiv3\\FyersWebsocket\\data_ws.py\", line 1433, in On_message\n    self.OnMessage(message)\n  File \"d:\\FyiersApiAutomation\\websocket\\fyers_websocket_ltp.py\", line 14, in onmessage\n    print(\"Symbol:\",message['symbol'],  \"Volume: \",message['total_vol_traded'])\n                                                   ~~~~~~~^^^^^^^^^^^^^^^^^^^^\nKeyError: 'total_vol_traded'","exception_name":"KeyError"}
{"level":"ERROR","location":"[On_message:1443] data_ws","message":"KeyError: The key 'total_vol_traded' is missing in the response.","timestamp":"2025-08-28 11:45:19,272+0530","service":"FyersDataSocket"}
{"level":"ERROR","location":"[On_message:1442] data_ws","message":"'total_vol_traded'","timestamp":"2025-08-28 11:45:19,679+0530","service":"FyersDataSocket","exception":"Traceback (most recent call last):\n  File \"C:\\Python311\\Lib\\site-packages\\fyers_apiv3\\FyersWebsocket\\data_ws.py\", line 1433, in On_message\n    self.OnMessage(message)\n  File \"d:\\FyiersApiAutomation\\websocket\\fyers_websocket_ltp.py\", line 14, in onmessage\n    print(\"Symbol:\",message['symbol'],  \"Volume: \",message['total_vol_traded'])\n                                                   ~~~~~~~^^^^^^^^^^^^^^^^^^^^\nKeyError: 'total_vol_traded'","exception_name":"KeyError"}
{"level":"ERROR","location":"[On_message:1443] data_ws","message":"KeyError: The key 'total_vol_traded' is missing in the response.","timestamp":"2025-08-28 11:45:19,679+0530","service":"FyersDataSocket"}
{"level":"ERROR","location":"[On_message:1442] data_ws","message":"'total_vol_traded'","timestamp":"2025-08-28 11:45:19,993+0530","service":"FyersDataSocket","exception":"Traceback (most recent call last):\n  File \"C:\\Python311\\Lib\\site-packages\\fyers_apiv3\\FyersWebsocket\\data_ws.py\", line 1433, in On_message\n    self.OnMessage(message)\n  File \"d:\\FyiersApiAutomation\\websocket\\fyers_websocket_ltp.py\", line 14, in onmessage\n    print(\"Symbol:\",message['symbol'],  \"Volume: \",message['total_vol_traded'])\n                                                   ~~~~~~~^^^^^^^^^^^^^^^^^^^^\nKeyError: 'total_vol_traded'","exception_name":"KeyError"}
{"level":"ERROR","location":"[On_message:1443] data_ws","message":"KeyError: The key 'total_vol_traded' is missing in the response.","timestamp":"2025-08-28 11:45:19,993+0530","service":"FyersDataSocket"}
{"level":"ERROR","location":"[On_message:1442] data_ws","message":"'total_vol_traded'","timestamp":"2025-08-28 11:45:20,602+0530","service":"FyersDataSocket","exception":"Traceback (most recent call last):\n  File \"C:\\Python311\\Lib\\site-packages\\fyers_apiv3\\FyersWebsocket\\data_ws.py\", line 1433, in On_message\n    self.OnMessage(message)\n  File \"d:\\FyiersApiAutomation\\websocket\\fyers_websocket_ltp.py\", line 14, in onmessage\n    print(\"Symbol:\",message['symbol'],  \"Volume: \",message['total_vol_traded'])\n                                                   ~~~~~~~^^^^^^^^^^^^^^^^^^^^\nKeyError: 'total_vol_traded'","exception_name":"KeyError"}
{"level":"ERROR","location":"[On_message:1443] data_ws","message":"KeyError: The key 'total_vol_traded' is missing in the response.","timestamp":"2025-08-28 11:45:20,610+0530","service":"FyersDataSocket"}
{"level":"ERROR","location":"[On_message:1442] data_ws","message":"'total_vol_traded'","timestamp":"2025-08-28 11:45:21,631+0530","service":"FyersDataSocket","exception":"Traceback (most recent call last):\n  File \"C:\\Python311\\Lib\\site-packages\\fyers_apiv3\\FyersWebsocket\\data_ws.py\", line 1433, in On_message\n    self.OnMessage(message)\n  File \"d:\\FyiersApiAutomation\\websocket\\fyers_websocket_ltp.py\", line 14, in onmessage\n    print(\"Symbol:\",message['symbol'],  \"Volume: \",message['total_vol_traded'])\n                                                   ~~~~~~~^^^^^^^^^^^^^^^^^^^^\nKeyError: 'total_vol_traded'","exception_name":"KeyError"}
{"level":"ERROR","location":"[On_message:1443] data_ws","message":"KeyError: The key 'total_vol_traded' is missing in the response.","timestamp":"2025-08-28 11:45:21,632+0530","service":"FyersDataSocket"}
{"level":"ERROR","location":"[On_message:1442] data_ws","message":"'total_vol_traded'","timestamp":"2025-08-28 11:45:23,059+0530","service":"FyersDataSocket","exception":"Traceback (most recent call last):\n  File \"C:\\Python311\\Lib\\site-packages\\fyers_apiv3\\FyersWebsocket\\data_ws.py\", line 1433, in On_message\n    self.OnMessage(message)\n  File \"d:\\FyiersApiAutomation\\websocket\\fyers_websocket_ltp.py\", line 14, in onmessage\n    print(\"Symbol:\",message['symbol'],  \"Volume: \",message['total_vol_traded'])\n                                                   ~~~~~~~^^^^^^^^^^^^^^^^^^^^\nKeyError: 'total_vol_traded'","exception_name":"KeyError"}
{"level":"ERROR","location":"[On_message:1443] data_ws","message":"KeyError: The key 'total_vol_traded' is missing in the response.","timestamp":"2025-08-28 11:45:23,063+0530","service":"FyersDataSocket"}
{"level":"ERROR","location":"[On_message:1442] data_ws","message":"'total_vol_traded'","timestamp":"2025-08-28 11:45:23,881+0530","service":"FyersDataSocket","exception":"Traceback (most recent call last):\n  File \"C:\\Python311\\Lib\\site-packages\\fyers_apiv3\\FyersWebsocket\\data_ws.py\", line 1433, in On_message\n    self.OnMessage(message)\n  File \"d:\\FyiersApiAutomation\\websocket\\fyers_websocket_ltp.py\", line 14, in onmessage\n    print(\"Symbol:\",message['symbol'],  \"Volume: \",message['total_vol_traded'])\n                                                   ~~~~~~~^^^^^^^^^^^^^^^^^^^^\nKeyError: 'total_vol_traded'","exception_name":"KeyError"}
{"level":"ERROR","location":"[On_message:1443] data_ws","message":"KeyError: The key 'total_vol_traded' is missing in the response.","timestamp":"2025-08-28 11:45:23,882+0530","service":"FyersDataSocket"}
{"level":"ERROR","location":"[On_message:1442] data_ws","message":"'total_vol_traded'","timestamp":"2025-08-28 11:45:24,191+0530","service":"FyersDataSocket","exception":"Traceback (most recent call last):\n  File \"C:\\Python311\\Lib\\site-packages\\fyers_apiv3\\FyersWebsocket\\data_ws.py\", line 1433, in On_message\n    self.OnMessage(message)\n  File \"d:\\FyiersApiAutomation\\websocket\\fyers_websocket_ltp.py\", line 14, in onmessage\n    print(\"Symbol:\",message['symbol'],  \"Volume: \",message['total_vol_traded'])\n                                                   ~~~~~~~^^^^^^^^^^^^^^^^^^^^\nKeyError: 'total_vol_traded'","exception_name":"KeyError"}
{"level":"ERROR","location":"[On_message:1443] data_ws","message":"KeyError: The key 'total_vol_traded' is missing in the response.","timestamp":"2025-08-28 11:45:24,191+0530","service":"FyersDataSocket"}
{"level":"ERROR","location":"[On_message:1442] data_ws","message":"'total_vol_traded'","timestamp":"2025-08-28 11:45:24,489+0530","service":"FyersDataSocket","exception":"Traceback (most recent call last):\n  File \"C:\\Python311\\Lib\\site-packages\\fyers_apiv3\\FyersWebsocket\\data_ws.py\", line 1433, in On_message\n    self.OnMessage(message)\n  File \"d:\\FyiersApiAutomation\\websocket\\fyers_websocket_ltp.py\", line 14, in onmessage\n    print(\"Symbol:\",message['symbol'],  \"Volume: \",message['total_vol_traded'])\n                                                   ~~~~~~~^^^^^^^^^^^^^^^^^^^^\nKeyError: 'total_vol_traded'","exception_name":"KeyError"}
{"level":"ERROR","location":"[On_message:1443] data_ws","message":"KeyError: The key 'total_vol_traded' is missing in the response.","timestamp":"2025-08-28 11:45:24,489+0530","service":"FyersDataSocket"}
{"level":"ERROR","location":"[On_message:1442] data_ws","message":"'total_vol_traded'","timestamp":"2025-08-28 11:45:24,908+0530","service":"FyersDataSocket","exception":"Traceback (most recent call last):\n  File \"C:\\Python311\\Lib\\site-packages\\fyers_apiv3\\FyersWebsocket\\data_ws.py\", line 1433, in On_message\n    self.OnMessage(message)\n  File \"d:\\FyiersApiAutomation\\websocket\\fyers_websocket_ltp.py\", line 14, in onmessage\n    print(\"Symbol:\",message['symbol'],  \"Volume: \",message['total_vol_traded'])\n                                                   ~~~~~~~^^^^^^^^^^^^^^^^^^^^\nKeyError: 'total_vol_traded'","exception_name":"KeyError"}
{"level":"ERROR","location":"[On_message:1443] data_ws","message":"KeyError: The key 'total_vol_traded' is missing in the response.","timestamp":"2025-08-28 11:45:24,908+0530","service":"FyersDataSocket"}
{"level":"ERROR","location":"[On_message:1442] data_ws","message":"'total_vol_traded'","timestamp":"2025-08-28 11:45:25,829+0530","service":"FyersDataSocket","exception":"Traceback (most recent call last):\n  File \"C:\\Python311\\Lib\\site-packages\\fyers_apiv3\\FyersWebsocket\\data_ws.py\", line 1433, in On_message\n    self.OnMessage(message)\n  File \"d:\\FyiersApiAutomation\\websocket\\fyers_websocket_ltp.py\", line 14, in onmessage\n    print(\"Symbol:\",message['symbol'],  \"Volume: \",message['total_vol_traded'])\n                                                   ~~~~~~~^^^^^^^^^^^^^^^^^^^^\nKeyError: 'total_vol_traded'","exception_name":"KeyError"}
{"level":"ERROR","location":"[On_message:1443] data_ws","message":"KeyError: The key 'total_vol_traded' is missing in the response.","timestamp":"2025-08-28 11:45:25,829+0530","service":"FyersDataSocket"}
{"level":"ERROR","location":"[On_message:1442] data_ws","message":"'total_vol_traded'","timestamp":"2025-08-28 11:45:26,133+0530","service":"FyersDataSocket","exception":"Traceback (most recent call last):\n  File \"C:\\Python311\\Lib\\site-packages\\fyers_apiv3\\FyersWebsocket\\data_ws.py\", line 1433, in On_message\n    self.OnMessage(message)\n  File \"d:\\FyiersApiAutomation\\websocket\\fyers_websocket_ltp.py\", line 14, in onmessage\n    print(\"Symbol:\",message['symbol'],  \"Volume: \",message['total_vol_traded'])\n                                                   ~~~~~~~^^^^^^^^^^^^^^^^^^^^\nKeyError: 'total_vol_traded'","exception_name":"KeyError"}
{"level":"ERROR","location":"[On_message:1443] data_ws","message":"KeyError: The key 'total_vol_traded' is missing in the response.","timestamp":"2025-08-28 11:45:26,138+0530","service":"FyersDataSocket"}
{"level":"ERROR","location":"[On_message:1442] data_ws","message":"'total_vol_traded'","timestamp":"2025-08-28 11:45:26,749+0530","service":"FyersDataSocket","exception":"Traceback (most recent call last):\n  File \"C:\\Python311\\Lib\\site-packages\\fyers_apiv3\\FyersWebsocket\\data_ws.py\", line 1433, in On_message\n    self.OnMessage(message)\n  File \"d:\\FyiersApiAutomation\\websocket\\fyers_websocket_ltp.py\", line 14, in onmessage\n    print(\"Symbol:\",message['symbol'],  \"Volume: \",message['total_vol_traded'])\n                                                   ~~~~~~~^^^^^^^^^^^^^^^^^^^^\nKeyError: 'total_vol_traded'","exception_name":"KeyError"}
{"level":"ERROR","location":"[On_message:1443] data_ws","message":"KeyError: The key 'total_vol_traded' is missing in the response.","timestamp":"2025-08-28 11:45:26,750+0530","service":"FyersDataSocket"}
{"level":"ERROR","location":"[On_message:1442] data_ws","message":"'total_vol_traded'","timestamp":"2025-08-28 11:45:26,813+0530","service":"FyersDataSocket","exception":"Traceback (most recent call last):\n  File \"C:\\Python311\\Lib\\site-packages\\fyers_apiv3\\FyersWebsocket\\data_ws.py\", line 1433, in On_message\n    self.OnMessage(message)\n  File \"d:\\FyiersApiAutomation\\websocket\\fyers_websocket_ltp.py\", line 14, in onmessage\n    print(\"Symbol:\",message['symbol'],  \"Volume: \",message['total_vol_traded'])\n                                                   ~~~~~~~^^^^^^^^^^^^^^^^^^^^\nKeyError: 'total_vol_traded'","exception_name":"KeyError"}
{"level":"ERROR","location":"[On_message:1443] data_ws","message":"KeyError: The key 'total_vol_traded' is missing in the response.","timestamp":"2025-08-28 11:45:26,813+0530","service":"FyersDataSocket"}
{"level":"ERROR","location":"[On_message:1442] data_ws","message":"'total_vol_traded'","timestamp":"2025-08-28 11:45:27,672+0530","service":"FyersDataSocket","exception":"Traceback (most recent call last):\n  File \"C:\\Python311\\Lib\\site-packages\\fyers_apiv3\\FyersWebsocket\\data_ws.py\", line 1433, in On_message\n    self.OnMessage(message)\n  File \"d:\\FyiersApiAutomation\\websocket\\fyers_websocket_ltp.py\", line 14, in onmessage\n    print(\"Symbol:\",message['symbol'],  \"Volume: \",message['total_vol_traded'])\n                                                   ~~~~~~~^^^^^^^^^^^^^^^^^^^^\nKeyError: 'total_vol_traded'","exception_name":"KeyError"}
{"level":"ERROR","location":"[On_message:1443] data_ws","message":"KeyError: The key 'total_vol_traded' is missing in the response.","timestamp":"2025-08-28 11:45:27,673+0530","service":"FyersDataSocket"}
{"level":"ERROR","location":"[On_message:1442] data_ws","message":"'total_vol_traded'","timestamp":"2025-08-28 11:45:28,179+0530","service":"FyersDataSocket","exception":"Traceback (most recent call last):\n  File \"C:\\Python311\\Lib\\site-packages\\fyers_apiv3\\FyersWebsocket\\data_ws.py\", line 1433, in On_message\n    self.OnMessage(message)\n  File \"d:\\FyiersApiAutomation\\websocket\\fyers_websocket_ltp.py\", line 14, in onmessage\n    print(\"Symbol:\",message['symbol'],  \"Volume: \",message['total_vol_traded'])\n                                                   ~~~~~~~^^^^^^^^^^^^^^^^^^^^\nKeyError: 'total_vol_traded'","exception_name":"KeyError"}
{"level":"ERROR","location":"[On_message:1443] data_ws","message":"KeyError: The key 'total_vol_traded' is missing in the response.","timestamp":"2025-08-28 11:45:28,179+0530","service":"FyersDataSocket"}
{"level":"ERROR","location":"[On_message:1442] data_ws","message":"'total_vol_traded'","timestamp":"2025-08-28 11:45:28,989+0530","service":"FyersDataSocket","exception":"Traceback (most recent call last):\n  File \"C:\\Python311\\Lib\\site-packages\\fyers_apiv3\\FyersWebsocket\\data_ws.py\", line 1433, in On_message\n    self.OnMessage(message)\n  File \"d:\\FyiersApiAutomation\\websocket\\fyers_websocket_ltp.py\", line 14, in onmessage\n    print(\"Symbol:\",message['symbol'],  \"Volume: \",message['total_vol_traded'])\n                                                   ~~~~~~~^^^^^^^^^^^^^^^^^^^^\nKeyError: 'total_vol_traded'","exception_name":"KeyError"}
{"level":"ERROR","location":"[On_message:1443] data_ws","message":"KeyError: The key 'total_vol_traded' is missing in the response.","timestamp":"2025-08-28 11:45:28,993+0530","service":"FyersDataSocket"}
{"level":"ERROR","location":"[On_message:1442] data_ws","message":"'symbol'","timestamp":"2025-08-28 11:45:55,114+0530","service":"FyersDataSocket","exception":"Traceback (most recent call last):\n  File \"C:\\Python311\\Lib\\site-packages\\fyers_apiv3\\FyersWebsocket\\data_ws.py\", line 1433, in On_message\n    self.OnMessage(message)\n  File \"d:\\FyiersApiAutomation\\websocket\\fyers_websocket_ltp.py\", line 14, in onmessage\n    print(\"Symbol:\",message['symbol'],  \"Volume: \",message['vol_traded_today'])\n                    ~~~~~~~^^^^^^^^^^\nKeyError: 'symbol'","exception_name":"KeyError"}
{"level":"ERROR","location":"[On_message:1443] data_ws","message":"KeyError: The key 'symbol' is missing in the response.","timestamp":"2025-08-28 11:45:55,123+0530","service":"FyersDataSocket"}
{"level":"ERROR","location":"[On_message:1442] data_ws","message":"'symbol'","timestamp":"2025-08-28 11:45:55,354+0530","service":"FyersDataSocket","exception":"Traceback (most recent call last):\n  File \"C:\\Python311\\Lib\\site-packages\\fyers_apiv3\\FyersWebsocket\\data_ws.py\", line 1433, in On_message\n    self.OnMessage(message)\n  File \"d:\\FyiersApiAutomation\\websocket\\fyers_websocket_ltp.py\", line 14, in onmessage\n    print(\"Symbol:\",message['symbol'],  \"Volume: \",message['vol_traded_today'])\n                    ~~~~~~~^^^^^^^^^^\nKeyError: 'symbol'","exception_name":"KeyError"}
{"level":"ERROR","location":"[On_message:1443] data_ws","message":"KeyError: The key 'symbol' is missing in the response.","timestamp":"2025-08-28 11:45:55,354+0530","service":"FyersDataSocket"}
{"level":"ERROR","location":"[On_message:1442] data_ws","message":"'symbol'","timestamp":"2025-08-28 11:45:56,679+0530","service":"FyersDataSocket","exception":"Traceback (most recent call last):\n  File \"C:\\Python311\\Lib\\site-packages\\fyers_apiv3\\FyersWebsocket\\data_ws.py\", line 1433, in On_message\n    self.OnMessage(message)\n  File \"d:\\FyiersApiAutomation\\websocket\\fyers_websocket_ltp.py\", line 14, in onmessage\n    print(\"Symbol:\",message['symbol'],  \"Volume: \",message['vol_traded_today'])\n                    ~~~~~~~^^^^^^^^^^\nKeyError: 'symbol'","exception_name":"KeyError"}
{"level":"ERROR","location":"[On_message:1443] data_ws","message":"KeyError: The key 'symbol' is missing in the response.","timestamp":"2025-08-28 11:45:56,679+0530","service":"FyersDataSocket"}
{"level":"ERROR","location":"[On_message:1442] data_ws","message":"'symbol'","timestamp":"2025-08-28 19:07:21,546+0530","service":"FyersDataSocket","exception":"Traceback (most recent call last):\n  File \"C:\\Python311\\Lib\\site-packages\\fyers_apiv3\\FyersWebsocket\\data_ws.py\", line 1433, in On_message\n    self.OnMessage(message)\n  File \"d:\\FyiersApiAutomation\\websocket\\fyers_websocket_ltp.py\", line 14, in onmessage\n    print(\"Symbol:\",message['symbol'],  \"Volume: \",message['vol_traded_today'])\n                    ~~~~~~~^^^^^^^^^^\nKeyError: 'symbol'","exception_name":"KeyError"}
{"level":"ERROR","location":"[On_message:1443] data_ws","message":"KeyError: The key 'symbol' is missing in the response.","timestamp":"2025-08-28 19:07:21,603+0530","service":"FyersDataSocket"}
{"level":"ERROR","location":"[On_message:1442] data_ws","message":"'symbol'","timestamp":"2025-08-28 19:07:21,708+0530","service":"FyersDataSocket","exception":"Traceback (most recent call last):\n  File \"C:\\Python311\\Lib\\site-packages\\fyers_apiv3\\FyersWebsocket\\data_ws.py\", line 1433, in On_message\n    self.OnMessage(message)\n  File \"d:\\FyiersApiAutomation\\websocket\\fyers_websocket_ltp.py\", line 14, in onmessage\n    print(\"Symbol:\",message['symbol'],  \"Volume: \",message['vol_traded_today'])\n                    ~~~~~~~^^^^^^^^^^\nKeyError: 'symbol'","exception_name":"KeyError"}
{"level":"ERROR","location":"[On_message:1443] data_ws","message":"KeyError: The key 'symbol' is missing in the response.","timestamp":"2025-08-28 19:07:21,725+0530","service":"FyersDataSocket"}
{"level":"ERROR","location":"[On_message:1442] data_ws","message":"'symbol'","timestamp":"2025-08-28 19:07:23,252+0530","service":"FyersDataSocket","exception":"Traceback (most recent call last):\n  File \"C:\\Python311\\Lib\\site-packages\\fyers_apiv3\\FyersWebsocket\\data_ws.py\", line 1433, in On_message\n    self.OnMessage(message)\n  File \"d:\\FyiersApiAutomation\\websocket\\fyers_websocket_ltp.py\", line 14, in onmessage\n    print(\"Symbol:\",message['symbol'],  \"Volume: \",message['vol_traded_today'])\n                    ~~~~~~~^^^^^^^^^^\nKeyError: 'symbol'","exception_name":"KeyError"}
{"level":"ERROR","location":"[On_message:1443] data_ws","message":"KeyError: The key 'symbol' is missing in the response.","timestamp":"2025-08-28 19:07:23,252+0530","service":"FyersDataSocket"}
{"level":"ERROR","location":"[On_message:1442] data_ws","message":"'symbol'","timestamp":"2025-08-28 19:08:13,883+0530","service":"FyersDataSocket","exception":"Traceback (most recent call last):\n  File \"C:\\Python311\\Lib\\site-packages\\fyers_apiv3\\FyersWebsocket\\data_ws.py\", line 1433, in On_message\n    self.OnMessage(message)\n  File \"d:\\FyiersApiAutomation\\websocket\\fyers_websocket_ltp.py\", line 13, in onmessage\n    print(\"Symbol:\",message['symbol'],  \"ltp: \",message['ltp'])\n                    ~~~~~~~^^^^^^^^^^\nKeyError: 'symbol'","exception_name":"KeyError"}
{"level":"ERROR","location":"[On_message:1443] data_ws","message":"KeyError: The key 'symbol' is missing in the response.","timestamp":"2025-08-28 19:08:13,889+0530","service":"FyersDataSocket"}
{"level":"ERROR","location":"[On_message:1442] data_ws","message":"'symbol'","timestamp":"2025-08-28 19:08:14,031+0530","service":"FyersDataSocket","exception":"Traceback (most recent call last):\n  File \"C:\\Python311\\Lib\\site-packages\\fyers_apiv3\\FyersWebsocket\\data_ws.py\", line 1433, in On_message\n    self.OnMessage(message)\n  File \"d:\\FyiersApiAutomation\\websocket\\fyers_websocket_ltp.py\", line 13, in onmessage\n    print(\"Symbol:\",message['symbol'],  \"ltp: \",message['ltp'])\n                    ~~~~~~~^^^^^^^^^^\nKeyError: 'symbol'","exception_name":"KeyError"}
{"level":"ERROR","location":"[On_message:1443] data_ws","message":"KeyError: The key 'symbol' is missing in the response.","timestamp":"2025-08-28 19:08:14,031+0530","service":"FyersDataSocket"}
{"level":"ERROR","location":"[On_message:1442] data_ws","message":"'symbol'","timestamp":"2025-08-28 19:08:16,168+0530","service":"FyersDataSocket","exception":"Traceback (most recent call last):\n  File \"C:\\Python311\\Lib\\site-packages\\fyers_apiv3\\FyersWebsocket\\data_ws.py\", line 1433, in On_message\n    self.OnMessage(message)\n  File \"d:\\FyiersApiAutomation\\websocket\\fyers_websocket_ltp.py\", line 13, in onmessage\n    print(\"Symbol:\",message['symbol'],  \"ltp: \",message['ltp'])\n                    ~~~~~~~^^^^^^^^^^\nKeyError: 'symbol'","exception_name":"KeyError"}
{"level":"ERROR","location":"[On_message:1443] data_ws","message":"KeyError: The key 'symbol' is missing in the response.","timestamp":"2025-08-28 19:08:16,168+0530","service":"FyersDataSocket"}
{"level":"ERROR","location":"[On_message:1442] data_ws","message":"'symbol'","timestamp":"2025-08-28 19:08:52,390+0530","service":"FyersDataSocket","exception":"Traceback (most recent call last):\n  File \"C:\\Python311\\Lib\\site-packages\\fyers_apiv3\\FyersWebsocket\\data_ws.py\", line 1433, in On_message\n    self.OnMessage(message)\n  File \"d:\\FyiersApiAutomation\\websocket\\fyers_websocket_ltp.py\", line 13, in onmessage\n    print(\"Symbol:\",message['symbol'],  \"ltp: \",message['ltp'])\n                    ~~~~~~~^^^^^^^^^^\nKeyError: 'symbol'","exception_name":"KeyError"}
{"level":"ERROR","location":"[On_message:1443] data_ws","message":"KeyError: The key 'symbol' is missing in the response.","timestamp":"2025-08-28 19:08:52,390+0530","service":"FyersDataSocket"}
{"level":"ERROR","location":"[On_message:1442] data_ws","message":"'symbol'","timestamp":"2025-08-28 19:08:52,533+0530","service":"FyersDataSocket","exception":"Traceback (most recent call last):\n  File \"C:\\Python311\\Lib\\site-packages\\fyers_apiv3\\FyersWebsocket\\data_ws.py\", line 1433, in On_message\n    self.OnMessage(message)\n  File \"d:\\FyiersApiAutomation\\websocket\\fyers_websocket_ltp.py\", line 13, in onmessage\n    print(\"Symbol:\",message['symbol'],  \"ltp: \",message['ltp'])\n                    ~~~~~~~^^^^^^^^^^\nKeyError: 'symbol'","exception_name":"KeyError"}
{"level":"ERROR","location":"[On_message:1443] data_ws","message":"KeyError: The key 'symbol' is missing in the response.","timestamp":"2025-08-28 19:08:52,533+0530","service":"FyersDataSocket"}
{"level":"ERROR","location":"[On_message:1442] data_ws","message":"'symbol'","timestamp":"2025-08-28 19:08:54,772+0530","service":"FyersDataSocket","exception":"Traceback (most recent call last):\n  File \"C:\\Python311\\Lib\\site-packages\\fyers_apiv3\\FyersWebsocket\\data_ws.py\", line 1433, in On_message\n    self.OnMessage(message)\n  File \"d:\\FyiersApiAutomation\\websocket\\fyers_websocket_ltp.py\", line 13, in onmessage\n    print(\"Symbol:\",message['symbol'],  \"ltp: \",message['ltp'])\n                    ~~~~~~~^^^^^^^^^^\nKeyError: 'symbol'","exception_name":"KeyError"}
{"level":"ERROR","location":"[On_message:1443] data_ws","message":"KeyError: The key 'symbol' is missing in the response.","timestamp":"2025-08-28 19:08:54,772+0530","service":"FyersDataSocket"}
